Workbook
Name CPIyear: 'Bundled Price (Nominal)'!$F$1

Sheet TableofContents
B2: Table of Contents
B4: Worksheet | C4: Description
B5: Case Assumptions | C5: Summary of key assumptions
B6: Dashboard | C6: Summary charts
B7: NEM Demand | C7: Summary of NEM underlying demand forecast
B8: NEM Generation | C8: Summary of NEM generation by state and technology
B9: NEM Capacity | C9: Summary of NEM capacity by state and technology type
B10: NEM Emissions | C10: Summary of NEM emissions by state and technology type
B11: NEM Interconnector | C11: Summary of NEM interconnector capacity and flows
B12: Gas Prices | C12: Summary of NEM gas prices by state
B13: Coal Prices | C13: Summary of NEM coal prices by power station
B14: Annual Black Price | C14: Summary of NEM annual time and dispatch weighted price by state
B15: Quarterly Black Price | C15: Summary of NEM quarterly time and dispatch weighted price by state
... B18: Bundled Price (Nominal) | C18: Summary of NEM bundled PV and wind dispatch weighted price by state (Nominal)

Sheet Case Assumptions
B2: Grattan Reference Case
B3: Assumption | C3: Parameter | D3: Grattan Reference Case
B4: Policy | C4: Renewable Energy Target | D4: State Government targets and expanded Capacity Investment Scheme drive emissions reductions to 2030. The CIS targets are delayed, expected to be met by 2033.
C5: Large Scale Renewable Energy Target (LRET) | D5: Implemented until 2030.
C6: Victorian Renewable Energy Target (VRET) | D6: 1st stage of VRET/QRET included 2nd stage of VRET, 40% renewables by 2025 included. 65% by 2030. 95% by 2035 included but not met. 2.6 GW storage by 2030, 6.3 GW by 2035. Offshore wind targets delayed by 2 years: 2 GW by 2034, 4GW by 2037 & 9 GW by 2042.
C7: Victoria Solar Homes Program | D7: Implemented
C8: Queensland Renewable Energy Target (QRET) | D8: Not included.
C9: New South Wales Electricity Plan (NRET) | D9: Implemented through lower WACCs on renewable plant: -Solar PV 4.1% -Wind 4.6%
C10: Snowy Hydro Expansion | D10: Implemented in 2030
C11: South Australian Energy Security Target (EST) | D11: Implemented
B12: Demand | C12: EV Growth | D12: AEMO ESOO 2024 (Central)
C13: Rooftop PV and PVNSG | D13: AEMO ESOO 2024 (Central)
C14: Embedded Storage | D14: AEMO ESOO 2024 (Central)
C15: Demand growth | D15: AEMO ESOO 2024 (Central)
B16: Fuel prices | C16: Gas Prices | D16: ACCC LNG Netback forward curve until 2027, converging to AEMO 2024 GSOO (Step Change) by 2032.
C17: Coal Prices | D17: AEMO Draft 2025 IASR (Step Change) until 2028, converging to AEMO 2024 ISP (Step Change) from 2029.
C18: Green Hydrogen Prices | D18: AEMO ISP 2024 (Step Change)
B19: Technology costs | C19: Renewable technology costs | D19: GenCost 2023-24 (Global NZE post 2050) renewable technology cost assumption
B20: Methodology | C20: New entrant pricing capable of delivering firm load | D20: Thermal technologies (gas, coal) and renewable technologies (wind, solar)
C21: Renewable Energy database update (list of committed and existing plants) | D21: Updated
C22: Demand profiles | D22: Historical 2019 demand profile, adjusted for PV and EV demand (from AEMO)
B23: Note that overlaying the above, Jacobs' has updated our database of renewable projects and incorporated market announcements.

Sheet Dashboard
B2: Dashboard
B4: NEM Demand | V4: NEM Emissions
B6: Total NEM Demand | GWh | L6: Total NEM Demand | GWh | V6: Generation Emissions Intensity | tonnes CO2e/MWh
B30: NEM Capacity & Generation
B32: Queensland Cumulative Capacity | MW | L32: Queensland Capacity Change | MW | V32: Queensland Generation | GWh
B56: New South Wales Cumulative Capacity | MW | L56: New South Wales Capacity Change | MW | V56: New South Wales Generation | GWh
B80: Victoria Cumulative Capacity | MW | L80: Victoria Capacity Change | MW | V80: Victoria Generation | GWh
B105: Tasmania Cumulative Capacity | MW | L105: Tasmania Capacity Change | MW | V105: Tasmania Generation | GWh
B129: South Australia Cumulative Capacity | MW | L129: South Australia Capacity Change | MW | V129: South Australia Generation | GWh
B152: Total NEM Cumulative Capacity | MW | L152: Total NEM Capacity Change | MW | V152: Total NEM Generation | GWh
B175: Total NEM Thermal Cumulative Capacity | MW | L175: Total NEM Thermal Capacity Change | MW | V175: Total NEM Thermal Generation | GWh
B198: Total NEM Coal Cumulative Capacity | MW | L198: Total NEM Coal Capacity Change | MW | V198: Total NEM Coal Generation | GWh
B222: Total NEM Gas Cumulative Capacity | MW | L222: Total NEM Gas Capacity Change | MW | V222: Total NEM Gas Generation | GWh
B246: Total NEM Renewable Cumulative Capacity | MW | L246: Total NEM Renewable Capacity Change | MW | V246: Total NEM Renewable Generation | GWh
B270: NEM Gas & Coal Prices
B272: Gas Price Regions | $/GJ | L272: Black Coal Average Price | $/GJ
B295: NEM Black Price
B297: Time Weighted Average Price | $/MWh | L297: Peak /Off-peak ratio | $/MWh
B320: Annual TWP and DWP
B322: Queensland | $/MWh | L322: New South Wales | $/MWh | V322: Victoria | $/MWh
B345: South Australia | $/MWh | L345: Tasmania | $/MWh
B369: Bundled Prices
B371: Generic PV Bundled Price | $/MWh | L371: Generic Wind Bundled Price | $/MWh | V371: Green Price (LGC, EIS) | $/MWh
B394: NEM Interconnector
B396: Firm Capacity Change | MW | L396: Net imports from other regions | TWh
B419: Anticipated Capacity Levels
B421: Anticipated capacity levels of wind and solar by 2030, Base scenario | L421: Anticipated capacity levels of wind and solar by 2040, Base scenario | V421: Anticipated capacity levels of wind and solar by 2050, Base scenario | AF421: Anticipated capacity levels of wind and solar by 2060, Base scenario

Sheet NEM Demand
A1: Underlying Demand
A2: Financial Year | C2: 2025 | D2: 2026 | E2: 2027 | F2: 2028 | G2: 2029 | H2: 2030 | I2: 2031 | J2: 2032 | K2: 2033 | L2: 2034 | M2: 2035 | N2: 2036 | O2: 2037 | P2: 2038 | Q2: 2039 | R2: 2040 | S2: 2041 | T2: 2042 | U2: 2043 | V2: 2044 | W2: 2045 | X2: 2046 | Y2: 2047 | Z2: 2048 | AA2: 2049 | AB2: 2050 | AC2: 2051 | AD2: 2052 | AE2: 2053 | AF2: 2054 | AG2: 2055 | AH2: 2056 | AI2: 2057 | AJ2: 2058 | AK2: 2059 | AL2: 2060
A3: Queensland
A4: Peak demand | B4: MW | C4: 10225.287 | D4: 10380.09 | E4: 10562.856 | F4: 10754.788 | G4: 10863.821 | H4: 11024.257 | I4: 11157.574 | J4: 11322.516 | K4: 11466.499 | L4: 11449.327 | M4: 11907.169 | N4: 12425.023 | O4: 12768.42 | P4: 13042.447 | Q4: 13344.379 | R4: 13890.575 | S4: 14024.716 | T4: 14647.798 | U4: 14895.047 | V4: 15307.034 | W4: 15619.466 | X4: 16064.77 | Y4: 16275.678 | Z4: 16208.017 | AA4: 16666.662 | AB4: 16786.316 | AC4: 17169.044 | AD4: 17729.366 | AE4: 18316.615 | AF4: 18669.515 | AG4: 19029.213 | AH4: 19580.897 | AI4: 20046.946 | AJ4: 20512.994 | AK4: 20979.043 | AL4: 21445.092
A5: Energy | B5: GWh | C5: 60617.128 | D5: 62212.666 | E5: 63816.374 | F5: 65317.668 | G5: 66750.828 | H5: 69399.232 | I5: 72107.442 | J5: 75789.438 | K5: 79683.746 | L5: 82281.186 | M5: 85656.614 | N5: 89201.834 | O5: 92038.823 | P5: 94255 | Q5: 97046.925 | R5: 101231.96 | S5: 102962.74 | T5: 107442.48 | U5: 110005.47 | V5: 113565.88 | W5: 116348.68 | X5: 119909 | Y5: 122273.87 | Z5: 123207.59 | AA5: 126953.75 | AB5: 128972.97 | AC5: 132309.21 | AD5: 136596.28 | AE5: 140867.88 | AF5: 143927.54 | AG5: 146987.2 | AH5: 149395.35 | AI5: 152995.54 | AJ5: 156700.68 | AK5: 160088.75 | AL5: 163598.16
A6: Load factor | B6: % | C6: 0.67673049 | D6: 0.68418505 | E6: 0.68967848 | F6: 0.69330563 | G6: 0.70140679 | H6: 0.71862321 | I6: 0.73774491 | J6: 0.76412014 | K6: 0.79329517 | L6: 0.82038269 | M6: 0.82119877 | N6: 0.81954441 | O6: 0.82286727 | P6: 0.82497582 | Q6: 0.83019346 | R6: 0.8319425 | S6: 0.83807309 | T6: 0.83733562 | U6: 0.84307906 | V6: 0.84694014 | W6: 0.85033715 | X6: 0.85206586 | Y6: 0.85761123 | Z6: 0.86776766 | AA6: 0.86954648 | AB6: 0.87708 | AC6: 0.87971067 | AD6: 0.87951155 | AE6: 0.87793555 | AF6: 0.8800488 | AG6: 0.88176847 | AH6: 0.87096438 | AI6: 0.87121722 | AJ6: 0.87204262 | AK6: 0.87110607 | AL6: 0.87085611
A7: New South Wales
A8: Peak demand | B8: MW | C8: 13293.547 | D8: 13436.44 | E8: 13605.254 | F8: 13767.481 | G8: 13781.289 | H8: 13852.645 | I8: 14053.381 | J8: 14116.247 | K8: 14156.698 | L8: 14138.764 | M8: 14457.492 | N8: 14843.863 | O8: 15226.102 | P8: 15531.568 | Q8: 15902.745 | R8: 16275.971 | S8: 16750.603 | T8: 17114.621 | U8: 17469.625 | V8: 17872.855 | W8: 18125.73 | X8: 18402.051 | Y8: 18724.164 | Z8: 19182.96 | AA8: 19553.093 | AB8: 19947.625 | AC8: 20358.785 | AD8: 21172.332 | AE8: 21569.512 | AF8: 21966.692 | AG8: 22371.166 | AH8: 22275.29 | AI8: 22685.431 | AJ8: 23103.102 | AK8: 23528.443 | AL8: 23961.595
A9: Energy | B9: GWh | C9: 74571.728 | D9: 75939.882 | E9: 77699.645 | F9: 79554.881 | G9: 81404.488 | H9: 83251.665 | I9: 85461.158 | J9: 87009.874 | K9: 87767.35 | L9: 89742.846 | M9: 91073.068 | N9: 93117.444 | O9: 95595.685 | P9: 98047.425 | Q9: 100006.73 | R9: 102387.52 | S9: 104781.45 | T9: 107825.81 | U9: 110160.68 | V9: 112437.73 | W9: 115024.11 | X9: 116646.09 | Y9: 118418.45 | Z9: 120484.53 | AA9: 123427.33 | AB9: 125801.41 | AC9: 128332.01 | AD9: 130969.25 | AE9: 136187.46 | AF9: 138735.04 | AG9: 141330.27 | AH9: 143634.68 | AI9: 146838.71 | AJ9: 149997.76 | AK9: 153076.69 | AL9: 156204.39
A10: Load factor | B10: % | C10: 0.64036743 | D10: 0.64518105 | E10: 0.65194095 | F10: 0.65964191 | G10: 0.67430193 | H10: 0.68605053 | I10: 0.69419879 | J10: 0.70363136 | K10: 0.70772887 | L10: 0.72457659 | M10: 0.71910596 | N10: 0.71611044 | O10: 0.71671328 | P10: 0.72063737 | Q10: 0.71788193 | R10: 0.71811832 | S10: 0.7140849 | T10: 0.71920273 | U10: 0.71984491 | V10: 0.71814811 | W10: 0.72441806 | X10: 0.72360212 | Y10: 0.72195954 | Z10: 0.71698748 | AA10: 0.72059584 | AB10: 0.71992991 | AC10: 0.7195799 | AD10: 0.7061493 | AE10: 0.72076337 | AF10: 0.72097033 | AG10: 0.721178 | AH10: 0.73609153 | AI10: 0.73890642 | AJ10: 0.74115725 | AK10: 0.74269716 | AL10: 0.74417215
A11: Victoria
A12: Peak demand | B12: MW | C12: 9593.713 | D12: 9697.0622 | E12: 9915.9267 | F12: 10027.401 | G12: 10166.539 | H12: 10269.01 | I12: 10316.968 | J12: 10421.2 | K12: 10507.946 | L12: 10579.767 | M12: 10905.479 | N12: 11279.722 | O12: 11631.936 | P12: 11947.877 | Q12: 12241.6 | R12: 12505.079 | S12: 12819.509 | T12: 13095.376 | U12: 13424.149 | V12: 13825.816 | W12: 14063.115 | X12: 14258.298 | Y12: 14506.598 | Z12: 14777.684 | AA12: 15053.976 | AB12: 15287.736 | AC12: 15499.527 | AD12: 15717.028 | AE12: 15894.075 | AF12: 16071.123 | AG12: 16250.143 | AH12: 15779.001 | AI12: 15954.767 | AJ12: 16132.491 | AK12: 16312.194 | AL12: 16493.899
A13: Energy | B13: GWh | C13: 47542.448 | D13: 48833.868 | E13: 50498.711 | F13: 52041.766 | G13: 53377.498 | H13: 54867.739 | I13: 56416.785 | J13: 59320.649 | K13: 63441.548 | L13: 66264.654 | M13: 68545.22 | N13: 70655.474 | O13: 73080.159 | P13: 75362.118 | Q13: 77409.066 | R13: 79312.064 | S13: 81019.121 | T13: 83056.278 | U13: 84843.593 | V13: 86973.677 | W13: 89576.036 | X13: 91113.476 | Y13: 92378.045 | Z13: 93986.756 | AA13: 95743.09 | AB13: 97533.158 | AC13: 99047.668 | AD13: 100419.84 | AE13: 101829 | AF13: 102976.08 | AG13: 104136.07 | AH13: 106121.17 | AI13: 107589.02 | AJ13: 108980.72 | AK13: 110344.01 | AL13: 111721.39
A14: Load factor | B14: % | C14: 0.56570591 | D14: 0.57487952 | E14: 0.58135697 | F14: 0.59246066 | G14: 0.59935066 | H14: 0.60993618 | I14: 0.62424077 | J14: 0.64980648 | K14: 0.68921042 | L14: 0.7149929 | M14: 0.71751061 | N14: 0.71506133 | O14: 0.71720508 | P14: 0.72004267 | Q14: 0.72185429 | R14: 0.72401688 | S14: 0.72145962 | T14: 0.7240197 | U14: 0.72148647 | V14: 0.71811328 | W14: 0.72712017 | X14: 0.72947568 | Y14: 0.72694085 | Z14: 0.7260327 | AA14: 0.72602592 | AB14: 0.72829109 | AC14: 0.72949394 | AD14: 0.72936515 | AE14: 0.73136154 | AF14: 0.7314523 | AG14: 0.73154307 | AH14: 0.76774752 | AI14: 0.76979198 | AJ14: 0.77115935 | AK14: 0.77220443 | AL14: 0.77323032
A15: South Australia
A16: Peak demand | B16: MW | C16: 2987.8326 | D16: 3047.4371 | E16: 3116.3992 | F16: 3175.5042 | G16: 3191.0635 | H16: 3200.5643 | I16: 3246.7036 | J16: 3285.0795 | K16: 3294.9293 | L16: 3312.4013 | M16: 3423.6983 | N16: 3554.9372 | O16: 3725.1185 | P16: 3824.1638 | Q16: 3923.5996 | R16: 4010.5316 | S16: 4118.0216 | T16: 4232.9815 | U16: 4388.0644 | V16: 4501.392 | W16: 4539.9853 | X16: 4637.5834 | Y16: 4662.8835 | Z16: 4771.0117 | AA16: 4877.5605 | AB16: 4904.5282 | AC16: 4949.1349 | AD16: 5166.7022 | AE16: 5237.4298 | AF16: 5308.1573 | AG16: 5379.84 | AH16: 5119.6008 | AI16: 5188.7371 | AJ16: 5258.8071 | AK16: 5329.8234 | AL16: 5401.7986
A17: Energy | B17: GWh | C17: 15529.38 | D17: 16285.83 | E17: 17389.273 | F17: 18040.493 | G17: 18362.566 | H17: 18591.601 | I17: 19054.735 | J17: 19409.812 | K17: 19748.992 | L17: 20570.345 | M17: 20893.528 | N17: 21595.553 | O17: 22423.364 | P17: 23496.811 | Q17: 24121.556 | R17: 24748.764 | S17: 25297.102 | T17: 25975.113 | U17: 26700.242 | V17: 27678.454 | W17: 28393.286 | X17: 28636.72 | Y17: 29252.337 | Z17: 29411.921 | AA17: 30093.958 | AB17: 30766.032 | AC17: 30936.136 | AD17: 31217.5 | AE17: 32589.843 | AF17: 33035.968 | AG17: 33488.201 | AH17: 33928.831 | AI17: 34508.248 | AJ17: 35130.789 | AK17: 35694.507 | AL17: 36284.332
A18: Load factor | B18: % | C18: 0.5933265 | D18: 0.61005787 | E18: 0.63697772 | F18: 0.64853229 | G18: 0.65689177 | H18: 0.66311084 | I18: 0.66997125 | J18: 0.67448351 | K18: 0.68421839 | L18: 0.70891557 | M18: 0.69664606 | N18: 0.69347096 | O18: 0.68715794 | P18: 0.70140416 | Q18: 0.70180512 | R18: 0.7044456 | S18: 0.70125835 | T18: 0.70049812 | U18: 0.69460532 | V18: 0.70192529 | W18: 0.71393244 | X18: 0.70489987 | Y18: 0.71614653 | Z18: 0.70373444 | AA18: 0.70432409 | AB18: 0.7160942 | AC18: 0.71356357 | AD18: 0.68973233 | AE18: 0.71032965 | AF18: 0.71045922 | AG18: 0.7105888 | AH18: 0.75653443 | AI18: 0.75920163 | AJ18: 0.76259956 | AK18: 0.76451228 | AL18: 0.76679034
A19: Tasmania
A20: Peak demand | B20: MW | C20: 1705.9414 | D20: 1723.9666 | E20: 1731.0859 | F20: 1732.3077 | G20: 1735.8649 | H20: 1738.6747 | I20: 1758.2769 | J20: 1798.6386 | K20: 1837.4416 | L20: 1859.6274 | M20: 1877.5479 | N20: 2017.3805 | O20: 2233.3403 | P20: 2163.1665 | Q20: 2150.5753 | R20: 2304.6764 | S20: 2160.3493 | T20: 2277.1083 | U20: 2271.8379 | V20: 2239.1482 | W20: 2173.6873 | X20: 2210.0201 | Y20: 2375.9225 | Z20: 2286.3596 | AA20: 2391.3119 | AB20: 2388.1528 | AC20: 2371.8535 | AD20: 2348.0257 | AE20: 2334.5307 | AF20: 2321.0356 | AG20: 2307.6186 | AH20: 2294.2791 | AI20: 2281.0167 | AJ20: 2267.831 | AK20: 2254.7215 | AL20: 2241.6878
A21: Energy | B21: GWh | C21: 11317.477 | D21: 11407.532 | E21: 11574.83 | F21: 11556.518 | G21: 11599.737 | H21: 12230.88 | I21: 13406.586 | J21: 13927.507 | K21: 15259.308 | L21: 16744.13 | M21: 15747.572 | N21: 15899.325 | O21: 17083.446 | P21: 18912.222 | Q21: 18317.981 | R21: 18211.358 | S21: 19516.306 | T21: 18294.125 | U21: 19282.856 | V21: 19238.225 | W21: 18961.404 | X21: 18407.073 | Y21: 18714.744 | Z21: 20119.627 | AA21: 19361.197 | AB21: 20249.947 | AC21: 20223.195 | AD21: 20085.171 | AE21: 19883.394 | AF21: 19769.116 | AG21: 20432.661 | AH21: 20610.443 | AI21: 20613.431 | AJ21: 20552.768 | AK21: 20715.898 | AL21: 20713.154
A22: Load factor | B22: % | C22: 0.75732345 | D22: 0.75536826 | E22: 0.76329411 | F22: 0.76154899 | G22: 0.76283063 | H22: 0.80303646 | I22: 0.87041594 | J22: 0.88394526 | K22: 0.94801936 | L22: 1.0278566 | M22: 0.95745522 | N22: 0.89967732 | O22: 0.87320553 | P22: 0.9980413 | Q22: 0.97234155 | R22: 0.90204513 | S22: 1.0312633 | T22: 0.9171151 | U22: 0.96892442 | V22: 0.9807946 | W22: 0.99579359 | X22: 0.95078955 | Y22: 0.89918182 | Z22: 1.0045494 | AA22: 0.92425513 | AB22: 0.96796059 | AC22: 0.97332482 | AD22: 0.97649174 | AE22: 0.97226987 | AF22: 0.97230236 | AG22: 1.0107804 | AH22: 1.0255031 | AI22: 1.0316151 | AJ22: 1.0345596 | AK22: 1.048834 | AL22: 1.0547924
A23: NEM
A24: Energy | B24: GWh | C24: 209578.16 | D24: 214679.78 | E24: 220978.83 | F24: 226511.33 | G24: 231495.12 | H24: 238341.12 | I24: 246446.71 | J24: 255457.28 | K24: 265900.95 | L24: 275603.16 | M24: 281916 | N24: 290469.63 | O24: 300221.48 | P24: 310073.58 | Q24: 316902.26 | R24: 325891.67 | S24: 333576.72 | T24: 342593.8 | U24: 350992.84 | V24: 359893.96 | W24: 368303.51 | X24: 374712.36 | Y24: 381037.45 | Z24: 387210.42 | AA24: 395579.32 | AB24: 403323.52 | AC24: 410848.22 | AD24: 419288.04 | AE24: 431357.58 | AF24: 438443.74 | AG24: 446374.4 | AH24: 453690.47 | AI24: 462544.95 | AJ24: 471362.71 | AK24: 479919.86 | AL24: 488521.43
A25: Growth rate | B25: % | C25: 0.0072346122 | D25: 0.024342305 | E25: 0.029341637 | F25: 0.025036299 | G25: 0.022002394 | H25: 0.029572978 | I25: 0.034008354 | J25: 0.036561958 | K25: 0.040882238 | L25: 0.036488081 | M25: 0.022905547 | N25: 0.030341052 | O25: 0.033572691 | P25: 0.032816102 | Q25: 0.022022784 | R25: 0.028366495 | S25: 0.023581609 | T25: 0.027031528 | U25: 0.024516026 | V25: 0.025359825 | W25: 0.023366747 | X25: 0.017400992 | Y25: 0.016879857 | Z25: 0.016200442 | AA25: 0.021613314 | AB25: 0.019576856 | AC25: 0.018656716 | AD25: 0.020542431 | AE25: 0.028785804 | AF25: 0.01642757 | AG25: 0.018088215 | AH25: 0.016389988 | AI25: 0.019516568 | AJ25: 0.019063567 | AK25: 0.018154072 | AL25: 0.017922925
A26: System load factor | B26: % | C26: 0.75372384 | D26: 0.76618619 | E26: 0.77421443 | F26: 0.78411426 | G26: 0.79807808 | H26: 0.80912165 | I26: 0.83114123 | J26: 0.8484616 | K26: 0.886578 | L26: 0.9192152 | M26: 0.91332569 | N26: 0.91511141 | O26: 0.90777228 | P26: 0.89385849 | Q26: 0.87040747 | R26: 0.87753817 | S26: 0.86682176 | T26: 0.85659226 | U26: 0.83977383 | V26: 0.85511827 | W26: 0.84607846 | X26: 0.85648255 | Y26: 0.86821352 | Z26: 0.86400965 | AA26: 0.86409932 | AB26: 0.87477897 | AC26: 0.88029667 | AD26: 0.87990247 | AE26: 0.87220816 | AF26: 0.87596184 | AG26: 0.89158875 | AH26: 0.8948903 | AI26: 0.88482343 | AJ26: 0.87863799 | AK26: 0.87426141 | AL26: 0.87250602

Sheet NEM Capacity
A1: Capacity
A2: Financial Year | C2: 2025 | D2: 2026 | E2: 2027 | F2: 2028 | G2: 2029 | H2: 2030 | I2: 2031 | J2: 2032 | K2: 2033 | L2: 2034 | M2: 2035 | N2: 2036 | O2: 2037 | P2: 2038 | Q2: 2039 | R2: 2040 | S2: 2041 | T2: 2042 | U2: 2043 | V2: 2044 | W2: 2045 | X2: 2046 | Y2: 2047 | Z2: 2048 | AA2: 2049 | AB2: 2050 | AC2: 2051 | AD2: 2052 | AE2: 2053 | AF2: 2054 | AG2: 2055 | AH2: 2056 | AI2: 2057 | AJ2: 2058 | AK2: 2059 | AL2: 2060
A3: Queensland South
A4: Black Coal | B4: MW | C4: 3182.34 | D4: 3182.34 | E4: 3182.34 | F4: 3182.34 | G4: 3182.34 | H4: 3182.34 | I4: 3182.34 | J4: 3182.34 | K4: 3182.34 | L4: 3182.34 | M4: 3182.34 | N4: 2538.34 | O4: 1477.92 | P4: 1477.92 | Q4: 1477.92 | R4: 1477.92 | S4: 1477.92 | T4: 800.88 | U4: 800.88 | V4: 800.88 | W4: 800.88 | X4: 800.88 | Y4: 800.88 | Z4: 800.88 | AA4: 800.88 | AB4: 800.88 | AC4: 0 | AD4: 0 | AE4: 0 | AF4: 0 | AG4: 0 | AH4: 0 | AI4: 0 | AJ4: 0 | AK4: 0 | AL4: 0
A5: Brown Coal | B5: MW | C5: 0 | D5: 0 | E5: 0 | F5: 0 | G5: 0 | H5: 0 | I5: 0 | J5: 0 | K5: 0 | L5: 0 | M5: 0 | N5: 0 | O5: 0 | P5: 0 | Q5: 0 | R5: 0 | S5: 0 | T5: 0 | U5: 0 | V5: 0 | W5: 0 | X5: 0 | Y5: 0 | Z5: 0 | AA5: 0 | AB5: 0 | AC5: 0 | AD5: 0 | AE5: 0 | AF5: 0 | AG5: 0 | AH5: 0 | AI5: 0 | AJ5: 0 | AK5: 0 | AL5: 0
A6: Hydrogen ready | B6: MW | C6: 0 | D6: 0 | E6: 0 | F6: 0 | G6: 482.8 | H6: 482.8 | I6: 482.8 | J6: 482.8 | K6: 482.8 | L6: 482.8 | M6: 862.8 | N6: 862.8 | O6: 862.8 | P6: 862.8 | Q6: 862.8 | R6: 862.8 | S6: 862.8 | T6: 862.8 | U6: 1036 | V6: 1036 | W6: 1036 | X6: 1036 | Y6: 1036 | Z6: 1582.2 | AA6: 1746.9 | AB6: 1746.9 | AC6: 1911.6 | AD6: 1911.6 | AE6: 1911.6 | AF6: 1911.6 | AG6: 1911.6 | AH6: 1911.6 | AI6: 1911.6 | AJ6: 1911.6 | AK6: 1911.6 | AL6: 1911.6
A7: Gas GT | B7: MW | C7: 1423.86 | D7: 1423.86 | E7: 1423.86 | F7: 1423.86 | G7: 1390.03 | H7: 1356.2 | I7: 1356.2 | J7: 1356.2 | K7: 1356.2 | L7: 1356.2 | M7: 1356.2 | N7: 1356.2 | O7: 1356.2 | P7: 1356.2 | Q7: 1356.2 | R7: 1356.2 | S7: 1356.2 | T7: 1356.2 | U7: 1356.2 | V7: 1356.2 | W7: 1356.2 | X7: 1356.2 | Y7: 839.78 | Z7: 839.78 | AA7: 839.78 | AB7: 839.78 | AC7: 501.48 | AD7: 501.48 | AE7: 501.48 | AF7: 501.48 | AG7: 501.48 | AH7: 501.48 | AI7: 0 | AJ7: 0 | AK7: 0 | AL7: 0
A8: Gas CCGT & Cogen | B8: MW | C8: 1117.42 | D8: 1117.42 | E8: 1117.42 | F8: 758.52 | G8: 758.52 | H8: 758.52 | I8: 758.52 | J8: 758.52 | K8: 758.52 | L8: 758.52 | M8: 758.52 | N8: 758.52 | O8: 758.52 | P8: 758.52 | Q8: 758.52 | R8: 758.52 | S8: 617.4 | T8: 617.4 | U8: 617.4 | V8: 617.4 | W8: 617.4 | X8: 0 | Y8: 0 | Z8: 0 | AA8: 0 | AB8: 0 | AC8: 0 | AD8: 0 | AE8: 0 | AF8: 0 | AG8: 0 | AH8: 0 | AI8: 0 | AJ8: 0 | AK8: 0 | AL8: 0
A9: Gas CC CCS | B9: MW | C9: 0 | D9: 0 | E9: 0 | F9: 0 | G9: 0 | H9: 0 | I9: 0 | J9: 0 | K9: 0 | L9: 0 | M9: 0 | N9: 0 | O9: 0 | P9: 0 | Q9: 0 | R9: 0 | S9: 0 | T9: 0 | U9: 0 | V9: 0 | W9: 0 | X9: 0 | Y9: 0 | Z9: 0 | AA9: 0 | AB9: 0 | AC9: 0 | AD9: 0 | AE9: 0 | AF9: 0 | AG9: 0 | AH9: 0 | AI9: 0 | AJ9: 0 | AK9: 0 | AL9: 0
A10: Gas Steam | B10: MW | C10: 0 | D10: 0 | E10: 0 | F10: 0 | G10: 0 | H10: 0 | I10: 0 | J10: 0 | K10: 0 | L10: 0 | M10: 0 | N10: 0 | O10: 0 | P10: 0 | Q10: 0 | R10: 0 | S10: 0 | T10: 0 | U10: 0 | V10: 0 | W10: 0 | X10: 0 | Y10: 0 | Z10: 0 | AA10: 0 | AB10: 0 | AC10: 0 | AD10: 0 | AE10: 0 | AF10: 0 | AG10: 0 | AH10: 0 | AI10: 0 | AJ10: 0 | AK10: 0 | AL10: 0
A11: Distillate | B11: MW | C11: 0 | D11: 0 | E11: 0 | F11: 0 | G11: 0 | H11: 0 | I11: 0 | J11: 0 | K11: 0 | L11: 0 | M11: 0 | N11: 0 | O11: 0 | P11: 0 | Q11: 0 | R11: 0 | S11: 0 | T11: 0 | U11: 0 | V11: 0 | W11: 0 | X11: 0 | Y11: 0 | Z11: 0 | AA11: 0 | AB11: 0 | AC11: 0 | AD11: 0 | AE11: 0 | AF11: 0 | AG11: 0 | AH11: 0 | AI11: 0 | AJ11: 0 | AK11: 0 | AL11: 0
A12: Hydro | B12: MW | C12: 54.495 | D12: 54.495 | E12: 54.495 | F12: 54.495 | G12: 54.495 | H12: 54.495 | I12: 54.495 | J12: 54.495 | K12: 54.495 | L12: 54.495 | M12: 54.495 | N12: 54.495 | O12: 54.495 | P12: 54.495 | Q12: 54.495 | R12: 54.495 | S12: 54.495 | T12: 54.495 | U12: 54.495 | V12: 54.495 | W12: 54.495 | X12: 54.495 | Y12: 54.495 | Z12: 54.495 | AA12: 54.495 | AB12: 54.495 | AC12: 54.495 | AD12: 54.495 | AE12: 54.495 | AF12: 54.495 | AG12: 54.495 | AH12: 54.495 | AI12: 54.495 | AJ12: 54.495 | AK12: 54.495 | AL12: 54.495
A13: Wind | B13: MW | C13: 1864.99 | D13: 1864.99 | E13: 1864.99 | F13: 1864.99 | G13: 1864.99 | H13: 1864.99 | I13: 1864.99 | J13: 1864.99 | K13: 1864.99 | L13: 1864.99 | M13: 1864.99 | N13: 1864.99 | O13: 1864.99 | P13: 1864.99 | Q13: 1864.99 | R13: 1864.99 | S13: 1864.99 | T13: 1864.99 | U13: 2064.99 | V13: 2296.99 | W13: 2496.99 | X13: 2496.99 | Y13: 2496.99 | Z13: 2496.99 | AA13: 2496.99 | AB13: 2696.99 | AC13: 2896.99 | AD13: 2896.99 | AE13: 2896.99 | AF13: 2896.99 | AG13: 2896.99 | AH13: 2896.99 | AI13: 2896.99 | AJ13: 2896.99 | AK13: 3296.99 | AL13: 3296.99
A14: Biomass | B14: MW | C14: 384.45 | D14: 384.45 | E14: 384.45 | F14: 384.45 | G14: 384.45 | H14: 384.45 | I14: 384.45 | J14: 384.45 | K14: 384.45 | L14: 384.45 | M14: 384.45 | N14: 384.45 | O14: 384.45 | P14: 384.45 | Q14: 384.45 | R14: 384.45 | S14: 384.45 | T14: 384.45 | U14: 384.45 | V14: 384.45 | W14: 384.45 | X14: 384.45 | Y14: 384.45 | Z14: 384.45 | AA14: 384.45 | AB14: 384.45 | AC14: 384.45 | AD14: 384.45 | AE14: 384.45 | AF14: 384.45 | AG14: 384.45 | AH14: 384.45 | AI14: 384.45 | AJ14: 384.45 | AK14: 384.45 | AL14: 384.45
A15: Solar | B15: MW | C15: 2163.77 | D15: 3040.49 | E15: 3991.29 | F15: 3991.29 | G15: 4241.29 | H15: 4241.29 | I15: 4241.29 | J15: 4241.29 | K15: 4241.29 | L15: 4241.29 | M15: 4391.29 | N15: 4391.29 | O15: 5611.29 | P15: 6311.29 | Q15: 6311.29 | R15: 7361.29 | S15: 7561.29 | T15: 7561.29 | U15: 7561.29 | V15: 7561.29 | W15: 7811.29 | X15: 8611.29 | Y15: 9611.29 | Z15: 9611.29 | AA15: 9611.29 | AB15: 10161.29 | AC15: 11211.29 | AD15: 11911.29 | AE15: 12111.29 | AF15: 12111.29 | AG15: 12111.29 | AH15: 12111.29 | AI15: 12111.29 | AJ15: 12511.29 | AK15: 12711.29 | AL15: 12911.29
... A22: Total | B22: MW | C22: 16629.9 | D22: 18574.129 | E22: 20009.486 | F22: 20750.558 | G22: 22358.762 | H22: 22990.909 | I22: 25540.472 | J22: 27285.025 | K22: 28085.836 | L22: 28644.217 | M22: 29705.799 | N22: 29601.496 | O22: 30410.731 | P22: 31816.838 | Q22: 32523.153 | R22: 34226.167 | S22: 34929.191 | T22: 34977.538 | U22: 36130.181 | V22: 37122.739 | W22: 38277.175 | X22: 39200.931 | Y22: 40449.227 | Z22: 41719.507 | AA22: 42604.208 | AB22: 44026.311 | AC22: 44845.472 | AD22: 46159.274 | AE22: 46963.545 | AF22: 47574.09 | AG22: 48189.876 | AH22: 48799.532 | AI22: 48905.505 | AJ22: 49913.64 | AK22: 51120.572 | AL22: 51936.45
A23: Queensland North
A24: Black Coal | B24: MW | C24: 0 | D24: 0 | E24: 0 | F24: 0 | G24: 0 | H24: 0 | I24: 0 | J24: 0 | K24: 0 | L24: 0 | M24: 0 | N24: 0 | O24: 0 | P24: 0 | Q24: 0 | R24: 0 | S24: 0 | T24: 0 | U24: 0 | V24: 0 | W24: 0 | X24: 0 | Y24: 0 | Z24: 0 | AA24: 0 | AB24: 0 | AC24: 0 | AD24: 0 | AE24: 0 | AF24: 0 | AG24: 0 | AH24: 0 | AI24: 0 | AJ24: 0 | AK24: 0 | AL24: 0
A25: Brown Coal | B25: MW | C25: 0 | D25: 0 | E25: 0 | F25: 0 | G25: 0 | H25: 0 | I25: 0 | J25: 0 | K25: 0 | L25: 0 | M25: 0 | N25: 0 | O25: 0 | P25: 0 | Q25: 0 | R25: 0 | S25: 0 | T25: 0 | U25: 0 | V25: 0 | W25: 0 | X25: 0 | Y25: 0 | Z25: 0 | AA25: 0 | AB25: 0 | AC25: 0 | AD25: 0 | AE25: 0 | AF25: 0 | AG25: 0 | AH25: 0 | AI25: 0 | AJ25: 0 | AK25: 0 | AL25: 0
A26: Hydrogen ready | B26: MW | C26: 0 | D26: 0 | E26: 0 | F26: 0 | G26: 0 | H26: 0 | I26: 0 | J26: 0 | K26: 0 | L26: 0 | M26: 0 | N26: 0 | O26: 0 | P26: 0 | Q26: 0 | R26: 193.12 | S26: 193.12 | T26: 193.12 | U26: 193.12 | V26: 358.92 | W26: 358.92 | X26: 358.92 | Y26: 358.92 | Z26: 358.92 | AA26: 358.92 | AB26: 358.92 | AC26: 358.92 | AD26: 358.92 | AE26: 358.92 | AF26: 358.92 | AG26: 358.92 | AH26: 358.92 | AI26: 358.92 | AJ26: 358.92 | AK26: 358.92 | AL26: 358.92
A27: Gas GT | B27: MW | C27: 416.91 | D27: 416.91 | E27: 416.91 | F27: 416.91 | G27: 416.91 | H27: 416.91 | I27: 416.91 | J27: 416.91 | K27: 126.37 | L27: 126.37 | M27: 126.37 | N27: 126.37 | O27: 126.37 | P27: 126.37 | Q27: 126.37 | R27: 126.37 | S27: 126.37 | T27: 126.37 | U27: 126.37 | V27: 126.37 | W27: 0 | X27: 0 | Y27: 0 | Z27: 0 | AA27: 0 | AB27: 0 | AC27: 0 | AD27: 0 | AE27: 0 | AF27: 0 | AG27: 0 | AH27: 0 | AI27: 0 | AJ27: 0 | AK27: 0 | AL27: 0
A28: Gas CCGT & Cogen | B28: MW | C28: 235.71 | D28: 235.71 | E28: 235.71 | F28: 235.71 | G28: 235.71 | H28: 235.71 | I28: 235.71 | J28: 235.71 | K28: 235.71 | L28: 235.71 | M28: 235.71 | N28: 235.71 | O28: 235.71 | P28: 235.71 | Q28: 235.71 | R28: 235.71 | S28: 235.71 | T28: 235.71 | U28: 235.71 | V28: 235.71 | W28: 235.71 | X28: 235.71 | Y28: 0 | Z28: 0 | AA28: 0 | AB28: 0 | AC28: 0 | AD28: 0 | AE28: 0 | AF28: 0 | AG28: 0 | AH28: 0 | AI28: 0 | AJ28: 0 | AK28: 0 | AL28: 0
A29: Gas CC CCS | B29: MW | C29: 0 | D29: 0 | E29: 0 | F29: 0 | G29: 0 | H29: 0 | I29: 0 | J29: 0 | K29: 0 | L29: 0 | M29: 0 | N29: 0 | O29: 0 | P29: 0 | Q29: 0 | R29: 0 | S29: 0 | T29: 0 | U29: 0 | V29: 0 | W29: 0 | X29: 0 | Y29: 0 | Z29: 0 | AA29: 0 | AB29: 0 | AC29: 0 | AD29: 0 | AE29: 0 | AF29: 0 | AG29: 0 | AH29: 0 | AI29: 0 | AJ29: 0 | AK29: 0 | AL29: 0
A30: Gas Steam | B30: MW | C30: 0 | D30: 0 | E30: 0 | F30: 0 | G30: 0 | H30: 0 | I30: 0 | J30: 0 | K30: 0 | L30: 0 | M30: 0 | N30: 0 | O30: 0 | P30: 0 | Q30: 0 | R30: 0 | S30: 0 | T30: 0 | U30: 0 | V30: 0 | W30: 0 | X30: 0 | Y30: 0 | Z30: 0 | AA30: 0 | AB30: 0 | AC30: 0 | AD30: 0 | AE30: 0 | AF30: 0 | AG30: 0 | AH30: 0 | AI30: 0 | AJ30: 0 | AK30: 0 | AL30: 0
A31: Distillate | B31: MW | C31: 0 | D31: 0 | E31: 0 | F31: 0 | G31: 0 | H31: 0 | I31: 0 | J31: 0 | K31: 0 | L31: 0 | M31: 0 | N31: 0 | O31: 0 | P31: 0 | Q31: 0 | R31: 0 | S31: 0 | T31: 0 | U31: 0 | V31: 0 | W31: 0 | X31: 0 | Y31: 0 | Z31: 0 | AA31: 0 | AB31: 0 | AC31: 0 | AD31: 0 | AE31: 0 | AF31: 0 | AG31: 0 | AH31: 0 | AI31: 0 | AJ31: 0 | AK31: 0 | AL31: 0
A32: Hydro | B32: MW | C32: 202.495 | D32: 202.495 | E32: 202.495 | F32: 202.495 | G32: 202.495 | H32: 202.495 | I32: 202.495 | J32: 202.495 | K32: 202.495 | L32: 202.495 | M32: 202.495 | N32: 202.495 | O32: 202.495 | P32: 202.495 | Q32: 202.495 | R32: 202.495 | S32: 202.495 | T32: 202.495 | U32: 202.495 | V32: 202.495 | W32: 202.495 | X32: 202.495 | Y32: 202.495 | Z32: 202.495 | AA32: 202.495 | AB32: 202.495 | AC32: 202.495 | AD32: 202.495 | AE32: 202.495 | AF32: 202.495 | AG32: 202.495 | AH32: 202.495 | AI32: 202.495 | AJ32: 202.495 | AK32: 202.495 | AL32: 202.495
A33: Wind | B33: MW | C33: 401.65 | D33: 401.65 | E33: 401.65 | F33: 474.75 | G33: 882.75 | H33: 882.75 | I33: 882.75 | J33: 882.75 | K33: 882.75 | L33: 1282.75 | M33: 1882.75 | N33: 2082.75 | O33: 2082.75 | P33: 2482.75 | Q33: 2482.75 | R33: 2882.75 | S33: 3682.75 | T33: 3682.75 | U33: 4282.75 | V33: 4282.75 | W33: 4482.75 | X33: 4482.75 | Y33: 4682.75 | Z33: 4682.75 | AA33: 4682.75 | AB33: 4682.75 | AC33: 4882.75 | AD33: 4882.75 | AE33: 4882.75 | AF33: 5282.75 | AG33: 5282.75 | AH33: 5282.75 | AI33: 5282.75 | AJ33: 6282.75 | AK33: 6682.75 | AL33: 6682.75
A34: Biomass | B34: MW | C34: 58.7125 | D34: 58.7125 | E34: 58.7125 | F34: 58.7125 | G34: 58.7125 | H34: 58.7125 | I34: 58.7125 | J34: 58.7125 | K34: 58.7125 | L34: 58.7125 | M34: 58.7125 | N34: 58.7125 | O34: 58.7125 | P34: 58.7125 | Q34: 58.7125 | R34: 58.7125 | S34: 58.7125 | T34: 58.7125 | U34: 58.7125 | V34: 58.7125 | W34: 58.7125 | X34: 58.7125 | Y34: 58.7125 | Z34: 58.7125 | AA34: 58.7125 | AB34: 58.7125 | AC34: 58.7125 | AD34: 58.7125 | AE34: 58.7125 | AF34: 58.7125 | AG34: 58.7125 | AH34: 58.7125 | AI34: 58.7125 | AJ34: 58.7125 | AK34: 58.7125 | AL34: 58.7125
A35: Solar | B35: MW | C35: 513.24 | D35: 513.24 | E35: 513.24 | F35: 727.04 | G35: 877.04 | H35: 877.04 | I35: 877.04 | J35: 877.04 | K35: 877.04 | L35: 877.04 | M35: 877.04 | N35: 877.04 | O35: 877.04 | P35: 987.04 | Q35: 987.04 | R35: 987.04 | S35: 987.04 | T35: 987.04 | U35: 987.04 | V35: 987.04 | W35: 987.04 | X35: 1387.04 | Y35: 1387.04 | Z35: 1387.04 | AA35: 1387.04 | AB35: 1587.04 | AC35: 1787.04 | AD35: 1787.04 | AE35: 2187.04 | AF35: 2187.04 | AG35: 2837.04 | AH35: 2837.04 | AI35: 2837.04 | AJ35: 2837.04 | AK35: 2837.04 | AL35: 2837.04
... A42: Total | B42: MW | C42: 2835.9158 | D42: 3198.9124 | E42: 3321.4015 | F42: 4190.6412 | G42: 5011.462 | H42: 5127.423 | I42: 5275.1321 | J42: 6174.6375 | K42: 6047.3173 | L42: 6592.6024 | M42: 7332.8141 | N42: 7676.1704 | O42: 7847.221 | P42: 8542.8043 | Q42: 8730.281 | R42: 9500.018 | S42: 10453.62 | T42: 10627.131 | U42: 11413.668 | V42: 11760.946 | W42: 12001.982 | X42: 12578.628 | Y42: 12725.182 | Z42: 12897.821 | AA42: 13070.463 | AB42: 13431.872 | AC42: 13961.267 | AD42: 14108.16 | AE42: 14652.578 | AF42: 15198.267 | AG42: 15994.939 | AH42: 16139.728 | AI42: 16283.625 | AJ42: 17427.367 | AK42: 17970.463 | AL42: 18115.457
A43: Queensland Central
A44: Black Coal | B44: MW | C44: 4300.8 | D44: 4300.8 | E44: 4300.8 | F44: 4300.8 | G44: 4300.8 | H44: 4300.8 | I44: 3663.8 | J44: 3663.8 | K44: 3663.8 | L44: 3663.8 | M44: 2118.2 | N44: 2118.2 | O44: 2118.2 | P44: 2118.2 | Q44: 2118.2 | R44: 2118.2 | S44: 2118.2 | T44: 2118.2 | U44: 1786.05 | V44: 1453.9 | W44: 1121.75 | X44: 789.6 | Y44: 789.6 | Z44: 789.6 | AA44: 789.6 | AB44: 789.6 | AC44: 0 | AD44: 0 | AE44: 0 | AF44: 0 | AG44: 0 | AH44: 0 | AI44: 0 | AJ44: 0 | AK44: 0 | AL44: 0
A45: Brown Coal | B45: MW | C45: 0 | D45: 0 | E45: 0 | F45: 0 | G45: 0 | H45: 0 | I45: 0 | J45: 0 | K45: 0 | L45: 0 | M45: 0 | N45: 0 | O45: 0 | P45: 0 | Q45: 0 | R45: 0 | S45: 0 | T45: 0 | U45: 0 | V45: 0 | W45: 0 | X45: 0 | Y45: 0 | Z45: 0 | AA45: 0 | AB45: 0 | AC45: 0 | AD45: 0 | AE45: 0 | AF45: 0 | AG45: 0 | AH45: 0 | AI45: 0 | AJ45: 0 | AK45: 0 | AL45: 0
A46: Hydrogen ready | B46: MW | C46: 0 | D46: 0 | E46: 0 | F46: 0 | G46: 380 | H46: 380 | I46: 380 | J46: 380 | K46: 380 | L46: 380 | M46: 380 | N46: 760 | O46: 1306.2 | P46: 1789 | Q46: 1789 | R46: 1789 | S46: 1789 | T46: 1789 | U46: 1789 | V46: 1789 | W46: 1789 | X46: 1789 | Y46: 2210.6 | Z46: 2590.6 | AA46: 2590.6 | AB46: 2590.6 | AC46: 2590.6 | AD46: 2590.6 | AE46: 2590.6 | AF46: 2590.6 | AG46: 2590.6 | AH46: 2590.6 | AI46: 2590.6 | AJ46: 2590.6 | AK46: 2590.6 | AL46: 2590.6
A47: Gas GT | B47: MW | C47: 82.42 | D47: 82.42 | E47: 82.42 | F47: 82.42 | G47: 82.42 | H47: 82.42 | I47: 82.42 | J47: 82.42 | K47: 82.42 | L47: 82.42 | M47: 45.6 | N47: 45.6 | O47: 45.6 | P47: 45.6 | Q47: 45.6 | R47: 45.6 | S47: 45.6 | T47: 45.6 | U47: 45.6 | V47: 45.6 | W47: 45.6 | X47: 45.6 | Y47: 45.6 | Z47: 45.6 | AA47: 45.6 | AB47: 45.6 | AC47: 45.6 | AD47: 45.6 | AE47: 45.6 | AF47: 45.6 | AG47: 45.6 | AH47: 45.6 | AI47: 45.6 | AJ47: 45.6 | AK47: 45.6 | AL47: 45.6
A48: Gas CCGT & Cogen | B48: MW | C48: 156.8 | D48: 156.8 | E48: 156.8 | F48: 156.8 | G48: 156.8 | H48: 156.8 | I48: 156.8 | J48: 156.8 | K48: 156.8 | L48: 156.8 | M48: 156.8 | N48: 156.8 | O48: 206.8 | P48: 206.8 | Q48: 206.8 | R48: 206.8 | S48: 206.8 | T48: 206.8 | U48: 206.8 | V48: 206.8 | W48: 206.8 | X48: 206.8 | Y48: 206.8 | Z48: 206.8 | AA48: 206.8 | AB48: 206.8 | AC48: 206.8 | AD48: 206.8 | AE48: 206.8 | AF48: 206.8 | AG48: 206.8 | AH48: 206.8 | AI48: 206.8 | AJ48: 206.8 | AK48: 206.8 | AL48: 206.8
A49: Gas CC CCS | B49: MW | C49: 0 | D49: 0 | E49: 0 | F49: 0 | G49: 0 | H49: 0 | I49: 0 | J49: 0 | K49: 0 | L49: 0 | M49: 0 | N49: 0 | O49: 0 | P49: 0 | Q49: 0 | R49: 0 | S49: 0 | T49: 0 | U49: 0 | V49: 0 | W49: 0 | X49: 0 | Y49: 0 | Z49: 0 | AA49: 0 | AB49: 0 | AC49: 0 | AD49: 0 | AE49: 0 | AF49: 0 | AG49: 0 | AH49: 0 | AI49: 0 | AJ49: 0 | AK49: 0 | AL49: 0
A50: Gas Steam | B50: MW | C50: 0 | D50: 0 | E50: 0 | F50: 0 | G50: 0 | H50: 0 | I50: 0 | J50: 0 | K50: 0 | L50: 0 | M50: 0 | N50: 0 | O50: 0 | P50: 0 | Q50: 0 | R50: 0 | S50: 0 | T50: 0 | U50: 0 | V50: 0 | W50: 0 | X50: 0 | Y50: 0 | Z50: 0 | AA50: 0 | AB50: 0 | AC50: 0 | AD50: 0 | AE50: 0 | AF50: 0 | AG50: 0 | AH50: 0 | AI50: 0 | AJ50: 0 | AK50: 0 | AL50: 0
A51: Distillate | B51: MW | C51: 0 | D51: 0 | E51: 0 | F51: 0 | G51: 0 | H51: 0 | I51: 0 | J51: 0 | K51: 0 | L51: 0 | M51: 0 | N51: 0 | O51: 0 | P51: 0 | Q51: 0 | R51: 0 | S51: 0 | T51: 0 | U51: 0 | V51: 0 | W51: 0 | X51: 0 | Y51: 0 | Z51: 0 | AA51: 0 | AB51: 0 | AC51: 0 | AD51: 0 | AE51: 0 | AF51: 0 | AG51: 0 | AH51: 0 | AI51: 0 | AJ51: 0 | AK51: 0 | AL51: 0
A52: Hydro | B52: MW | C52: 0 | D52: 0 | E52: 0 | F52: 0 | G52: 0 | H52: 0 | I52: 0 | J52: 0 | K52: 0 | L52: 0 | M52: 0 | N52: 0 | O52: 0 | P52: 0 | Q52: 0 | R52: 0 | S52: 0 | T52: 0 | U52: 0 | V52: 0 | W52: 0 | X52: 0 | Y52: 0 | Z52: 0 | AA52: 0 | AB52: 0 | AC52: 0 | AD52: 0 | AE52: 0 | AF52: 0 | AG52: 0 | AH52: 0 | AI52: 0 | AJ52: 0 | AK52: 0 | AL52: 0
...

Sheet NEM Generation
A1: Generation Sent Out
A2: Financial Year | C2: 2025 | D2: 2026 | E2: 2027 | F2: 2028 | G2: 2029 | H2: 2030 | I2: 2031 | J2: 2032 | K2: 2033 | L2: 2034 | M2: 2035 | N2: 2036 | O2: 2037 | P2: 2038 | Q2: 2039 | R2: 2040 | S2: 2041 | T2: 2042 | U2: 2043 | V2: 2044 | W2: 2045 | X2: 2046 | Y2: 2047 | Z2: 2048 | AA2: 2049 | AB2: 2050 | AC2: 2051 | AD2: 2052 | AE2: 2053 | AF2: 2054 | AG2: 2055 | AH2: 2056 | AI2: 2057 | AJ2: 2058 | AK2: 2059 | AL2: 2060
A3: Queensland South
A4: Black Coal | B4: GWh | C4: 18469.25 | D4: 18684.61 | E4: 17857.69 | F4: 16646.08 | G4: 15655.86 | H4: 15586.1 | I4: 16852.05 | J4: 17991.35 | K4: 19117.44 | L4: 19283.56 | M4: 19450.33 | N4: 17698.57 | O4: 12848.64 | P4: 9364.05 | Q4: 9439.3398 | R4: 9331.5701 | S4: 8945.04 | T4: 7060.6299 | U4: 5063.51 | V4: 5075.8301 | W4: 5069.0601 | X4: 4920.4299 | Y4: 4823.72 | Z4: 4921.74 | AA4: 4943.99 | AB4: 4889.6001 | AC4: 1665.5101 | AD4: 0 | AE4: 0 | AF4: 0 | AG4: 0 | AH4: 0 | AI4: 0 | AJ4: 0 | AK4: 0 | AL4: 0
A5: Brown Coal | B5: GWh | C5: 0 | D5: 0 | E5: 0 | F5: 0 | G5: 0 | H5: 0 | I5: 0 | J5: 0 | K5: 0 | L5: 0 | M5: 0 | N5: 0 | O5: 0 | P5: 0 | Q5: 0 | R5: 0 | S5: 0 | T5: 0 | U5: 0 | V5: 0 | W5: 0 | X5: 0 | Y5: 0 | Z5: 0 | AA5: 0 | AB5: 0 | AC5: 0 | AD5: 0 | AE5: 0 | AF5: 0 | AG5: 0 | AH5: 0 | AI5: 0 | AJ5: 0 | AK5: 0 | AL5: 0
A6: Hydrogen ready | B6: GWh | C6: 0 | D6: 0 | E6: 0 | F6: 0 | G6: 634.79999 | H6: 584.90002 | I6: 893.28003 | J6: 1287.36 | K6: 1588 | L6: 1805.59 | M6: 257.04 | N6: 282.69999 | O6: 301.7 | P6: 345.63001 | Q6: 327.82999 | R6: 328.6 | S6: 320.42 | T6: 334.52001 | U6: 260.52001 | V6: 423.31 | W6: 514.64001 | X6: 585.82999 | Y6: 941.85001 | Z6: 1602.08 | AA6: 1965.08 | AB6: 1899.87 | AC6: 2230.41 | AD6: 2854.34 | AE6: 3111.8599 | AF6: 2961.4999 | AG6: 2921.4001 | AH6: 3051.9101 | AI6: 3410.95 | AJ6: 3380.3001 | AK6: 3300.4301 | AL6: 3399.6498
A7: Gas GT | B7: GWh | C7: 3.4899999 | D7: 7.7299998 | E7: 17.79 | F7: 26.85 | G7: 13.72 | H7: 6.8800001 | I7: 12.99 | J7: 37.58 | K7: 61.76 | L7: 97.34 | M7: 484.15001 | N7: 535.3 | O7: 600.18002 | P7: 709.08001 | Q7: 673.04001 | R7: 749.62001 | S7: 774.14002 | T7: 843.98002 | U7: 894.25001 | V7: 980.43001 | W7: 1034.73 | X7: 1351.16 | Y7: 687.59997 | Z7: 730.18997 | AA7: 778.60999 | AB7: 738.12999 | AC7: 754.95002 | AD7: 839.97 | AE7: 834.18999 | AF7: 818.41001 | AG7: 804.89 | AH7: 809.47001 | AI7: 0 | AJ7: 0 | AK7: 0 | AL7: 0
A8: Gas CCGT & Cogen | B8: GWh | C8: 662.80002 | D8: 1044.1 | E8: 1269.17 | F8: 665.29 | G8: 259.82 | H8: 217.59 | I8: 370.91 | J8: 649.07999 | K8: 831.12 | L8: 1015.73 | M8: 2883.2 | N8: 3144.1 | O8: 3452.2 | P8: 3706.7201 | Q8: 3665.67 | R8: 3581.2599 | S8: 2776.3101 | T8: 2888.97 | U8: 3015.6201 | V8: 3073.6399 | W8: 3184.5 | X8: 240.89999 | Y8: 0 | Z8: 0 | AA8: 0 | AB8: 0 | AC8: 0 | AD8: 0 | AE8: 0 | AF8: 0 | AG8: 0 | AH8: 0 | AI8: 0 | AJ8: 0 | AK8: 0 | AL8: 0
A9: Gas CC CCS | B9: GWh | C9: 0 | D9: 0 | E9: 0 | F9: 0 | G9: 0 | H9: 0 | I9: 0 | J9: 0 | K9: 0 | L9: 0 | M9: 0 | N9: 0 | O9: 0 | P9: 0 | Q9: 0 | R9: 0 | S9: 0 | T9: 0 | U9: 0 | V9: 0 | W9: 0 | X9: 0 | Y9: 0 | Z9: 0 | AA9: 0 | AB9: 0 | AC9: 0 | AD9: 0 | AE9: 0 | AF9: 0 | AG9: 0 | AH9: 0 | AI9: 0 | AJ9: 0 | AK9: 0 | AL9: 0
A10: Gas Steam | B10: GWh | C10: 0 | D10: 0 | E10: 0 | F10: 0 | G10: 0 | H10: 0 | I10: 0 | J10: 0 | K10: 0 | L10: 0 | M10: 0 | N10: 0 | O10: 0 | P10: 0 | Q10: 0 | R10: 0 | S10: 0 | T10: 0 | U10: 0 | V10: 0 | W10: 0 | X10: 0 | Y10: 0 | Z10: 0 | AA10: 0 | AB10: 0 | AC10: 0 | AD10: 0 | AE10: 0 | AF10: 0 | AG10: 0 | AH10: 0 | AI10: 0 | AJ10: 0 | AK10: 0 | AL10: 0
A11: Distillate | B11: GWh | C11: 0 | D11: 0 | E11: 0 | F11: 0 | G11: 0 | H11: 0 | I11: 0 | J11: 0 | K11: 0 | L11: 0 | M11: 0 | N11: 0 | O11: 0 | P11: 0 | Q11: 0 | R11: 0 | S11: 0 | T11: 0 | U11: 0 | V11: 0 | W11: 0 | X11: 0 | Y11: 0 | Z11: 0 | AA11: 0 | AB11: 0 | AC11: 0 | AD11: 0 | AE11: 0 | AF11: 0 | AG11: 0 | AH11: 0 | AI11: 0 | AJ11: 0 | AK11: 0 | AL11: 0
A12: Hydro | B12: GWh | C12: 66.220001 | D12: 66.220001 | E12: 66.220001 | F12: 66.220001 | G12: 66.220001 | H12: 66.220001 | I12: 66.220001 | J12: 66.220001 | K12: 66.220001 | L12: 66.220001 | M12: 66.220001 | N12: 66.220001 | O12: 66.220001 | P12: 66.220001 | Q12: 66.220001 | R12: 66.220001 | S12: 66.220001 | T12: 66.220001 | U12: 66.220001 | V12: 66.220001 | W12: 66.220001 | X12: 66.220001 | Y12: 66.220001 | Z12: 66.220001 | AA12: 66.220001 | AB12: 66.220001 | AC12: 66.220001 | AD12: 66.220001 | AE12: 66.220001 | AF12: 66.220001 | AG12: 66.220001 | AH12: 66.220001 | AI12: 66.220001 | AJ12: 66.220001 | AK12: 66.220001 | AL12: 66.220001
A13: Wind | B13: GWh | C13: 5258.4647 | D13: 5209.1739 | E13: 5043.8157 | F13: 4977.7798 | G13: 4885.761 | H13: 4956.6368 | I13: 5146.4005 | J13: 5268.1931 | K13: 5283.3571 | L13: 5276.4692 | M13: 5277.6423 | N13: 5280.3038 | O13: 5284.8539 | P13: 5283.3657 | Q13: 5289.0637 | R13: 5276.7932 | S13: 5241.2787 | T13: 5250.5159 | U13: 5737.7319 | V13: 6342.119 | W13: 6851.6246 | X13: 6811.521 | Y13: 6774.8825 | Z13: 6742.3778 | AA13: 6749.5328 | AB13: 7257.2699 | AC13: 7767.0108 | AD13: 7778.0817 | AE13: 7783.8814 | AF13: 7799.6389 | AG13: 7806.9618 | AH13: 7815.9452 | AI13: 7822.2955 | AJ13: 7792.0069 | AK13: 8885.4613 | AL13: 8877.426
A14: Biomass | B14: GWh | C14: 2118.5134 | D14: 2018.1733 | E14: 1923.8834 | F14: 1862.7833 | G14: 1779.3433 | H14: 1788.0233 | I14: 1882.7033 | J14: 2044.5933 | K14: 2109.6633 | L14: 2087.6833 | M14: 2078.7434 | N14: 2076.0633 | O14: 2052.9733 | P14: 2022.7233 | Q14: 2064.4733 | R14: 2015.9834 | S14: 1909.5034 | T14: 1899.3734 | U14: 1809.8233 | V14: 1804.8734 | W14: 1802.6234 | X14: 1752.8834 | Y14: 1727.5633 | Z14: 1750.9633 | AA14: 1745.0833 | AB14: 1721.7634 | AC14: 1631.8634 | AD14: 1709.2033 | AE14: 1697.5633 | AF14: 1671.0633 | AG14: 1632.3033 | AH14: 1655.4333 | AI14: 1652.9633 | AJ14: 1630.7833 | AK14: 1622.5633 | AL14: 1646.7833
A15: Solar | B15: GWh | C15: 4962.921 | D15: 7099.76 | E15: 9110.3382 | F15: 8991.0616 | G15: 9411.6213 | H15: 9548.1518 | I15: 9913.7006 | J15: 10148.314 | K15: 10177.525 | L15: 10164.257 | M15: 10524.439 | N15: 10529.746 | O15: 13494.327 | P15: 15173.611 | Q15: 15189.976 | R15: 17658.662 | S15: 17951.704 | T15: 17983.342 | U15: 17730.123 | V15: 17794.148 | W15: 18346.371 | X15: 19911.954 | Y15: 21838.401 | Z15: 21733.625 | AA15: 21756.688 | AB15: 22984.674 | AC15: 25258.194 | AD15: 26801.951 | AE15: 27226.898 | AF15: 27282.015 | AG15: 27307.63 | AH15: 27339.052 | AI15: 27361.265 | AJ15: 28091.013 | AK15: 28416.705 | AL15: 28794.893
... A22: Total | B22: GWh | C22: 38805.013 | D22: 42389.627 | E22: 44123.074 | F22: 43156.192 | G22: 43348.232 | H22: 44612.619 | I22: 49304.785 | J22: 52944.171 | K22: 55364.208 | L22: 57238.771 | M22: 59983.383 | N22: 59111.927 | O22: 58222.319 | P22: 57581.092 | Q22: 58229.119 | R22: 61437.907 | S22: 61222.931 | T22: 60436.551 | U22: 59168.468 | V22: 61228.772 | W22: 63333.34 | X22: 62739.445 | Y22: 65186.7 | Z22: 66341.908 | AA22: 67362.158 | AB22: 69407.221 | AC22: 70243.088 | AD22: 72281.02 | AE22: 74114.143 | AF22: 74850.119 | AG22: 75553.582 | AH22: 76465.839 | AI22: 76657.487 | AJ22: 78125.284 | AK22: 80117.109 | AL22: 80960.152
A23: Queensland North
A24: Black Coal | B24: GWh | C24: 0 | D24: 0 | E24: 0 | F24: 0 | G24: 0 | H24: 0 | I24: 0 | J24: 0 | K24: 0 | L24: 0 | M24: 0 | N24: 0 | O24: 0 | P24: 0 | Q24: 0 | R24: 0 | S24: 0 | T24: 0 | U24: 0 | V24: 0 | W24: 0 | X24: 0 | Y24: 0 | Z24: 0 | AA24: 0 | AB24: 0 | AC24: 0 | AD24: 0 | AE24: 0 | AF24: 0 | AG24: 0 | AH24: 0 | AI24: 0 | AJ24: 0 | AK24: 0 | AL24: 0
A25: Brown Coal | B25: GWh | C25: 0 | D25: 0 | E25: 0 | F25: 0 | G25: 0 | H25: 0 | I25: 0 | J25: 0 | K25: 0 | L25: 0 | M25: 0 | N25: 0 | O25: 0 | P25: 0 | Q25: 0 | R25: 0 | S25: 0 | T25: 0 | U25: 0 | V25: 0 | W25: 0 | X25: 0 | Y25: 0 | Z25: 0 | AA25: 0 | AB25: 0 | AC25: 0 | AD25: 0 | AE25: 0 | AF25: 0 | AG25: 0 | AH25: 0 | AI25: 0 | AJ25: 0 | AK25: 0 | AL25: 0
A26: Hydrogen ready | B26: GWh | C26: 0 | D26: 0 | E26: 0 | F26: 0 | G26: 0 | H26: 0 | I26: 0 | J26: 0 | K26: 0 | L26: 0 | M26: 0 | N26: 0 | O26: 0 | P26: 0 | Q26: 0 | R26: 120.15 | S26: 167.31 | T26: 176.45 | U26: 344.73 | V26: 231.69999 | W26: 245.69 | X26: 451.56999 | Y26: 396.41002 | Z26: 258.26 | AA26: 267.95 | AB26: 187.78 | AC26: 268.85 | AD26: 357.24 | AE26: 408.50999 | AF26: 437.13999 | AG26: 428.84999 | AH26: 344.50999 | AI26: 493.56001 | AJ26: 499.38 | AK26: 481.85001 | AL26: 391.29999
A27: Gas GT | B27: GWh | C27: 1.56 | D27: 1.44 | E27: 1.5399999 | F27: 1.43 | G27: 1.25 | H27: 1.05 | I27: 2.58 | J27: 6.7700001 | K27: 5.9400001 | L27: 5.4699998 | M27: 5.8299999 | N27: 6.1399999 | O27: 6.4299998 | P27: 6.2800002 | Q27: 6.21 | R27: 5.6300001 | S27: 6.3800001 | T27: 6.4200001 | U27: 5.75 | V27: 4.1900001 | W27: 0 | X27: 0 | Y27: 0 | Z27: 0 | AA27: 0 | AB27: 0 | AC27: 0 | AD27: 0 | AE27: 0 | AF27: 0 | AG27: 0 | AH27: 0 | AI27: 0 | AJ27: 0 | AK27: 0 | AL27: 0
A28: Gas CCGT & Cogen | B28: GWh | C28: 103.64 | D28: 96.269997 | E28: 105.01 | F28: 91.169998 | G28: 73.220001 | H28: 56.860001 | I28: 196.83 | J28: 414.35999 | K28: 431.94 | L28: 419.67999 | M28: 505.67999 | N28: 533.65997 | O28: 529.54999 | P28: 523.69 | Q28: 515.97998 | R28: 469.60001 | S28: 393.42999 | T28: 384.22 | U28: 393.28 | V28: 191.84 | W28: 128.94 | X28: 143.41 | Y28: 0 | Z28: 0 | AA28: 0 | AB28: 0 | AC28: 0 | AD28: 0 | AE28: 0 | AF28: 0 | AG28: 0 | AH28: 0 | AI28: 0 | AJ28: 0 | AK28: 0 | AL28: 0
A29: Gas CC CCS | B29: GWh | C29: 0 | D29: 0 | E29: 0 | F29: 0 | G29: 0 | H29: 0 | I29: 0 | J29: 0 | K29: 0 | L29: 0 | M29: 0 | N29: 0 | O29: 0 | P29: 0 | Q29: 0 | R29: 0 | S29: 0 | T29: 0 | U29: 0 | V29: 0 | W29: 0 | X29: 0 | Y29: 0 | Z29: 0 | AA29: 0 | AB29: 0 | AC29: 0 | AD29: 0 | AE29: 0 | AF29: 0 | AG29: 0 | AH29: 0 | AI29: 0 | AJ29: 0 | AK29: 0 | AL29: 0
A30: Gas Steam | B30: GWh | C30: 0 | D30: 0 | E30: 0 | F30: 0 | G30: 0 | H30: 0 | I30: 0 | J30: 0 | K30: 0 | L30: 0 | M30: 0 | N30: 0 | O30: 0 | P30: 0 | Q30: 0 | R30: 0 | S30: 0 | T30: 0 | U30: 0 | V30: 0 | W30: 0 | X30: 0 | Y30: 0 | Z30: 0 | AA30: 0 | AB30: 0 | AC30: 0 | AD30: 0 | AE30: 0 | AF30: 0 | AG30: 0 | AH30: 0 | AI30: 0 | AJ30: 0 | AK30: 0 | AL30: 0
A31: Distillate | B31: GWh | C31: 0 | D31: 0 | E31: 0 | F31: 0 | G31: 0 | H31: 0 | I31: 0 | J31: 0 | K31: 0 | L31: 0 | M31: 0 | N31: 0 | O31: 0 | P31: 0 | Q31: 0 | R31: 0 | S31: 0 | T31: 0 | U31: 0 | V31: 0 | W31: 0 | X31: 0 | Y31: 0 | Z31: 0 | AA31: 0 | AB31: 0 | AC31: 0 | AD31: 0 | AE31: 0 | AF31: 0 | AG31: 0 | AH31: 0 | AI31: 0 | AJ31: 0 | AK31: 0 | AL31: 0
A32: Hydro | B32: GWh | C32: 591.08002 | D32: 591.08002 | E32: 591.07001 | F32: 591.08002 | G32: 591.08002 | H32: 591.08002 | I32: 591.08002 | J32: 591.08002 | K32: 591.08002 | L32: 591.08002 | M32: 591.08002 | N32: 591.07001 | O32: 591.08002 | P32: 591.08002 | Q32: 591.08002 | R32: 591.08002 | S32: 591.08002 | T32: 591.07001 | U32: 591.08002 | V32: 591.08002 | W32: 591.08002 | X32: 591.08002 | Y32: 591.08002 | Z32: 591.08002 | AA32: 591.08002 | AB32: 591.08002 | AC32: 591.08002 | AD32: 591.08002 | AE32: 591.07001 | AF32: 591.08002 | AG32: 591.08002 | AH32: 591.08002 | AI32: 591.08002 | AJ32: 591.08002 | AK32: 591.08002 | AL32: 591.08002
A33: Wind | B33: GWh | C33: 1151.9252 | D33: 1151.9252 | E33: 1151.9252 | F33: 1366.3589 | G33: 2589.5865 | H33: 2603.5726 | I33: 2605.5411 | J33: 2606.0286 | K33: 2606.0286 | L33: 3952.9278 | M33: 5844.7763 | N33: 6514.1209 | O33: 6526.4604 | P33: 7586.0807 | Q33: 7586.0807 | R33: 8973.8892 | S33: 11281.751 | T33: 11291.037 | U33: 12763.82 | V33: 12754.216 | W33: 13508.766 | X33: 13352.696 | Y33: 14102.462 | Z33: 14053.171 | AA33: 14082.771 | AB33: 14035.192 | AC33: 14462.973 | AD33: 14566.779 | AE33: 14433.792 | AF33: 15650.503 | AG33: 15193.445 | AH33: 15280.042 | AI33: 15400.923 | AJ33: 18065.76 | AK33: 18933.536 | AL33: 19031.443
A34: Biomass | B34: GWh | C34: 280.27999 | D34: 267.2 | E34: 254.12 | F34: 240.65001 | G34: 201.52 | H34: 206.06001 | I34: 245.45 | J34: 272.18001 | K34: 287.32999 | L34: 284.31 | M34: 283.46001 | N34: 284.69 | O34: 281.77 | P34: 281.65001 | Q34: 283.63 | R34: 278.38999 | S34: 253.02 | T34: 254.38 | U34: 246.37999 | V34: 216.75 | W34: 211.56001 | X34: 210.37 | Y34: 10.54 | Z34: 11.05 | AA34: 12.41 | AB34: 11.49 | AC34: 11.87 | AD34: 14.06 | AE34: 11.51 | AF34: 12.04 | AG34: 13.58 | AH34: 12.7 | AI34: 13.75 | AJ34: 14.82 | AK34: 14.45 | AL34: 15.54
A35: Solar | B35: GWh | C35: 843.3596 | D35: 843.3596 | E35: 843.3596 | F35: 1363.0398 | G35: 1726.8437 | H35: 1736.1702 | I35: 1737.4829 | J35: 1737.8079 | K35: 1737.8079 | L35: 1737.8079 | M35: 1735.2826 | N35: 1734.4501 | O35: 1737.7356 | P35: 2021.1063 | Q35: 2021.1063 | R35: 2020.6181 | S35: 2006.4691 | T35: 2008.1207 | U35: 1980.7793 | V35: 1979.289 | W35: 1983.3318 | X35: 2831.1007 | Y35: 2840.4459 | Z35: 2830.5179 | AA35: 2836.4799 | AB35: 3285.5049 | AC35: 3671.191 | AD35: 3697.5406 | AE35: 4394.6297 | AF35: 4364.9889 | AG35: 5690.6381 | AH35: 5723.0725 | AI35: 5768.3479 | AJ35: 5650.087 | AK35: 5614.0112 | AL35: 5643.0417
... A42: Total | B42: GWh | C42: 4224.4493 | D42: 4693.0595 | E42: 4845.6415 | F42: 5867.4535 | G42: 7548.8454 | H42: 7706.6139 | I42: 8065.1011 | J42: 8960.7757 | K42: 9027.1347 | L42: 10690.052 | M42: 14428.668 | N42: 15752.947 | O42: 16912.33 | P42: 18582.594 | Q42: 18855.499 | R42: 20732.021 | S42: 22994.481 | T42: 23532.991 | U42: 24988.584 | V42: 25037.049 | W42: 25910.874 | X42: 26713.025 | Y42: 27653.773 | Z42: 27744.252 | AA42: 28198.184 | AB42: 28353.694 | AC42: 29282.464 | AD42: 29902.529 | AE42: 30274.542 | AF42: 31681.971 | AG42: 32080.293 | AH42: 32354.292 | AI42: 32741.06 | AJ42: 35321.767 | AK42: 36239.251 | AL42: 36552.473
A43: Queensland Central
A44: Black Coal | B44: GWh | C44: 18797.34 | D44: 17182.58 | E44: 16145.64 | F44: 15021.04 | G44: 17954.57 | H44: 17868.07 | I44: 17219.27 | J44: 14783.7 | K44: 15674.57 | L44: 16144.11 | M44: 11691.99 | N44: 11006.96 | O44: 11232.04 | P44: 11193.03 | Q44: 10242.49 | R44: 10493.66 | S44: 9042.3299 | T44: 10353.9 | U44: 8928.2899 | V44: 8081.54 | W44: 6291.5499 | X44: 5125.9298 | Y44: 4697.3699 | Z44: 4758.4199 | AA44: 4725.5999 | AB44: 4697.9001 | AC44: 2453.2899 | AD44: 0 | AE44: 0 | AF44: 0 | AG44: 0 | AH44: 0 | AI44: 0 | AJ44: 0 | AK44: 0 | AL44: 0
A45: Brown Coal | B45: GWh | C45: 0 | D45: 0 | E45: 0 | F45: 0 | G45: 0 | H45: 0 | I45: 0 | J45: 0 | K45: 0 | L45: 0 | M45: 0 | N45: 0 | O45: 0 | P45: 0 | Q45: 0 | R45: 0 | S45: 0 | T45: 0 | U45: 0 | V45: 0 | W45: 0 | X45: 0 | Y45: 0 | Z45: 0 | AA45: 0 | AB45: 0 | AC45: 0 | AD45: 0 | AE45: 0 | AF45: 0 | AG45: 0 | AH45: 0 | AI45: 0 | AJ45: 0 | AK45: 0 | AL45: 0
A46: Hydrogen ready | B46: GWh | C46: 0 | D46: 0 | E46: 0 | F46: 0 | G46: 207.64 | H46: 183.27 | I46: 304.95001 | J46: 546.65002 | K46: 648.06 | L46: 737.82001 | M46: 112.21 | N46: 432.51001 | O46: 677.05999 | P46: 713.28001 | Q46: 692.11002 | R46: 852.30002 | S46: 790.45999 | T46: 800.63998 | U46: 844.86998 | V46: 1110.47 | W46: 1284.65 | X46: 1683.66 | Y46: 2405.35 | Z46: 2272.12 | AA46: 2544.4301 | AB46: 2183.6199 | AC46: 3317.97 | AD46: 4475.74 | AE46: 4834.76 | AF46: 4581.2101 | AG46: 4272.45 | AH46: 4332.45 | AI46: 4737.7801 | AJ46: 4235.04 | AK46: 4080.18 | AL46: 4318.5001
A47: Gas GT | B47: GWh | C47: 10.91 | D47: 7.7900002 | E47: 8.3700001 | F47: 5.6299998 | G47: 7.5899998 | H47: 6.4499998 | I47: 19.01 | J47: 40.820001 | K47: 52.149999 | L47: 63.579998 | M47: 88.93 | N47: 136.05 | O47: 166.99001 | P47: 176.55 | Q47: 183.46001 | R47: 176.99001 | S47: 169.23 | T47: 135.33 | U47: 138.38 | V47: 150.31 | W47: 169.89999 | X47: 183.53999 | Y47: 181.42 | Z47: 187.07001 | AA47: 193.84 | AB47: 172.53 | AC47: 188.21001 | AD47: 215 | AE47: 221.61 | AF47: 214.59 | AG47: 203.14999 | AH47: 205.12 | AI47: 204.92 | AJ47: 196.48 | AK47: 192.53 | AL47: 201.37
A48: Gas CCGT & Cogen | B48: GWh | C48: 257.07001 | D48: 233.09 | E48: 232.00999 | F48: 214.32001 | G48: 217.84 | H48: 213.72 | I48: 239.33 | J48: 284.67999 | K48: 312.79001 | L48: 325.95999 | M48: 430.07001 | N48: 528.37 | O48: 805.71997 | P48: 826.38 | Q48: 842.71002 | R48: 836.20001 | S48: 791.45001 | T48: 691.40997 | U48: 696.38 | V48: 742.91998 | W48: 801.54999 | X48: 864.60999 | Y48: 864.40002 | Z48: 865.40002 | AA48: 889.58002 | AB48: 810.42999 | AC48: 345.64999 | AD48: 373.07999 | AE48: 383.34 | AF48: 368.09 | AG48: 355.73999 | AH48: 363.89999 | AI48: 402.51999 | AJ48: 380.51001 | AK48: 369.14001 | AL48: 369.29999
A49: Gas CC CCS | B49: GWh | C49: 0 | D49: 0 | E49: 0 | F49: 0 | G49: 0 | H49: 0 | I49: 0 | J49: 0 | K49: 0 | L49: 0 | M49: 0 | N49: 0 | O49: 0 | P49: 0 | Q49: 0 | R49: 0 | S49: 0 | T49: 0 | U49: 0 | V49: 0 | W49: 0 | X49: 0 | Y49: 0 | Z49: 0 | AA49: 0 | AB49: 0 | AC49: 0 | AD49: 0 | AE49: 0 | AF49: 0 | AG49: 0 | AH49: 0 | AI49: 0 | AJ49: 0 | AK49: 0 | AL49: 0
A50: Gas Steam | B50: GWh | C50: 0 | D50: 0 | E50: 0 | F50: 0 | G50: 0 | H50: 0 | I50: 0 | J50: 0 | K50: 0 | L50: 0 | M50: 0 | N50: 0 | O50: 0 | P50: 0 | Q50: 0 | R50: 0 | S50: 0 | T50: 0 | U50: 0 | V50: 0 | W50: 0 | X50: 0 | Y50: 0 | Z50: 0 | AA50: 0 | AB50: 0 | AC50: 0 | AD50: 0 | AE50: 0 | AF50: 0 | AG50: 0 | AH50: 0 | AI50: 0 | AJ50: 0 | AK50: 0 | AL50: 0
A51: Distillate | B51: GWh | C51: 0 | D51: 0 | E51: 0 | F51: 0 | G51: 0 | H51: 0 | I51: 0 | J51: 0 | K51: 0 | L51: 0 | M51: 0 | N51: 0 | O51: 0 | P51: 0 | Q51: 0 | R51: 0 | S51: 0 | T51: 0 | U51: 0 | V51: 0 | W51: 0 | X51: 0 | Y51: 0 | Z51: 0 | AA51: 0 | AB51: 0 | AC51: 0 | AD51: 0 | AE51: 0 | AF51: 0 | AG51: 0 | AH51: 0 | AI51: 0 | AJ51: 0 | AK51: 0 | AL51: 0
A52: Hydro | B52: GWh | C52: 0 | D52: 0 | E52: 0 | F52: 0 | G52: 0 | H52: 0 | I52: 0 | J52: 0 | K52: 0 | L52: 0 | M52: 0 | N52: 0 | O52: 0 | P52: 0 | Q52: 0 | R52: 0 | S52: 0 | T52: 0 | U52: 0 | V52: 0 | W52: 0 | X52: 0 | Y52: 0 | Z52: 0 | AA52: 0 | AB52: 0 | AC52: 0 | AD52: 0 | AE52: 0 | AF52: 0 | AG52: 0 | AH52: 0 | AI52: 0 | AJ52: 0 | AK52: 0 | AL52: 0
...

Sheet CoalRetirements
A1: Coal Plant Installed Capacity (MW)
A2: Plant | B2: Type | C2: State | D2: 2025 | E2: 2026 | F2: 2027 | G2: 2028 | H2: 2029 | I2: 2030 | J2: 2031 | K2: 2032 | L2: 2033 | M2: 2034 | N2: 2035 | O2: 2036 | P2: 2037 | Q2: 2038 | R2: 2039 | S2: 2040 | T2: 2041 | U2: 2042 | V2: 2043 | W2: 2044 | X2: 2045 | Y2: 2046 | Z2: 2047 | AA2: 2048 | AB2: 2049 | AC2: 2050 | AD2: 2051 | AE2: 2052 | AF2: 2053 | AG2: 2054 | AH2: 2055 | AI2: 2056 | AJ2: 2057 | AK2: 2058 | AL2: 2059 | AM2: 2060
A3: LYA | B3: Brown Coal | C3: Victoria | D3: 2031.12 | E3: 2031.12 | F3: 2031.12 | G3: 2031.12 | H3: 2031.12 | I3: 2031.12 | J3: 2031.12 | K3: 2031.12 | L3: 2031.12 | M3: 2031.12 | N3: 1523.34
A4: LYB | B4: Brown Coal | C4: Victoria | D4: 984.4 | E4: 984.4 | F4: 984.4 | G4: 984.4 | H4: 984.4 | I4: 984.4 | J4: 984.4 | K4: 984.4 | L4: 984.4 | M4: 984.4 | N4: 984.4 | O4: 984.4 | P4: 984.4 | Q4: 984.4 | R4: 984.4 | S4: 984.4 | T4: 984.4 | U4: 984.4 | V4: 984.4 | W4: 984.4 | X4: 984.4 | Y4: 984.4 | Z4: 984.4
A5: YALL | B5: Brown Coal | C5: Victoria | D5: 1375.2 | E5: 1375.2 | F5: 1375.2 | G5: 1375.2 | H5: 1375.2
A6: BAYSWATR | B6: Black Coal | C6: New South Wales | D6: 2481.6 | E6: 2481.6 | F6: 2481.6 | G6: 2481.6 | H6: 2481.6 | I6: 2481.6 | J6: 2481.6 | K6: 1240.8
A7: ERARING | B7: Black Coal | C7: New South Wales | D7: 2707.2 | E7: 1353.6 | F7: 1353.6 | G7: 1353.6
A8: MTPIPER | B8: Black Coal | C8: New South Wales | D8: 1330 | E8: 1330 | F8: 1330 | G8: 1330 | H8: 1330 | I8: 1330 | J8: 1330 | K8: 1330 | L8: 1330 | M8: 1330 | N8: 1330 | O8: 1330 | P8: 1330 | Q8: 1330 | R8: 1330 | S8: 1330
A9: LIDDELL | B9: Black Coal | C9: New South Wales
A10: VALESPNT | B10: Black Coal | C10: New South Wales | D10: 1254 | E10: 1254 | F10: 1254 | G10: 1254 | H10: 1254 | I10: 1254 | J10: 1254 | K10: 1254 | L10: 1254
A11: MILLMERN | B11: Black Coal | C11: Queensland South | D11: 800.88 | E11: 800.88 | F11: 800.88 | G11: 800.88 | H11: 800.88 | I11: 800.88 | J11: 800.88 | K11: 800.88 | L11: 800.88 | M11: 800.88 | N11: 800.88 | O11: 800.88 | P11: 800.88 | Q11: 800.88 | R11: 800.88 | S11: 800.88 | T11: 800.88 | U11: 800.88 | V11: 800.88 | W11: 800.88 | X11: 800.88 | Y11: 800.88 | Z11: 800.88 | AA11: 800.88 | AB11: 800.88 | AC11: 800.88
A12: TARONG | B12: Black Coal | C12: Queensland South | D12: 1288 | E12: 1288 | F12: 1288 | G12: 1288 | H12: 1288 | I12: 1288 | J12: 1288 | K12: 1288 | L12: 1288 | M12: 1288 | N12: 1288 | O12: 644
A13: TARONGN | B13: Black Coal | C13: Queensland South | D13: 416.42 | E13: 416.42 | F13: 416.42 | G13: 416.42 | H13: 416.42 | I13: 416.42 | J13: 416.42 | K13: 416.42 | L13: 416.42 | M13: 416.42 | N13: 416.42 | O13: 416.42
A14: KoganCrk | B14: Black Coal | C14: Queensland South | D14: 677.04 | E14: 677.04 | F14: 677.04 | G14: 677.04 | H14: 677.04 | I14: 677.04 | J14: 677.04 | K14: 677.04 | L14: 677.04 | M14: 677.04 | N14: 677.04 | O14: 677.04 | P14: 677.04 | Q14: 677.04 | R14: 677.04 | S14: 677.04 | T14: 677.04
A15: CALLIDEC | B15: Black Coal | C15: Queensland Central | D15: 789.6 | E15: 789.6 | F15: 789.6 | G15: 789.6 | H15: 789.6 | I15: 789.6 | J15: 789.6 | K15: 789.6 | L15: 789.6 | M15: 789.6 | N15: 789.6 | O15: 789.6 | P15: 789.6 | Q15: 789.6 | R15: 789.6 | S15: 789.6 | T15: 789.6 | U15: 789.6 | V15: 789.6 | W15: 789.6 | X15: 789.6 | Y15: 789.6 | Z15: 789.6 | AA15: 789.6 | AB15: 789.6 | AC15: 789.6
A16: CALLIDEB | B16: Black Coal | C16: Queensland Central | D16: 637 | E16: 637 | F16: 637 | G16: 637 | H16: 637 | I16: 637
A17: STANWELL | B17: Black Coal | C17: Queensland Central | D17: 1328.6 | E17: 1328.6 | F17: 1328.6 | G17: 1328.6 | H17: 1328.6 | I17: 1328.6 | J17: 1328.6 | K17: 1328.6 | L17: 1328.6 | M17: 1328.6 | N17: 1328.6 | O17: 1328.6 | P17: 1328.6 | Q17: 1328.6 | R17: 1328.6 | S17: 1328.6 | T17: 1328.6 | U17: 1328.6 | V17: 996.45 | W17: 664.3 | X17: 332.15
A18: GPS | B18: Black Coal | C18: Queensland Central | D18: 1545.6 | E18: 1545.6 | F18: 1545.6 | G18: 1545.6 | H18: 1545.6 | I18: 1545.6 | J18: 1545.6 | K18: 1545.6 | L18: 1545.6 | M18: 1545.6

Sheet NEM Emissions
A1: Emissions
A2: Financial Year | C2: 2025 | D2: 2026 | E2: 2027 | F2: 2028 | G2: 2029 | H2: 2030 | I2: 2031 | J2: 2032 | K2: 2033 | L2: 2034 | M2: 2035 | N2: 2036 | O2: 2037 | P2: 2038 | Q2: 2039 | R2: 2040 | S2: 2041 | T2: 2042 | U2: 2043 | V2: 2044 | W2: 2045 | X2: 2046 | Y2: 2047 | Z2: 2048 | AA2: 2049 | AB2: 2050 | AC2: 2051 | AD2: 2052 | AE2: 2053 | AF2: 2054 | AG2: 2055 | AH2: 2056 | AI2: 2057 | AJ2: 2058 | AK2: 2059 | AL2: 2060
A3: Queensland South
A4: Black Coal | B4: Mt CO2e | C4: 16.72849 | D4: 16.998495 | E4: 16.282403 | F4: 15.284321 | G4: 14.441741 | H4: 14.374529 | I4: 15.462668 | J4: 16.405623 | K4: 17.390672 | L4: 17.528387 | M4: 17.65988 | N4: 16.055474 | O4: 11.684445 | P4: 8.5751973 | Q4: 8.6385271 | R4: 8.5503541 | S4: 8.2220674 | T4: 6.5598017 | U4: 4.7991222 | V4: 4.8113199 | W4: 4.8037376 | X4: 4.6839811 | Y4: 4.6059623 | Z4: 4.6870748 | AA4: 4.7039644 | AB4: 4.6610461 | AC4: 1.602567 | AD4: 0 | AE4: 0 | AF4: 0 | AG4: 0 | AH4: 0 | AI4: 0 | AJ4: 0 | AK4: 0 | AL4: 0
A5: Brown Coal | B5: Mt CO2e | C5: 0 | D5: 0 | E5: 0 | F5: 0 | G5: 0 | H5: 0 | I5: 0 | J5: 0 | K5: 0 | L5: 0 | M5: 0 | N5: 0 | O5: 0 | P5: 0 | Q5: 0 | R5: 0 | S5: 0 | T5: 0 | U5: 0 | V5: 0 | W5: 0 | X5: 0 | Y5: 0 | Z5: 0 | AA5: 0 | AB5: 0 | AC5: 0 | AD5: 0 | AE5: 0 | AF5: 0 | AG5: 0 | AH5: 0 | AI5: 0 | AJ5: 0 | AK5: 0 | AL5: 0
A6: Hydrogen ready | B6: Mt CO2e | C6: 0 | D6: 0 | E6: 0 | F6: 0 | G6: 0.32325771 | H6: 0.29900237 | I6: 0.44941122 | J6: 0.63432289 | K6: 0.77503143 | L6: 0.87252998 | M6: 0 | N6: 0 | O6: 0 | P6: 0 | Q6: 0 | R6: 0 | S6: 0 | T6: 0 | U6: 0 | V6: 0 | W6: 0 | X6: 0 | Y6: 0 | Z6: 0 | AA6: 0 | AB6: 0 | AC6: 0 | AD6: 0 | AE6: 0 | AF6: 0 | AG6: 0 | AH6: 0 | AI6: 0 | AJ6: 0 | AK6: 0 | AL6: 0
A7: Gas GT | B7: Mt CO2e | C7: 0.0023706599 | D7: 0.00519045 | E7: 0.01173613 | F7: 0.01763729 | G7: 0.0088556399 | H7: 0.0045614401 | I7: 0.00852622 | J7: 0.02452796 | K7: 0.040076861 | L7: 0.06263465 | M7: 0.29954969 | N7: 0.33139067 | O7: 0.37097065 | P7: 0.43762439 | Q7: 0.41605856 | R7: 0.46050297 | S7: 0.47517195 | T7: 0.5165231 | U7: 0.54906574 | V7: 0.59850782 | W7: 0.63188918 | X7: 0.82586599 | Y7: 0.41676543 | Z7: 0.44218766 | AA7: 0.47007 | AB7: 0.44609217 | AC7: 0.45640358 | AD7: 0.50721008 | AE7: 0.50253715 | AF7: 0.4935591 | AG7: 0.48504318 | AH7: 0.48875396 | AI7: 0 | AJ7: 0 | AK7: 0 | AL7: 0
A8: Gas CCGT & Cogen | B8: Mt CO2e | C8: 0.30174676 | D8: 0.46514645 | E8: 0.56278613 | F8: 0.29435579 | G8: 0.11549342 | H8: 0.097690222 | I8: 0.16519084 | J8: 0.28527673 | K8: 0.36265635 | L8: 0.44060923 | M8: 1.2065022 | N8: 1.3128519 | O8: 1.432536 | P8: 1.5316256 | Q8: 1.5198262 | R8: 1.4801882 | S8: 1.1530242 | T8: 1.1948127 | U8: 1.2414747 | V8: 1.262701 | W8: 1.3039305 | X8: 0.096337934 | Y8: 0 | Z8: 0 | AA8: 0 | AB8: 0 | AC8: 0 | AD8: 0 | AE8: 0 | AF8: 0 | AG8: 0 | AH8: 0 | AI8: 0 | AJ8: 0 | AK8: 0 | AL8: 0
A9: Gas CC CCS | B9: Mt CO2e | C9: 0 | D9: 0 | E9: 0 | F9: 0 | G9: 0 | H9: 0 | I9: 0 | J9: 0 | K9: 0 | L9: 0 | M9: 0 | N9: 0 | O9: 0 | P9: 0 | Q9: 0 | R9: 0 | S9: 0 | T9: 0 | U9: 0 | V9: 0 | W9: 0 | X9: 0 | Y9: 0 | Z9: 0 | AA9: 0 | AB9: 0 | AC9: 0 | AD9: 0 | AE9: 0 | AF9: 0 | AG9: 0 | AH9: 0 | AI9: 0 | AJ9: 0 | AK9: 0 | AL9: 0
A10: Gas Steam | B10: Mt CO2e | C10: 0 | D10: 0 | E10: 0 | F10: 0 | G10: 0 | H10: 0 | I10: 0 | J10: 0 | K10: 0 | L10: 0 | M10: 0 | N10: 0 | O10: 0 | P10: 0 | Q10: 0 | R10: 0 | S10: 0 | T10: 0 | U10: 0 | V10: 0 | W10: 0 | X10: 0 | Y10: 0 | Z10: 0 | AA10: 0 | AB10: 0 | AC10: 0 | AD10: 0 | AE10: 0 | AF10: 0 | AG10: 0 | AH10: 0 | AI10: 0 | AJ10: 0 | AK10: 0 | AL10: 0
