Workbook

Sheet Summary
A2: Key demand fields highlighted in grey
A4: NEM
A5: Source | B5: AEMO ESOO 2024
A6: Underlying Demand - Gross
A7: Financial Year | C7: 2017 | D7: 2018 | E7: 2019 | F7: 2020 | G7: 2021 | H7: 2022 | I7: 2023 | J7: 2024 | K7: 2025 | L7: 2026 | M7: 2027 | N7: 2028 | O7: 2029 | P7: 2030 | Q7: 2031 | R7: 2032 | S7: 2033 | T7: 2034 | U7: 2035 | V7: 2036 | W7: 2037 | X7: 2038 | Y7: 2039 | Z7: 2040 | AA7: 2041 | AB7: 2042 | AC7: 2043 | AD7: 2044 | AE7: 2045 | AF7: 2046 | AG7: 2047 | AH7: 2048 | AI7: 2049 | AJ7: 2050 | AK7: 2051 | AL7: 2052 | AM7: 2053 | AN7: 2054 | AO7: 2055
A8: Queensland | B8: GWh | J8: 60484.599 | K8: 59012.792 | L8: 60594.014 | M8: 62183.406 | N8: 63665.872 | O8: 65089.229 | P8: 67723.317 | Q8: 70417.21 | R8: 74080.221 | S8: 77964.883 | T8: 80548.007 | U8: 83909.119 | V8: 87700.664 | W8: 90539.829 | X8: 93123.792 | Y8: 95901.401 | Z8: 100068.94 | AA8: 101788.58 | AB8: 106254 | AC8: 108802.68 | AD8: 112345.44 | AE8: 115117.26 | AF8: 118663.27 | AG8: 121013.82 | AH8: 121929.73 | AI8: 125665.07 | AJ8: 127669.97 | AK8: 130991.9 | AL8: 135261 | AM8: 139521.93 | AN8: 142567.27 | AO8: 145612.62
A9: New South Wales | B9: GWh | J9: 72510.876 | K9: 73152.272 | L9: 74513.831 | M9: 76266.998 | N9: 78112.381 | O9: 79958.651 | P9: 81799.233 | Q9: 84002.13 | R9: 85540.921 | S9: 86295.132 | T9: 88264.033 | U9: 89587.66 | V9: 91655.36 | W9: 94130.317 | X9: 96656.834 | Y9: 98610.643 | Z9: 100982.78 | AA9: 103374.36 | AB9: 106413.23 | AC9: 108742.6 | AD9: 111010.93 | AE9: 113595.03 | AF9: 115211.51 | AG9: 116978.38 | AH9: 119035.69 | AI9: 121976.26 | AJ9: 124344.85 | AK9: 126869.94 | AL9: 129498.35 | AM9: 134714.4 | AN9: 137256.48 | AO9: 139846.43
A10: Victoria | B10: GWh | J10: 45313.113 | K10: 46774.709 | L10: 48051.743 | M10: 49702.2 | N10: 51228.647 | O10: 52583.467 | P10: 54059.322 | Q10: 55593.982 | R10: 58538.567 | S10: 62647.217 | T10: 65455.937 | U10: 67722.117 | V10: 69870.357 | W10: 72282.802 | X10: 74560.793 | Y10: 76593.355 | Z10: 78479.692 | AA10: 80174.638 | AB10: 82197.41 | AC10: 83970.338 | AD10: 86083.604 | AE10: 88674.01 | AF10: 90197.064 | AG10: 91447.247 | AH10: 93038.982 | AI10: 94783.521 | AJ10: 96559.202 | AK10: 98059.326 | AL10: 99414.367 | AM10: 100811.89 | AN10: 101944.58 | AO10: 103089.99
A11: South Australia | B11: GWh | J11: 14598.81 | K11: 15466.028 | L11: 16221.982 | M11: 17324.929 | N11: 17975.475 | O11: 18297.23 | P11: 18532.819 | Q11: 18995.457 | R11: 19349.874 | S11: 19688.722 | T11: 20509.578 | U11: 20839.316 | V11: 21540.694 | W11: 22368.159 | X11: 23441.11 | Y11: 24065.358 | Z11: 24691.915 | AA11: 25239.912 | AB11: 25917.428 | AC11: 26642.06 | AD11: 27619.615 | AE11: 28351.054 | AF11: 28593.992 | AG11: 29209.112 | AH11: 29368.081 | AI11: 30049.741 | AJ11: 30721.319 | AK11: 30890.926 | AL11: 31171.669 | AM11: 32543.641 | AN11: 32989.27 | AO11: 33441.002
A12: Tasmania | B12: GWh | J12: 10567.723 | K12: 10840.246 | L12: 10927.327 | M12: 11091.651 | N12: 11069.032 | O12: 11110.61 | P12: 11738.778 | Q12: 12911.511 | R12: 13428.092 | S12: 14758.284 | T12: 16240.132 | U12: 15240.6 | V12: 15387.981 | W12: 16570.525 | X12: 18396.327 | Y12: 17799.112 | Z12: 17688.085 | AA12: 18991.489 | AB12: 17766.333 | AC12: 18752.09 | AD12: 18703.023 | AE12: 18424.69 | AF12: 17867.385 | AG12: 18172.082 | AH12: 19572.496 | AI12: 18812.586 | AJ12: 19698.362 | AK12: 19668.636 | AL12: 19526.11 | AM12: 19322.886 | AN12: 19205.634 | AO12: 19865.798
A13: NEM | B13: GWh | J13: 203475.12 | K13: 205246.05 | L13: 210308.9 | M13: 216569.18 | N13: 222051.41 | O13: 227039.19 | P13: 233853.47 | Q13: 241920.29 | R13: 250937.68 | S13: 261354.24 | T13: 271017.69 | U13: 277298.81 | V13: 286155.06 | W13: 295891.63 | X13: 306178.86 | Y13: 312969.87 | Z13: 321911.41 | AA13: 329568.98 | AB13: 338548.4 | AC13: 346909.77 | AD13: 355762.61 | AE13: 364162.04 | AF13: 370533.22 | AG13: 376820.64 | AH13: 382944.97 | AI13: 391287.17 | AJ13: 398993.7 | AK13: 406480.72 | AL13: 414871.49 | AM13: 426914.75 | AN13: 433963.23 | AO13: 441855.85
A15: Operational Demand - exlcuding rooftop solar etc
A16: Financial Year | C16: 2017 | D16: 2018 | E16: 2019 | F16: 2020 | G16: 2021 | H16: 2022 | I16: 2023 | J16: 2024 | K16: 2025 | L16: 2026 | M16: 2027 | N16: 2028 | O16: 2029 | P16: 2030 | Q16: 2031 | R16: 2032 | S16: 2033 | T16: 2034 | U16: 2035 | V16: 2036 | W16: 2037 | X16: 2038 | Y16: 2039 | Z16: 2040 | AA16: 2041 | AB16: 2042 | AC16: 2043 | AD16: 2044 | AE16: 2045 | AF16: 2046 | AG16: 2047 | AH16: 2048 | AI16: 2049 | AJ16: 2050 | AK16: 2051 | AL16: 2052 | AM16: 2053 | AN16: 2054 | AO16: 2055
A17: Queensland | B17: GWh | J17: 52829.587 | K17: 50412.794 | L17: 51302.404 | M17: 52289.67 | N17: 52895.065 | O17: 53636.192 | P17: 55282.848 | Q17: 57092.342 | R17: 59374.496 | S17: 62309.487 | T17: 64057.187 | U17: 66630.567 | V17: 69517.034 | W17: 71530.638 | X17: 73355.246 | Y17: 75313.661 | Z17: 78794.335 | AA17: 80084.88 | AB17: 83608.216 | AC17: 85471.361 | AD17: 88095.649 | AE17: 89619.753 | AF17: 92284.699 | AG17: 93735.261 | AH17: 93644.805 | AI17: 96370.66 | AJ17: 97283.53 | AK17: 99874.366 | AL17: 103218.88 | AM17: 106518.91 | AN17: 108591.76 | AO17: 110773.76
A18: New South Wales | B18: GWh | J18: 64562.615 | K18: 63975.495 | L18: 64466.32 | M18: 65331.176 | N18: 66072.185 | O18: 66965.011 | P18: 67471.907 | Q18: 68386.11 | R18: 68630.967 | S18: 68246.34 | T18: 69171.505 | U18: 69431.367 | V18: 70344.705 | W18: 71785.884 | X18: 73316.939 | Y18: 74260.288 | Z18: 75645.619 | AA18: 77139.116 | AB18: 79179.031 | AC18: 80414.287 | AD18: 81649.796 | AE18: 83057.038 | AF18: 83654.042 | AG18: 84311.767 | AH18: 85031.961 | AI18: 86700.631 | AJ18: 87867.145 | AK18: 89407.982 | AL18: 91007.927 | AM18: 95004.049 | AN18: 96419.06 | AO18: 97840.477
A19: Victoria | B19: GWh | J19: 40608.914 | K19: 40796.629 | L19: 41468.84 | M19: 42401.574 | N19: 43283.853 | O19: 43299.376 | P19: 44043.715 | Q19: 44453.718 | R19: 46727.691 | S19: 49947.682 | T19: 51996.892 | U19: 53532 | V19: 54880.841 | W19: 56573.343 | X19: 58197.087 | Y19: 59488.958 | Z19: 60718.968 | AA19: 61555.046 | AB19: 62736.453 | AC19: 63650.067 | AD19: 64896.907 | AE19: 66424.18 | AF19: 67133.591 | AG19: 67430.096 | AH19: 67924.295 | AI19: 68648.593 | AJ19: 69494.207 | AK19: 70307.729 | AL19: 70693.063 | AM19: 71117.377 | AN19: 71390.023 | AO19: 71598.309
A20: South Australia | B20: GWh | J20: 11733.538 | K20: 12066.221 | L20: 12525.738 | M20: 13361.152 | N20: 13722.106 | O20: 13761.427 | P20: 13737.012 | Q20: 13791.454 | R20: 13832.419 | S20: 13790.39 | T20: 14294.101 | U20: 14305.117 | V20: 14676.492 | W20: 15218.564 | X20: 16034.734 | Y20: 16363.409 | Z20: 16710.41 | AA20: 16966.068 | AB20: 17392.602 | AC20: 17931.839 | AD20: 18705.249 | AE20: 19126.772 | AF20: 19187.606 | AG20: 19547.642 | AH20: 19345.081 | AI20: 19774.859 | AJ20: 20120.588 | AK20: 20074.072 | AL20: 20135.822 | AM20: 21064.671 | AN20: 21357.978 | AO20: 21463.741
A21: Tasmania | B21: GWh | J21: 10275.545 | K21: 10490.881 | L21: 10551.543 | M21: 10659.043 | N21: 10580.891 | O21: 10560.21 | P21: 11136.357 | Q21: 12232.158 | R21: 12694.359 | S21: 13965.169 | T21: 15391.413 | U21: 14337.47 | V21: 14427.813 | W21: 15551.028 | X21: 17315.205 | Y21: 16650.927 | Z21: 16467.959 | AA21: 17704.704 | AB21: 16416.328 | AC21: 17338.299 | AD21: 17227.204 | AE21: 16888.512 | AF21: 16269.183 | AG21: 16507.08 | AH21: 17837.04 | AI21: 17009.302 | AJ21: 17830.651 | AK21: 17740.773 | AL21: 17532.775 | AM21: 17263.771 | AN21: 17080.304 | AO21: 17674.248
A22: NEM | B22: GWh | J22: 180010.2 | K22: 177742.02 | L22: 180314.84 | M22: 184042.61 | N22: 186554.1 | O22: 188222.22 | P22: 191671.84 | Q22: 195955.78 | R22: 201259.93 | S22: 208259.07 | T22: 214911.1 | U22: 218236.52 | V22: 223846.88 | W22: 230659.46 | X22: 238219.21 | Y22: 242077.24 | Z22: 248337.29 | AA22: 253449.82 | AB22: 259332.63 | AC22: 264805.85 | AD22: 270574.81 | AE22: 275116.25 | AF22: 278529.12 | AG22: 281531.85 | AH22: 283783.18 | AI22: 288504.04 | AJ22: 292596.12 | AK22: 297404.92 | AL22: 302588.47 | AM22: 310968.78 | AN22: 314839.12 | AO22: 319350.54
A25: WEM | B25: Annual underlying consumption 2024 Expected Scenario (based on step change scenario)
A26: Source | B26: https://aemo.com.au/-/media/files/electricity/wem/planning_and_forecasting/esoo/2024/2024-wem-electricity-statement-of-opportunities.pdf?la=en
E27: =E7 -> 2019 | F27: =F7 -> 2020 | G27: =G7 -> 2021 | H27: =H7 -> 2022 | I27: =I7 -> 2023 | J27: =J7&"F" -> 2024F | K27: =K7&"F" -> 2025F | L27: =L7&"F" -> 2026F | M27: =M7&"F" -> 2027F | N27: =N7&"F" -> 2028F | O27: =O7&"F" -> 2029F | P27: =P7&"F" -> 2030F | Q27: =Q7&"F" -> 2031F | ... T27: =T7&"F" -> 2034F | U27: =U7 -> 2035 | V27: =V7 -> 2036 | W27: =W7 -> 2037 | X27: =X7 -> 2038 | Y27: =Y7 -> 2039 | Z27: =Z7 -> 2040 | AA27: =AA7 -> 2041 | AB27: =AB7 -> 2042 | ... AJ27: =AJ7 -> 2050
A28: 2024 Expected Underlying Consumption (Fig.6) | B28: GWh | E28: 17471.63 | F28: 18107.077 | G28: 18558.214 | H28: 19340.246 | I28: 18934.793 | J28: 19931.19 | K28: 20616.53 | L28: 21158.89 | M28: 21830.34 | N28: 22547.21 | O28: 23649.4 | P28: 25620.2 | Q28: 28010.49 | R28: 30055.15 | S28: 32111.2 | T28: 34241.82 | U28: =T28*(1+U76) -> 35208.97 | V28: =U28*(1+V76) -> 36203.437 | W28: =V28*(1+W76) -> 37225.992 | X28: =W28*(1+X76) -> 38277.429 | Y28: =X28*(1+Y76) -> 39358.564 | Z28: =Y28*(1+Z76) -> 40470.235 | AA28: =Z28*(1+AA76) -> 41613.305 | AB28: =AA28*(1+AB76) -> 42788.66 | ... AJ28: =AI28*(1+AJ76) -> 53468.812
A30: 2024 Expected Operational Consumption (Fig.13) | B30: GWh | E30: 17262.9 | F30: 17621.787 | G30: 17653.125 | H30: 17932.484 | I30: 17203.165 | J30: 17800.19 | K30: 18018.23 | L30: 18082.42 | M30: 18287.25 | N30: 18530.04 | O30: 19188.22 | P30: 20799.68 | Q30: 22832.89 | R30: 24464.77 | S30: 26117.93 | T30: 27867.57
A34: NWIS
A35: Source | B35: Horizon power annual report for FY24 actual consumption
B36: tariff methodology for growth in peak load used to project overall load
B37: https://www.horizonpower.com.au/globalassets/media/documents/annual-reports/20232024/horizon-power_annual-report-2024?v=4a6c54
F38: =F16 -> 2020 | G38: =G16 -> 2021 | H38: =H16 -> 2022 | I38: =I16 -> 2023 | J38: =J16 -> 2024 | K38: =K16 -> 2025 | L38: =L16 -> 2026 | M38: =M16 -> 2027 | ... Z38: =Z16 -> 2040 | AA38: =AA27 -> 2041 | AB38: =AB27 -> 2042 | AC38: =AC27 -> 2043 | AD38: =AD27 -> 2044 | AE38: =AE27 -> 2045 | AF38: =AF27 -> 2046 | AG38: =AG27 -> 2047 | AH38: =AH27 -> 2048 | ... AJ38: =AJ27 -> 2050
A39: NWIS forecast based on CEFC 2024 figures, and then escalated at Horizon growth in peak demand | B39: GWh | F39: =G39*notes!D19/notes!E19 -> 4362.7375 | G39: =H39*notes!E19/notes!F19 -> 4438.6112 | H39: =I39*notes!F19/notes!G19 -> 4552.4217 | I39: =J39*notes!G19/notes!H19 -> 4362.7375 | J39: 4867.696 | K39: =J39*notes!I19/notes!H19 -> 4867.696 | L39: =K39*notes!J19/notes!I19 -> 4552.4217 | M39: =L39*notes!K19/notes!J19 -> 4606.6172 | N39: =M39*notes!L19/notes!K19 -> 4660.8127 | O39: =N39*notes!M19/notes!L19 -> 4715.0082 | P39: =O39*notes!N19/notes!M19 -> 4769.2037 | Q39: =P39*notes!O19/notes!N19 -> 4823.3992 | R39: =Q39*notes!P19/notes!O19 -> 4877.5947 | ... Z39: =Y39*notes!X19/notes!W19 -> 5311.1587 | AA39: =Z39*(1+AA77) -> 5369.9624 | AB39: =AA39*(1+AB77) -> 5429.4171 | AC39: =AB39*(1+AC77) -> 5489.5301 | AD39: =AC39*(1+AD77) -> 5550.3087 | AE39: =AD39*(1+AE77) -> 5611.7602 | AF39: =AE39*(1+AF77) -> 5673.8921 | AG39: =AF39*(1+AG77) -> 5736.7119 | AH39: =AG39*(1+AH77) -> 5800.2271 | ... AJ39: =AI39*(1+AJ77) -> 5929.3752
A40: Pre 2024, scaled down using Horixon peak demand forecast
A42: DKIS | B42: Annual System Consumption (period ending 31st August)
A43: Source | B43: https://utilicom.nt.gov.au/electricity/reporting/electricity-outlook-report
B44: https://utilicom.nt.gov.au/publications/reports-and-reviews/pre-2025/2023-northern-territory-electricity-outlook-report-data
A46: Period ending (31 August) | C46: =C16 -> 2017 | D46: =D16 -> 2018 | E46: =E16 -> 2019 | F46: =F16 -> 2020 | G46: =G16 -> 2021 | H46: =H16 -> 2022 | I46: =I16 -> 2023 | J46: =J16 & "F" -> 2024F | K46: =K16 & "F" -> 2025F | L46: =L16 & "F" -> 2026F | M46: =M16 & "F" -> 2027F | N46: =N16 & "F" -> 2028F | O46: =O16 & "F" -> 2029F | P46: =P16 & "F" -> 2030F | Q46: =Q16 & "F" -> 2031F | ... S46: =S16 & "F" -> 2033F | T46: =T38 -> 2034 | U46: =U38 -> 2035 | V46: =V38 -> 2036 | W46: =W38 -> 2037 | X46: =X38 -> 2038 | Y46: =Y38 -> 2039 | Z46: =Z38 -> 2040 | AA46: =AA38 -> 2041 | ... AJ46: =AJ38 -> 2050
A47: Darwin | B47: GWh | C47: 1445.6654 | D47: 1456.4343 | E47: 1396.4834 | F47: 1329.7053 | G47: 1318.8528 | H47: 1392.6506 | I47: 1310.852 | J47: 1303.864 | K47: 1340.528 | L47: 1341.943 | M47: 1339.164 | N47: 1336.816 | O47: 1334.53 | P47: 1332.64 | Q47: 1330.938 | R47: 1329.785 | S47: 1328.442 | T47: =S47*(1+T$77) -> 1343.0403 | U47: =T47*(1+U$77) -> 1357.6385 | V47: =U47*(1+V$77) -> 1372.2368 | W47: =V47*(1+W$77) -> 1386.8351 | X47: =W47*(1+X$77) -> 1401.4333 | Y47: =X47*(1+Y$77) -> 1416.0316 | Z47: =Y47*(1+Z$77) -> 1430.6298 | AA47: =Z47*(1+AA$77) -> 1446.4694 | ... AJ47: =AI47*(1+AJ$77) -> 1597.1545
A48: Manton, Batchelor, Pine Creek | B48: GWh | C48: 74.758973 | D48: 40.859813 | E48: 47.046203 | F48: 46.667706 | G48: 22.082426 | H48: 20.821712 | I48: 22.73555 | J48: 21.79848 | K48: 27.97303 | L48: 29.97694 | M48: 29.91986 | N48: 29.91967 | O48: 29.95682 | P48: 29.95682 | Q48: 30.01596 | R48: 30.11266 | S48: 30.16718 | T48: =S48*(1+T$77) -> 30.498687 | U48: =T48*(1+U$77) -> 30.830195 | V48: =U48*(1+V$77) -> 31.161702 | W48: =V48*(1+W$77) -> 31.49321 | X48: =W48*(1+X$77) -> 31.824717 | Y48: =X48*(1+Y$77) -> 32.156225 | Z48: =Y48*(1+Z$77) -> 32.487732 | AA48: =Z48*(1+AA$77) -> 32.847428 | ... AJ48: =AI48*(1+AJ$77) -> 36.26929
A49: Katherine | B49: GWh | C49: 119.3411 | D49: 122.96482 | E49: 128.47022 | F49: 129.01341 | G49: 124.37693 | H49: 132.21949 | I49: 123.48468 | J49: 129.5827 | K49: 140.4275 | L49: 173.7085 | M49: 173.5649 | N49: 173.5716 | O49: 173.3709 | P49: 173.3131 | Q49: 173.4838 | R49: 173.4578 | S49: 173.4578 | T49: =S49*(1+T$77) -> 175.36393 | U49: =T49*(1+U$77) -> 177.27006 | V49: =U49*(1+V$77) -> 179.17619 | W49: =V49*(1+W$77) -> 181.08232 | X49: =W49*(1+X$77) -> 182.98845 | Y49: =X49*(1+Y$77) -> 184.89458 | Z49: =Y49*(1+Z$77) -> 186.80071 | AA49: =Z49*(1+AA$77) -> 188.86891 | ... AJ49: =AI49*(1+AJ$77) -> 208.54423
A50: Darwin-Katherine Total Consumption | B50: GWh | C50: 1639.7655 | D50: 1620.2589 | E50: 1571.9998 | F50: 1505.3864 | G50: 1465.3121 | H50: 1545.6918 | I50: 1457.0722 | J50: 1455.2452 | K50: 1508.9285 | L50: 1545.6284 | M50: 1542.6488 | N50: 1540.3073 | O50: 1537.8577 | P50: 1535.9099 | Q50: 1534.4378 | R50: 1533.3555 | S50: 1532.067 | T50: =S50*(1+T$77) -> 1548.9029 | U50: =T50*(1+U$77) -> 1565.7388 | V50: =U50*(1+V$77) -> 1582.5747 | W50: =V50*(1+W$77) -> 1599.4106 | X50: =W50*(1+X$77) -> 1616.2465 | Y50: =X50*(1+Y$77) -> 1633.0824 | Z50: =Y50*(1+Z$77) -> 1649.9183 | AA50: =Z50*(1+AA$77) -> 1668.1857 | ... AJ50: =AI50*(1+AJ$77) -> 1841.968
B52: https://utilicom.nt.gov.au/__data/assets/pdf_file/0010/1509571/2024-Northern-Territory-Electricity-Outlook-Report-Update_Final.pdf
...

Sheet notes
A2: Horizon Power Tariff setting methodology
B3: https://nwis.com.au/media/cfkhzdic/tariff-setting-methodology.pdf
D15: 2020 | E15: =D15+1 -> 2021 | F15: =E15+1 -> 2022 | G15: =F15+1 -> 2023 | H15: =G15+1 -> 2024 | I15: =H15+1 -> 2025 | J15: =I15+1 -> 2026 | K15: =J15+1 -> 2027 | L15: =K15+1 -> 2028 | ... X15: =W15+1 -> 2040
B16: P50 Peak demand | C16: kw | D16: 115000 | E16: 117000 | F16: 120000 | G16: 115000 | H16: 128310.5 | I16: =H16 -> 128310.5 | J16: 120000 | K16: =J16+$K$17 -> 121428.57 | L16: =K16+$K$17 -> 122857.14 | M16: =L16+$K$17 -> 124285.71 | N16: =M16+$K$17 -> 125714.29 | O16: =N16+$K$17 -> 127142.86 | P16: =O16+$K$17 -> 128571.43 | Q16: =P16+$K$17 -> 130000 | R16: =Q16+$K$17 -> 131428.57 | ... W16: =V16+$K$17 -> 138571.43 | X16: 140000
K17: =(X16-J16)/14 -> 1428.5714
B18: Assumed LF | D18: 1 | E18: =D18 -> 1 | F18: =E18 -> 1 | G18: =F18 -> 1 | H18: =G18 -> 1 | I18: =H18 -> 1 | J18: =I18 -> 1 | K18: =J18 -> 1 | L18: =K18 -> 1 | ... X18: =W18 -> 1
B19: Inferred Consumption forecast | C19: GWh | D19: =D16*8760/1000000/D18 -> 1007.4 | E19: =E16*8760/1000000/E18 -> 1024.92 | F19: =F16*8760/1000000/F18 -> 1051.2 | G19: =G16*8760/1000000/G18 -> 1007.4 | H19: =H16*8760/1000000/H18 -> 1124 | I19: =I16*8760/1000000/I18 -> 1124 | J19: =J16*8760/1000000/J18 -> 1051.2 | K19: =K16*8760/1000000/K18 -> 1063.7143 | ... X19: =X16*8760/1000000/X18 -> 1226.4
B20: Demand to mtach to | C20: GWh | H20: 1124
B21: (Assumes constant load factor)
D22: =D16*8760/1000000/D18 -> 1007.4
B24: Horizon Power Annual report
B25: https://www.horizonpower.com.au/globalassets/media/documents/annual-reports/20232024/horizon-power_annual-report-2024?v=4a6c54
B27: FY 2024 | E27: 1,124 GWh delivered | G27: p14 annual report
A31: Clen Energy Finance Corporation | E31: 45517
B32: Superpowering up Accelerating the electrification and decarbonisation of the Pilbara
B33: Figure 2.2 NWIS grid connected generation facilities
A62: Powerlink data on Mt Isa
A64: Queensland data from PowerLink (includes Mt Isa from 2032)
A65: Source | B65: https://www.powerlink.com.au/planning-report/transmission-annual-planning-report-2024
A66: Period ending | C66: =Summary!C7 -> 2017 | D66: =Summary!D7 -> 2018 | E66: =Summary!E7 -> 2019 | F66: =Summary!F7 -> 2020 | G66: =Summary!G7 -> 2021 | H66: =Summary!H7 -> 2022 | I66: =Summary!I7 -> 2023 | J66: =Summary!J7 -> 2024 | K66: =Summary!K7 & "F" -> 2025F | L66: =Summary!L7 & "F" -> 2026F | M66: =Summary!M7 & "F" -> 2027F | N66: =Summary!N7 & "F" -> 2028F | O66: =Summary!O7 & "F" -> 2029F | P66: =Summary!P7 & "F" -> 2030F | Q66: =Summary!Q7 & "F" -> 2031F | R66: =Summary!R7 & "F" -> 2032F | ... T66: =Summary!T7 & "F" -> 2034F | U66: 2035 | V66: =U66+1 -> 2036 | W66: =V66+1 -> 2037 | X66: =W66+1 -> 2038 | Y66: =X66+1 -> 2039 | Z66: =Y66+1 -> 2040
A67: PowerLink (Transmission Delivered) | C67: 49880 | D67: 48739 | E67: 48764 | F67: 47860 | G67: 47421.236 | H67: 47405.248 | I67: 46214.125 | J67: 47476.542 | K67: 46697.001 | L67: 48031.669 | M67: 48883.464 | N67: 50217.171 | O67: 52000.033 | P67: 53785.258 | Q67: 57649.942 | R67: 60434.265 | S67: 60436.719 | T67: 60515.941
A68: Report indicated Mt Isa being connected from 2032 @ 901GWh pa included above | R68: 901 | S68: 901 | T68: 901
A69: AEMO 2024 ESOO Step Change Op Sent Out (converted to Transmission Delievered) | K69: 46812.138 | L69: 47377.061 | M69: 47946.461 | N69: 48377.861 | O69: 48936.961 | P69: 50780.261 | Q69: 52588.761 | R69: 55240.56 | S69: 58118.961 | T69: 59695.461
A70: Difference to PowerLink | K70: =K69/K67-1 -> 0.0024656232 | L70: =L69/L67-1 -> -0.013628687 | M70: =M69/M67-1 -> -0.019168117 | N70: =N69/N67-1 -> -0.036627114 | O70: =O69/O67-1 -> -0.058905208 | P70: =P69/P67-1 -> -0.055870274 | Q70: =Q69/Q67-1 -> -0.087791618 | R70: =R69/R67-1 -> -0.085939724 | ... T70: =T69/T67-1 -> -0.013558084
A71: Difference to AEMO Op Sent Out | K71: =K69/Summary!K17-1 -> -0.071423462 | L71: =L69/Summary!L17-1 -> -0.07651384 | M71: =M69/Summary!M17-1 -> -0.083060569 | N71: =N69/Summary!N17-1 -> -0.085399356 | O71: =O69/Summary!O17-1 -> -0.087613075 | P71: =P69/Summary!P17-1 -> -0.081446371 | Q71: =Q69/Summary!Q17-1 -> -0.078882407 | R71: =R69/Summary!R17-1 -> -0.069624773 | ... T71: =T69/Summary!T17-1 -> -0.068091136
A73: Whole of system Plan WA
A76: https://www.wa.gov.au/government/document-collections/whole-of-system-plan#:~:text=The%20Whole%20of%20System%20Plan,of%20our%20main%20electricity%20system.&text=Whole%20of%20System%20Planning%20provides,like%20over%20the%20coming%20decades.
A78: 20 YEAR PROJECTION 2020 TO 2040 FOR swis SYSTEM ONLY
B82: Techtopia senario (most like WA ESOO 2024) | G82: 21345.7 | H82: 22485.61 | I82: 24023.14 | J82: 25954.79 | K82: 28056.43 | L82: 30399.34 | M82: 33552.65 | N82: 34887.41 | O82: 35750.01 | P82: 36450.53 | Q82: 37679.16 | R82: 38719.62 | S82: 39453.33 | T82: 40362.76 | U82: 41201.14 | V82: 42472.48 | W82: 43109.98 | X82: 44401.67 | Y82: 45390.52 | Z82: 46876.33
B84: SWIS forecast (ESOO plus extension) | G84: =Summary!G28 -> 18558.214 | H84: =Summary!H28 -> 19340.246 | I84: =Summary!I28 -> 18934.793 | J84: =Summary!J28 -> 19931.19 | K84: =Summary!K28 -> 20616.53 | L84: =Summary!L28 -> 21158.89 | M84: =Summary!M28 -> 21830.34 | N84: =Summary!N28 -> 22547.21 | ... Z84: =Summary!Z28 -> 40470.235
H85: =H84/G84-1 -> 0.042139389 | I85: =I84/H84-1 -> -0.020964218 | J85: =J84/I84-1 -> 0.052622559 | K85: =K84/J84-1 -> 0.034385303 | L85: =L84/K84-1 -> 0.026307046 | M85: =M84/L84-1 -> 0.031733706 | N85: =N84/M84-1 -> 0.032838243 | O85: =O84/N84-1 -> 0.048883653 | ... Z85: =Z84/Y84-1 -> 0.028244703
