Workbook
Name Summary_CDP: 'NEM Emissions'!#REF!

Sheet Summary
A2: Key demand fields highlighted in grey
A4: NEM
A5: Source | B5: AEMO ESOO 2024
A6: NEM Demand breakdown
A7: Financial Year | C7: 2017 | D7: 2018 | E7: 2019 | F7: 2020 | G7: 2021 | H7: 2022 | I7: 2023 | J7: 2024 | K7: 2025 | L7: 2026 | M7: 2027 | N7: 2028 | O7: 2029 | P7: 2030 | Q7: 2031 | R7: 2032 | S7: 2033 | T7: 2034 | U7: 2035 | V7: 2036 | W7: 2037 | X7: 2038 | Y7: 2039 | Z7: 2040 | AA7: 2041 | AB7: 2042 | AC7: 2043 | AD7: 2044 | AE7: 2045 | AF7: 2046 | AG7: 2047 | AH7: 2048 | AI7: 2049 | AJ7: 2050 | AK7: 2051 | AL7: 2052 | AM7: 2053 | AN7: 2054 | AO7: 2055
A8: Residential | B8: GWh | K8: =SUMIFS('NEM demand data'!$I$2:$I$4357,'NEM demand data'!$D$2:$D$4357,Summary!$A8,'NEM demand data'!$F$2:$F$4357,Summary!$A$4,'NEM demand data'!$H$2:$H$4357,Summary!K$7)*1000 -> 33853.6 | L8: =SUMIFS('NEM demand data'!$I$2:$I$4357,'NEM demand data'!$D$2:$D$4357,Summary!$A8,'NEM demand data'!$F$2:$F$4357,Summary!$A$4,'NEM demand data'!$H$2:$H$4357,Summary!L$7)*1000 -> 31302.1 | M8: =SUMIFS('NEM demand data'!$I$2:$I$4357,'NEM demand data'!$D$2:$D$4357,Summary!$A8,'NEM demand data'!$F$2:$F$4357,Summary!$A$4,'NEM demand data'!$H$2:$H$4357,Summary!M$7)*1000 -> 28739.8 | N8: =SUMIFS('NEM demand data'!$I$2:$I$4357,'NEM demand data'!$D$2:$D$4357,Summary!$A8,'NEM demand data'!$F$2:$F$4357,Summary!$A$4,'NEM demand data'!$H$2:$H$4357,Summary!N$7)*1000 -> 26255.6 | O8: =SUMIFS('NEM demand data'!$I$2:$I$4357,'NEM demand data'!$D$2:$D$4357,Summary!$A8,'NEM demand data'!$F$2:$F$4357,Summary!$A$4,'NEM demand data'!$H$2:$H$4357,Summary!O$7)*1000 -> 24153.6 | P8: =SUMIFS('NEM demand data'!$I$2:$I$4357,'NEM demand data'!$D$2:$D$4357,Summary!$A8,'NEM demand data'!$F$2:$F$4357,Summary!$A$4,'NEM demand data'!$H$2:$H$4357,Summary!P$7)*1000 -> 22550.6 | Q8: =SUMIFS('NEM demand data'!$I$2:$I$4357,'NEM demand data'!$D$2:$D$4357,Summary!$A8,'NEM demand data'!$F$2:$F$4357,Summary!$A$4,'NEM demand data'!$H$2:$H$4357,Summary!Q$7)*1000 -> 20707.6 | R8: =SUMIFS('NEM demand data'!$I$2:$I$4357,'NEM demand data'!$D$2:$D$4357,Summary!$A8,'NEM demand data'!$F$2:$F$4357,Summary!$A$4,'NEM demand data'!$H$2:$H$4357,Summary!R$7)*1000 -> 18727.5 | ... AN8: =SUMIFS('NEM demand data'!$I$2:$I$4357,'NEM demand data'!$D$2:$D$4357,Summary!$A8,'NEM demand data'!$F$2:$F$4357,Summary!$A$4,'NEM demand data'!$H$2:$H$4357,Summary!AN$7)*1000 -> -20716.8 | AO8: =AN8/AM8*AN8 -> -21312.024
A9: Business | B9: GWh | K9: =SUMIFS('NEM demand data'!$I$2:$I$4357,'NEM demand data'!$D$2:$D$4357,Summary!$A9,'NEM demand data'!$F$2:$F$4357,Summary!$A$4,'NEM demand data'!$H$2:$H$4357,Summary!K$7)*1000 -> 129893.2 | L9: =SUMIFS('NEM demand data'!$I$2:$I$4357,'NEM demand data'!$D$2:$D$4357,Summary!$A9,'NEM demand data'!$F$2:$F$4357,Summary!$A$4,'NEM demand data'!$H$2:$H$4357,Summary!L$7)*1000 -> 130446.1 | M9: =SUMIFS('NEM demand data'!$I$2:$I$4357,'NEM demand data'!$D$2:$D$4357,Summary!$A9,'NEM demand data'!$F$2:$F$4357,Summary!$A$4,'NEM demand data'!$H$2:$H$4357,Summary!M$7)*1000 -> 131462.4 | N9: =SUMIFS('NEM demand data'!$I$2:$I$4357,'NEM demand data'!$D$2:$D$4357,Summary!$A9,'NEM demand data'!$F$2:$F$4357,Summary!$A$4,'NEM demand data'!$H$2:$H$4357,Summary!N$7)*1000 -> 131998.5 | O9: =SUMIFS('NEM demand data'!$I$2:$I$4357,'NEM demand data'!$D$2:$D$4357,Summary!$A9,'NEM demand data'!$F$2:$F$4357,Summary!$A$4,'NEM demand data'!$H$2:$H$4357,Summary!O$7)*1000 -> 131495.7 | P9: =SUMIFS('NEM demand data'!$I$2:$I$4357,'NEM demand data'!$D$2:$D$4357,Summary!$A9,'NEM demand data'!$F$2:$F$4357,Summary!$A$4,'NEM demand data'!$H$2:$H$4357,Summary!P$7)*1000 -> 131164 | Q9: =SUMIFS('NEM demand data'!$I$2:$I$4357,'NEM demand data'!$D$2:$D$4357,Summary!$A9,'NEM demand data'!$F$2:$F$4357,Summary!$A$4,'NEM demand data'!$H$2:$H$4357,Summary!Q$7)*1000 -> 131183.5 | R9: =SUMIFS('NEM demand data'!$I$2:$I$4357,'NEM demand data'!$D$2:$D$4357,Summary!$A9,'NEM demand data'!$F$2:$F$4357,Summary!$A$4,'NEM demand data'!$H$2:$H$4357,Summary!R$7)*1000 -> 131720.7 | ... AN9: =SUMIFS('NEM demand data'!$I$2:$I$4357,'NEM demand data'!$D$2:$D$4357,Summary!$A9,'NEM demand data'!$F$2:$F$4357,Summary!$A$4,'NEM demand data'!$H$2:$H$4357,Summary!AN$7)*1000 -> 112777.1 | AO9: =AN9/AM9*AN9 -> 112196.41
A10: Electrification | B10: GWh | K10: =SUMIFS('NEM demand data'!$I$2:$I$4357,'NEM demand data'!$D$2:$D$4357,Summary!$A10,'NEM demand data'!$F$2:$F$4357,Summary!$A$4,'NEM demand data'!$H$2:$H$4357,Summary!K$7)*1000 -> 1456.6 | L10: =SUMIFS('NEM demand data'!$I$2:$I$4357,'NEM demand data'!$D$2:$D$4357,Summary!$A10,'NEM demand data'!$F$2:$F$4357,Summary!$A$4,'NEM demand data'!$H$2:$H$4357,Summary!L$7)*1000 -> 3974.6 | M10: =SUMIFS('NEM demand data'!$I$2:$I$4357,'NEM demand data'!$D$2:$D$4357,Summary!$A10,'NEM demand data'!$F$2:$F$4357,Summary!$A$4,'NEM demand data'!$H$2:$H$4357,Summary!M$7)*1000 -> 6844.5 | N10: =SUMIFS('NEM demand data'!$I$2:$I$4357,'NEM demand data'!$D$2:$D$4357,Summary!$A10,'NEM demand data'!$F$2:$F$4357,Summary!$A$4,'NEM demand data'!$H$2:$H$4357,Summary!N$7)*1000 -> 9337 | O10: =SUMIFS('NEM demand data'!$I$2:$I$4357,'NEM demand data'!$D$2:$D$4357,Summary!$A10,'NEM demand data'!$F$2:$F$4357,Summary!$A$4,'NEM demand data'!$H$2:$H$4357,Summary!O$7)*1000 -> 12028.5 | P10: =SUMIFS('NEM demand data'!$I$2:$I$4357,'NEM demand data'!$D$2:$D$4357,Summary!$A10,'NEM demand data'!$F$2:$F$4357,Summary!$A$4,'NEM demand data'!$H$2:$H$4357,Summary!P$7)*1000 -> 14029.1 | Q10: =SUMIFS('NEM demand data'!$I$2:$I$4357,'NEM demand data'!$D$2:$D$4357,Summary!$A10,'NEM demand data'!$F$2:$F$4357,Summary!$A$4,'NEM demand data'!$H$2:$H$4357,Summary!Q$7)*1000 -> 15768.2 | R10: =SUMIFS('NEM demand data'!$I$2:$I$4357,'NEM demand data'!$D$2:$D$4357,Summary!$A10,'NEM demand data'!$F$2:$F$4357,Summary!$A$4,'NEM demand data'!$H$2:$H$4357,Summary!R$7)*1000 -> 17348.8 | ... AN10: =SUMIFS('NEM demand data'!$I$2:$I$4357,'NEM demand data'!$D$2:$D$4357,Summary!$A10,'NEM demand data'!$F$2:$F$4357,Summary!$A$4,'NEM demand data'!$H$2:$H$4357,Summary!AN$7)*1000 -> 40014.2 | AO10: =AN10/AM10*AN10 -> 40431.916
A11: Electric Vehicles | B11: GWh | K11: =SUMIFS('NEM demand data'!$I$2:$I$4357,'NEM demand data'!$D$2:$D$4357,Summary!$A11,'NEM demand data'!$F$2:$F$4357,Summary!$A$4,'NEM demand data'!$H$2:$H$4357,Summary!K$7)*1000 -> 719.1 | L11: =SUMIFS('NEM demand data'!$I$2:$I$4357,'NEM demand data'!$D$2:$D$4357,Summary!$A11,'NEM demand data'!$F$2:$F$4357,Summary!$A$4,'NEM demand data'!$H$2:$H$4357,Summary!L$7)*1000 -> 1248.5 | M11: =SUMIFS('NEM demand data'!$I$2:$I$4357,'NEM demand data'!$D$2:$D$4357,Summary!$A11,'NEM demand data'!$F$2:$F$4357,Summary!$A$4,'NEM demand data'!$H$2:$H$4357,Summary!M$7)*1000 -> 1961.5 | N11: =SUMIFS('NEM demand data'!$I$2:$I$4357,'NEM demand data'!$D$2:$D$4357,Summary!$A11,'NEM demand data'!$F$2:$F$4357,Summary!$A$4,'NEM demand data'!$H$2:$H$4357,Summary!N$7)*1000 -> 2877.8 | O11: =SUMIFS('NEM demand data'!$I$2:$I$4357,'NEM demand data'!$D$2:$D$4357,Summary!$A11,'NEM demand data'!$F$2:$F$4357,Summary!$A$4,'NEM demand data'!$H$2:$H$4357,Summary!O$7)*1000 -> 3927.9 | P11: =SUMIFS('NEM demand data'!$I$2:$I$4357,'NEM demand data'!$D$2:$D$4357,Summary!$A11,'NEM demand data'!$F$2:$F$4357,Summary!$A$4,'NEM demand data'!$H$2:$H$4357,Summary!P$7)*1000 -> 5122.8 | Q11: =SUMIFS('NEM demand data'!$I$2:$I$4357,'NEM demand data'!$D$2:$D$4357,Summary!$A11,'NEM demand data'!$F$2:$F$4357,Summary!$A$4,'NEM demand data'!$H$2:$H$4357,Summary!Q$7)*1000 -> 6457.4 | R11: =SUMIFS('NEM demand data'!$I$2:$I$4357,'NEM demand data'!$D$2:$D$4357,Summary!$A11,'NEM demand data'!$F$2:$F$4357,Summary!$A$4,'NEM demand data'!$H$2:$H$4357,Summary!R$7)*1000 -> 7918.6 | ... AN11: =SUMIFS('NEM demand data'!$I$2:$I$4357,'NEM demand data'!$D$2:$D$4357,Summary!$A11,'NEM demand data'!$F$2:$F$4357,Summary!$A$4,'NEM demand data'!$H$2:$H$4357,Summary!AN$7)*1000 -> 76309.7 | AO11: =AN11/AM11*AN11 -> 79837.044
A12: Hydrogen Production | B12: GWh | K12: =SUMIFS('NEM demand data'!$I$2:$I$4357,'NEM demand data'!$D$2:$D$4357,Summary!$A12,'NEM demand data'!$F$2:$F$4357,Summary!$A$4,'NEM demand data'!$H$2:$H$4357,Summary!K$7)*1000 -> 110.8 | L12: =SUMIFS('NEM demand data'!$I$2:$I$4357,'NEM demand data'!$D$2:$D$4357,Summary!$A12,'NEM demand data'!$F$2:$F$4357,Summary!$A$4,'NEM demand data'!$H$2:$H$4357,Summary!L$7)*1000 -> 556 | M12: =SUMIFS('NEM demand data'!$I$2:$I$4357,'NEM demand data'!$D$2:$D$4357,Summary!$A12,'NEM demand data'!$F$2:$F$4357,Summary!$A$4,'NEM demand data'!$H$2:$H$4357,Summary!M$7)*1000 -> 1111.8 | N12: =SUMIFS('NEM demand data'!$I$2:$I$4357,'NEM demand data'!$D$2:$D$4357,Summary!$A12,'NEM demand data'!$F$2:$F$4357,Summary!$A$4,'NEM demand data'!$H$2:$H$4357,Summary!N$7)*1000 -> 1395.2 | O12: =SUMIFS('NEM demand data'!$I$2:$I$4357,'NEM demand data'!$D$2:$D$4357,Summary!$A12,'NEM demand data'!$F$2:$F$4357,Summary!$A$4,'NEM demand data'!$H$2:$H$4357,Summary!O$7)*1000 -> 2003.7 | P12: =SUMIFS('NEM demand data'!$I$2:$I$4357,'NEM demand data'!$D$2:$D$4357,Summary!$A12,'NEM demand data'!$F$2:$F$4357,Summary!$A$4,'NEM demand data'!$H$2:$H$4357,Summary!P$7)*1000 -> 4634.9 | Q12: =SUMIFS('NEM demand data'!$I$2:$I$4357,'NEM demand data'!$D$2:$D$4357,Summary!$A12,'NEM demand data'!$F$2:$F$4357,Summary!$A$4,'NEM demand data'!$H$2:$H$4357,Summary!Q$7)*1000 -> 8203.1 | R12: =SUMIFS('NEM demand data'!$I$2:$I$4357,'NEM demand data'!$D$2:$D$4357,Summary!$A12,'NEM demand data'!$F$2:$F$4357,Summary!$A$4,'NEM demand data'!$H$2:$H$4357,Summary!R$7)*1000 -> 12027.9 | ... AN12: =SUMIFS('NEM demand data'!$I$2:$I$4357,'NEM demand data'!$D$2:$D$4357,Summary!$A12,'NEM demand data'!$F$2:$F$4357,Summary!$A$4,'NEM demand data'!$H$2:$H$4357,Summary!AN$7)*1000 -> 67677.1 | AO12: =AN12/AM12*AN12 -> 67677.1
A13: Losses | B13: GWh | J13: =SUMIFS('NEM demand data'!$I$2:$I$4357,'NEM demand data'!$D$2:$D$4357,Summary!$A13,'NEM demand data'!$F$2:$F$4357,Summary!$A$4,'NEM demand data'!$H$2:$H$4357,Summary!J$7)*1000 -> 10332.6 | K13: =SUMIFS('NEM demand data'!$I$2:$I$4357,'NEM demand data'!$D$2:$D$4357,Summary!$A13,'NEM demand data'!$F$2:$F$4357,Summary!$A$4,'NEM demand data'!$H$2:$H$4357,Summary!K$7)*1000 -> 9532.8 | L13: =SUMIFS('NEM demand data'!$I$2:$I$4357,'NEM demand data'!$D$2:$D$4357,Summary!$A13,'NEM demand data'!$F$2:$F$4357,Summary!$A$4,'NEM demand data'!$H$2:$H$4357,Summary!L$7)*1000 -> 9596.8 | M13: =SUMIFS('NEM demand data'!$I$2:$I$4357,'NEM demand data'!$D$2:$D$4357,Summary!$A13,'NEM demand data'!$F$2:$F$4357,Summary!$A$4,'NEM demand data'!$H$2:$H$4357,Summary!M$7)*1000 -> 9728.1 | N13: =SUMIFS('NEM demand data'!$I$2:$I$4357,'NEM demand data'!$D$2:$D$4357,Summary!$A13,'NEM demand data'!$F$2:$F$4357,Summary!$A$4,'NEM demand data'!$H$2:$H$4357,Summary!N$7)*1000 -> 9845.4 | O13: =SUMIFS('NEM demand data'!$I$2:$I$4357,'NEM demand data'!$D$2:$D$4357,Summary!$A13,'NEM demand data'!$F$2:$F$4357,Summary!$A$4,'NEM demand data'!$H$2:$H$4357,Summary!O$7)*1000 -> 9939.5 | P13: =SUMIFS('NEM demand data'!$I$2:$I$4357,'NEM demand data'!$D$2:$D$4357,Summary!$A13,'NEM demand data'!$F$2:$F$4357,Summary!$A$4,'NEM demand data'!$H$2:$H$4357,Summary!P$7)*1000 -> 10042 | Q13: =SUMIFS('NEM demand data'!$I$2:$I$4357,'NEM demand data'!$D$2:$D$4357,Summary!$A13,'NEM demand data'!$F$2:$F$4357,Summary!$A$4,'NEM demand data'!$H$2:$H$4357,Summary!Q$7)*1000 -> 10164.7 | ... AN13: =SUMIFS('NEM demand data'!$I$2:$I$4357,'NEM demand data'!$D$2:$D$4357,Summary!$A13,'NEM demand data'!$F$2:$F$4357,Summary!$A$4,'NEM demand data'!$H$2:$H$4357,Summary!AN$7)*1000 -> 13542 | AO13: =AN13/AM13*AN13 -> 13751.595
A14: Small Non Scheduled Generation | B14: GWh | J14: =SUMIFS('NEM demand data'!$I$2:$I$4357,'NEM demand data'!$D$2:$D$4357,Summary!$A14,'NEM demand data'!$F$2:$F$4357,Summary!$A$4,'NEM demand data'!$H$2:$H$4357,Summary!J$7)*1000 -> 6836.2 | K14: =SUMIFS('NEM demand data'!$I$2:$I$4357,'NEM demand data'!$D$2:$D$4357,Summary!$A14,'NEM demand data'!$F$2:$F$4357,Summary!$A$4,'NEM demand data'!$H$2:$H$4357,Summary!K$7)*1000 -> 7052.3 | L14: =SUMIFS('NEM demand data'!$I$2:$I$4357,'NEM demand data'!$D$2:$D$4357,Summary!$A14,'NEM demand data'!$F$2:$F$4357,Summary!$A$4,'NEM demand data'!$H$2:$H$4357,Summary!L$7)*1000 -> 7563.4 | M14: =SUMIFS('NEM demand data'!$I$2:$I$4357,'NEM demand data'!$D$2:$D$4357,Summary!$A14,'NEM demand data'!$F$2:$F$4357,Summary!$A$4,'NEM demand data'!$H$2:$H$4357,Summary!M$7)*1000 -> 8074.3 | N14: =SUMIFS('NEM demand data'!$I$2:$I$4357,'NEM demand data'!$D$2:$D$4357,Summary!$A14,'NEM demand data'!$F$2:$F$4357,Summary!$A$4,'NEM demand data'!$H$2:$H$4357,Summary!N$7)*1000 -> 8610.3 | O14: =SUMIFS('NEM demand data'!$I$2:$I$4357,'NEM demand data'!$D$2:$D$4357,Summary!$A14,'NEM demand data'!$F$2:$F$4357,Summary!$A$4,'NEM demand data'!$H$2:$H$4357,Summary!O$7)*1000 -> 9065.2 | P14: =SUMIFS('NEM demand data'!$I$2:$I$4357,'NEM demand data'!$D$2:$D$4357,Summary!$A14,'NEM demand data'!$F$2:$F$4357,Summary!$A$4,'NEM demand data'!$H$2:$H$4357,Summary!P$7)*1000 -> 9571.9 | Q14: =SUMIFS('NEM demand data'!$I$2:$I$4357,'NEM demand data'!$D$2:$D$4357,Summary!$A14,'NEM demand data'!$F$2:$F$4357,Summary!$A$4,'NEM demand data'!$H$2:$H$4357,Summary!Q$7)*1000 -> 10217.9 | ... AN14: =SUMIFS('NEM demand data'!$I$2:$I$4357,'NEM demand data'!$D$2:$D$4357,Summary!$A14,'NEM demand data'!$F$2:$F$4357,Summary!$A$4,'NEM demand data'!$H$2:$H$4357,Summary!AN$7)*1000 -> 35352.6 | AO14: =AN14/AM14*AN14 -> 36714.952
A15: Auxiliary | B15: GWh | J15: =SUMIFS('NEM demand data'!$I$2:$I$4357,'NEM demand data'!$D$2:$D$4357,Summary!$A15,'NEM demand data'!$F$2:$F$4357,Summary!$A$4,'NEM demand data'!$H$2:$H$4357,Summary!J$7)*1000 -> 7782.3 | K15: =SUMIFS('NEM demand data'!$I$2:$I$4357,'NEM demand data'!$D$2:$D$4357,Summary!$A15,'NEM demand data'!$F$2:$F$4357,Summary!$A$4,'NEM demand data'!$H$2:$H$4357,Summary!K$7)*1000 -> 7928 | L15: =SUMIFS('NEM demand data'!$I$2:$I$4357,'NEM demand data'!$D$2:$D$4357,Summary!$A15,'NEM demand data'!$F$2:$F$4357,Summary!$A$4,'NEM demand data'!$H$2:$H$4357,Summary!L$7)*1000 -> 8069.9 | M15: =SUMIFS('NEM demand data'!$I$2:$I$4357,'NEM demand data'!$D$2:$D$4357,Summary!$A15,'NEM demand data'!$F$2:$F$4357,Summary!$A$4,'NEM demand data'!$H$2:$H$4357,Summary!M$7)*1000 -> 7794 | N15: =SUMIFS('NEM demand data'!$I$2:$I$4357,'NEM demand data'!$D$2:$D$4357,Summary!$A15,'NEM demand data'!$F$2:$F$4357,Summary!$A$4,'NEM demand data'!$H$2:$H$4357,Summary!N$7)*1000 -> 6300.3 | O15: =SUMIFS('NEM demand data'!$I$2:$I$4357,'NEM demand data'!$D$2:$D$4357,Summary!$A15,'NEM demand data'!$F$2:$F$4357,Summary!$A$4,'NEM demand data'!$H$2:$H$4357,Summary!O$7)*1000 -> 5243.7 | P15: =SUMIFS('NEM demand data'!$I$2:$I$4357,'NEM demand data'!$D$2:$D$4357,Summary!$A15,'NEM demand data'!$F$2:$F$4357,Summary!$A$4,'NEM demand data'!$H$2:$H$4357,Summary!P$7)*1000 -> 4684.8 | Q15: =SUMIFS('NEM demand data'!$I$2:$I$4357,'NEM demand data'!$D$2:$D$4357,Summary!$A15,'NEM demand data'!$F$2:$F$4357,Summary!$A$4,'NEM demand data'!$H$2:$H$4357,Summary!Q$7)*1000 -> 3933.8 | ... AN15: =SUMIFS('NEM demand data'!$I$2:$I$4357,'NEM demand data'!$D$2:$D$4357,Summary!$A15,'NEM demand data'!$F$2:$F$4357,Summary!$A$4,'NEM demand data'!$H$2:$H$4357,Summary!AN$7)*1000 -> 755.7 | AO15: =AN15/AM15*AN15 -> 764.399
A16: Rooftop PV | B16: GWh | J16: =K16/L16*K16 -> 24233.455 | K16: =SUMIFS('NEM demand data'!$I$2:$I$4357,'NEM demand data'!$D$2:$D$4357,Summary!$A16,'NEM demand data'!$F$2:$F$4357,Summary!$A$4,'NEM demand data'!$H$2:$H$4357,Summary!K$7)*1000 -> 26959.5 | L16: =SUMIFS('NEM demand data'!$I$2:$I$4357,'NEM demand data'!$D$2:$D$4357,Summary!$A16,'NEM demand data'!$F$2:$F$4357,Summary!$A$4,'NEM demand data'!$H$2:$H$4357,Summary!L$7)*1000 -> 29992.2 | M16: =SUMIFS('NEM demand data'!$I$2:$I$4357,'NEM demand data'!$D$2:$D$4357,Summary!$A16,'NEM demand data'!$F$2:$F$4357,Summary!$A$4,'NEM demand data'!$H$2:$H$4357,Summary!M$7)*1000 -> 33056.4 | N16: =SUMIFS('NEM demand data'!$I$2:$I$4357,'NEM demand data'!$D$2:$D$4357,Summary!$A16,'NEM demand data'!$F$2:$F$4357,Summary!$A$4,'NEM demand data'!$H$2:$H$4357,Summary!N$7)*1000 -> 36191.4 | O16: =SUMIFS('NEM demand data'!$I$2:$I$4357,'NEM demand data'!$D$2:$D$4357,Summary!$A16,'NEM demand data'!$F$2:$F$4357,Summary!$A$4,'NEM demand data'!$H$2:$H$4357,Summary!O$7)*1000 -> 38881 | P16: =SUMIFS('NEM demand data'!$I$2:$I$4357,'NEM demand data'!$D$2:$D$4357,Summary!$A16,'NEM demand data'!$F$2:$F$4357,Summary!$A$4,'NEM demand data'!$H$2:$H$4357,Summary!P$7)*1000 -> 41225.7 | Q16: =SUMIFS('NEM demand data'!$I$2:$I$4357,'NEM demand data'!$D$2:$D$4357,Summary!$A16,'NEM demand data'!$F$2:$F$4357,Summary!$A$4,'NEM demand data'!$H$2:$H$4357,Summary!Q$7)*1000 -> 43744.3 | R16: =SUMIFS('NEM demand data'!$I$2:$I$4357,'NEM demand data'!$D$2:$D$4357,Summary!$A16,'NEM demand data'!$F$2:$F$4357,Summary!$A$4,'NEM demand data'!$H$2:$H$4357,Summary!R$7)*1000 -> 46507.2 | ... AN16: =SUMIFS('NEM demand data'!$I$2:$I$4357,'NEM demand data'!$D$2:$D$4357,Summary!$A16,'NEM demand data'!$F$2:$F$4357,Summary!$A$4,'NEM demand data'!$H$2:$H$4357,Summary!AN$7)*1000 -> 113487.9 | AO16: =AN16/AM16*AN16 -> 116511.67
A17: Operational (Sent Out) | B17: GWh | J17: =SUMIFS('NEM demand data'!$I$2:$I$4357,'NEM demand data'!$D$2:$D$4357,Summary!$A17,'NEM demand data'!$F$2:$F$4357,Summary!$A$4,'NEM demand data'!$H$2:$H$4357,Summary!J$7)*1000 -> 177057.2 | K17: =SUM(K8:K13) -> 175566.1 | L17: =SUM(L8:L13) -> 177124.1 | M17: =SUM(M8:M13) -> 179848.1 | N17: =SUM(N8:N13) -> 181709.5 | O17: =SUM(O8:O13) -> 183548.9 | P17: =SUM(P8:P13) -> 187543.4 | Q17: =SUM(Q8:Q13) -> 192484.5 | R17: =SUM(R8:R13) -> 198050.7 | ... AN17: =SUM(AN8:AN13) -> 289603.3 | AO17: =AN17/AM17*AN17 -> 292460.21
A18: Operational (As Generated, incl Auxiliary) + Small Non Scheduled Generation | B18: GWh | J18: =J17+J15+J14 -> 191675.7 | K18: =K17+K15+K14 -> 190546.4 | L18: =L17+L15+L14 -> 192757.4 | M18: =M17+M15+M14 -> 195716.4 | N18: =N17+N15+N14 -> 196620.1 | O18: =O17+O15+O14 -> 197857.8 | P18: =P17+P15+P14 -> 201800.1 | Q18: =Q17+Q15+Q14 -> 206636.2 | ... AO18: =AO17+AO15+AO14 -> 329939.56
A19: Underlying Demand - Operational Sent out + Rooftop PV + Non-scheduled | B19: GWh | J19: =SUM(J17+J16+J14) -> 208126.86 | K19: =SUM(K17+K16+K14) -> 209577.9 | L19: =SUM(L17+L16+L14) -> 214679.7 | M19: =SUM(M17+M16+M14) -> 220978.8 | N19: =SUM(N17+N16+N14) -> 226511.2 | O19: =SUM(O17+O16+O14) -> 231495.1 | P19: =SUM(P17+P16+P14) -> 238341 | Q19: =SUM(Q17+Q16+Q14) -> 246446.7 | ... AO19: =SUM(AO17+AO16+AO14) -> 445686.83
A22: WEM
A23: Source | B23: WEM ESOO 2024
A24: WEM Demand breakdown | C24: SWIS
A25: Financial Year | C25: 2017 | D25: 2018 | E25: 2019 | F25: 2020 | G25: 2021 | H25: 2022 | I25: 2023 | J25: 2024 | K25: 2025 | L25: 2026 | M25: 2027 | N25: 2028 | O25: 2029 | P25: 2030 | Q25: 2031 | R25: 2032 | S25: 2033 | T25: 2034 | U25: 2035 | V25: 2036 | W25: 2037 | X25: 2038 | Y25: 2039 | Z25: 2040 | AA25: 2041 | AB25: 2042 | AC25: 2043 | AD25: 2044 | AE25: 2045 | AF25: 2046 | AG25: 2047 | AH25: 2048 | AI25: 2049 | AJ25: 2050 | AK25: 2051 | AL25: 2052 | AM25: 2053 | AN25: 2054 | AO25: 2055
A26: Residential | B26: GWh | J26: =SUMIFS('WEM demand data'!$I$2:$I$4357,'WEM demand data'!$D$2:$D$4357,Summary!$A26,'WEM demand data'!$F$2:$F$4357,Summary!$C$24,'WEM demand data'!$H$2:$H$4357,Summary!J$25)*1000 -> 3249.5 | K26: =SUMIFS('WEM demand data'!$I$2:$I$4357,'WEM demand data'!$D$2:$D$4357,Summary!$A26,'WEM demand data'!$F$2:$F$4357,Summary!$C$24,'WEM demand data'!$H$2:$H$4357,Summary!K$25)*1000 -> 2996.4 | L26: =SUMIFS('WEM demand data'!$I$2:$I$4357,'WEM demand data'!$D$2:$D$4357,Summary!$A26,'WEM demand data'!$F$2:$F$4357,Summary!$C$24,'WEM demand data'!$H$2:$H$4357,Summary!L$25)*1000 -> 2705 | M26: =SUMIFS('WEM demand data'!$I$2:$I$4357,'WEM demand data'!$D$2:$D$4357,Summary!$A26,'WEM demand data'!$F$2:$F$4357,Summary!$C$24,'WEM demand data'!$H$2:$H$4357,Summary!M$25)*1000 -> 2382.7 | N26: =SUMIFS('WEM demand data'!$I$2:$I$4357,'WEM demand data'!$D$2:$D$4357,Summary!$A26,'WEM demand data'!$F$2:$F$4357,Summary!$C$24,'WEM demand data'!$H$2:$H$4357,Summary!N$25)*1000 -> 2018.2 | O26: =SUMIFS('WEM demand data'!$I$2:$I$4357,'WEM demand data'!$D$2:$D$4357,Summary!$A26,'WEM demand data'!$F$2:$F$4357,Summary!$C$24,'WEM demand data'!$H$2:$H$4357,Summary!O$25)*1000 -> 1631.8 | P26: =SUMIFS('WEM demand data'!$I$2:$I$4357,'WEM demand data'!$D$2:$D$4357,Summary!$A26,'WEM demand data'!$F$2:$F$4357,Summary!$C$24,'WEM demand data'!$H$2:$H$4357,Summary!P$25)*1000 -> 1279.5 | Q26: =SUMIFS('WEM demand data'!$I$2:$I$4357,'WEM demand data'!$D$2:$D$4357,Summary!$A26,'WEM demand data'!$F$2:$F$4357,Summary!$C$24,'WEM demand data'!$H$2:$H$4357,Summary!Q$25)*1000 -> 916.6 | ... T26: =SUMIFS('WEM demand data'!$I$2:$I$4357,'WEM demand data'!$D$2:$D$4357,Summary!$A26,'WEM demand data'!$F$2:$F$4357,Summary!$C$24,'WEM demand data'!$H$2:$H$4357,Summary!T$25)*1000 -> -180.9 | U26: =SUMIFS('WEM demand data'!$I$2:$I$4357,'WEM demand data'!$D$2:$D$4357,Summary!$A26,'WEM demand data'!$F$2:$F$4357,Summary!$A$4,'WEM demand data'!$H$2:$H$4357,Summary!U$7)*1000 -> 0 | V26: =SUMIFS('WEM demand data'!$I$2:$I$4357,'WEM demand data'!$D$2:$D$4357,Summary!$A26,'WEM demand data'!$F$2:$F$4357,Summary!$A$4,'WEM demand data'!$H$2:$H$4357,Summary!V$7)*1000 -> 0 | W26: =SUMIFS('WEM demand data'!$I$2:$I$4357,'WEM demand data'!$D$2:$D$4357,Summary!$A26,'WEM demand data'!$F$2:$F$4357,Summary!$A$4,'WEM demand data'!$H$2:$H$4357,Summary!W$7)*1000 -> 0 | X26: =SUMIFS('WEM demand data'!$I$2:$I$4357,'WEM demand data'!$D$2:$D$4357,Summary!$A26,'WEM demand data'!$F$2:$F$4357,Summary!$A$4,'WEM demand data'!$H$2:$H$4357,Summary!X$7)*1000 -> 0 | Y26: =SUMIFS('WEM demand data'!$I$2:$I$4357,'WEM demand data'!$D$2:$D$4357,Summary!$A26,'WEM demand data'!$F$2:$F$4357,Summary!$A$4,'WEM demand data'!$H$2:$H$4357,Summary!Y$7)*1000 -> 0 | Z26: =SUMIFS('WEM demand data'!$I$2:$I$4357,'WEM demand data'!$D$2:$D$4357,Summary!$A26,'WEM demand data'!$F$2:$F$4357,Summary!$A$4,'WEM demand data'!$H$2:$H$4357,Summary!Z$7)*1000 -> 0 | AA26: =SUMIFS('WEM demand data'!$I$2:$I$4357,'WEM demand data'!$D$2:$D$4357,Summary!$A26,'WEM demand data'!$F$2:$F$4357,Summary!$A$4,'WEM demand data'!$H$2:$H$4357,Summary!AA$7)*1000 -> 0 | AB26: =SUMIFS('WEM demand data'!$I$2:$I$4357,'WEM demand data'!$D$2:$D$4357,Summary!$A26,'WEM demand data'!$F$2:$F$4357,Summary!$A$4,'WEM demand data'!$H$2:$H$4357,Summary!AB$7)*1000 -> 0 | ... AJ26: =SUMIFS('WEM demand data'!$I$2:$I$4357,'WEM demand data'!$D$2:$D$4357,Summary!$A26,'WEM demand data'!$F$2:$F$4357,Summary!$A$4,'WEM demand data'!$H$2:$H$4357,Summary!AJ$7)*1000 -> 0
A27: Business | B27: GWh | J27: =SUMIFS('WEM demand data'!$I$2:$I$4357,'WEM demand data'!$D$2:$D$4357,Summary!$A27,'WEM demand data'!$F$2:$F$4357,Summary!$C$24,'WEM demand data'!$H$2:$H$4357,Summary!J$25)*1000 -> 13031 | K27: =SUMIFS('WEM demand data'!$I$2:$I$4357,'WEM demand data'!$D$2:$D$4357,Summary!$A27,'WEM demand data'!$F$2:$F$4357,Summary!$C$24,'WEM demand data'!$H$2:$H$4357,Summary!K$25)*1000 -> 13394.3 | L27: =SUMIFS('WEM demand data'!$I$2:$I$4357,'WEM demand data'!$D$2:$D$4357,Summary!$A27,'WEM demand data'!$F$2:$F$4357,Summary!$C$24,'WEM demand data'!$H$2:$H$4357,Summary!L$25)*1000 -> 13511.4 | M27: =SUMIFS('WEM demand data'!$I$2:$I$4357,'WEM demand data'!$D$2:$D$4357,Summary!$A27,'WEM demand data'!$F$2:$F$4357,Summary!$C$24,'WEM demand data'!$H$2:$H$4357,Summary!M$25)*1000 -> 13627.1 | N27: =SUMIFS('WEM demand data'!$I$2:$I$4357,'WEM demand data'!$D$2:$D$4357,Summary!$A27,'WEM demand data'!$F$2:$F$4357,Summary!$C$24,'WEM demand data'!$H$2:$H$4357,Summary!N$25)*1000 -> 13643.5 | O27: =SUMIFS('WEM demand data'!$I$2:$I$4357,'WEM demand data'!$D$2:$D$4357,Summary!$A27,'WEM demand data'!$F$2:$F$4357,Summary!$C$24,'WEM demand data'!$H$2:$H$4357,Summary!O$25)*1000 -> 13802.7 | P27: =SUMIFS('WEM demand data'!$I$2:$I$4357,'WEM demand data'!$D$2:$D$4357,Summary!$A27,'WEM demand data'!$F$2:$F$4357,Summary!$C$24,'WEM demand data'!$H$2:$H$4357,Summary!P$25)*1000 -> 13869.4 | Q27: =SUMIFS('WEM demand data'!$I$2:$I$4357,'WEM demand data'!$D$2:$D$4357,Summary!$A27,'WEM demand data'!$F$2:$F$4357,Summary!$C$24,'WEM demand data'!$H$2:$H$4357,Summary!Q$25)*1000 -> 13926.3 | ... T27: =SUMIFS('WEM demand data'!$I$2:$I$4357,'WEM demand data'!$D$2:$D$4357,Summary!$A27,'WEM demand data'!$F$2:$F$4357,Summary!$C$24,'WEM demand data'!$H$2:$H$4357,Summary!T$25)*1000 -> 14130.8 | U27: =SUMIFS('WEM demand data'!$I$2:$I$4357,'WEM demand data'!$D$2:$D$4357,Summary!$A27,'WEM demand data'!$F$2:$F$4357,Summary!$A$4,'WEM demand data'!$H$2:$H$4357,Summary!U$7)*1000 -> 0 | V27: =SUMIFS('WEM demand data'!$I$2:$I$4357,'WEM demand data'!$D$2:$D$4357,Summary!$A27,'WEM demand data'!$F$2:$F$4357,Summary!$A$4,'WEM demand data'!$H$2:$H$4357,Summary!V$7)*1000 -> 0 | W27: =SUMIFS('WEM demand data'!$I$2:$I$4357,'WEM demand data'!$D$2:$D$4357,Summary!$A27,'WEM demand data'!$F$2:$F$4357,Summary!$A$4,'WEM demand data'!$H$2:$H$4357,Summary!W$7)*1000 -> 0 | X27: =SUMIFS('WEM demand data'!$I$2:$I$4357,'WEM demand data'!$D$2:$D$4357,Summary!$A27,'WEM demand data'!$F$2:$F$4357,Summary!$A$4,'WEM demand data'!$H$2:$H$4357,Summary!X$7)*1000 -> 0 | Y27: =SUMIFS('WEM demand data'!$I$2:$I$4357,'WEM demand data'!$D$2:$D$4357,Summary!$A27,'WEM demand data'!$F$2:$F$4357,Summary!$A$4,'WEM demand data'!$H$2:$H$4357,Summary!Y$7)*1000 -> 0 | Z27: =SUMIFS('WEM demand data'!$I$2:$I$4357,'WEM demand data'!$D$2:$D$4357,Summary!$A27,'WEM demand data'!$F$2:$F$4357,Summary!$A$4,'WEM demand data'!$H$2:$H$4357,Summary!Z$7)*1000 -> 0 | AA27: =SUMIFS('WEM demand data'!$I$2:$I$4357,'WEM demand data'!$D$2:$D$4357,Summary!$A27,'WEM demand data'!$F$2:$F$4357,Summary!$A$4,'WEM demand data'!$H$2:$H$4357,Summary!AA$7)*1000 -> 0 | AB27: =SUMIFS('WEM demand data'!$I$2:$I$4357,'WEM demand data'!$D$2:$D$4357,Summary!$A27,'WEM demand data'!$F$2:$F$4357,Summary!$A$4,'WEM demand data'!$H$2:$H$4357,Summary!AB$7)*1000 -> 0 | ... AJ27: =SUMIFS('WEM demand data'!$I$2:$I$4357,'WEM demand data'!$D$2:$D$4357,Summary!$A27,'WEM demand data'!$F$2:$F$4357,Summary!$A$4,'WEM demand data'!$H$2:$H$4357,Summary!AJ$7)*1000 -> 0
A28: Electrification | B28: GWh | J28: =SUMIFS('WEM demand data'!$I$2:$I$4357,'WEM demand data'!$D$2:$D$4357,Summary!$A28,'WEM demand data'!$F$2:$F$4357,Summary!$C$24,'WEM demand data'!$H$2:$H$4357,Summary!J$25)*1000 -> 10.6 | K28: =SUMIFS('WEM demand data'!$I$2:$I$4357,'WEM demand data'!$D$2:$D$4357,Summary!$A28,'WEM demand data'!$F$2:$F$4357,Summary!$C$24,'WEM demand data'!$H$2:$H$4357,Summary!K$25)*1000 -> 75.6 | L28: =SUMIFS('WEM demand data'!$I$2:$I$4357,'WEM demand data'!$D$2:$D$4357,Summary!$A28,'WEM demand data'!$F$2:$F$4357,Summary!$C$24,'WEM demand data'!$H$2:$H$4357,Summary!L$25)*1000 -> 237.8 | M28: =SUMIFS('WEM demand data'!$I$2:$I$4357,'WEM demand data'!$D$2:$D$4357,Summary!$A28,'WEM demand data'!$F$2:$F$4357,Summary!$C$24,'WEM demand data'!$H$2:$H$4357,Summary!M$25)*1000 -> 539.7 | N28: =SUMIFS('WEM demand data'!$I$2:$I$4357,'WEM demand data'!$D$2:$D$4357,Summary!$A28,'WEM demand data'!$F$2:$F$4357,Summary!$C$24,'WEM demand data'!$H$2:$H$4357,Summary!N$25)*1000 -> 997.3 | O28: =SUMIFS('WEM demand data'!$I$2:$I$4357,'WEM demand data'!$D$2:$D$4357,Summary!$A28,'WEM demand data'!$F$2:$F$4357,Summary!$C$24,'WEM demand data'!$H$2:$H$4357,Summary!O$25)*1000 -> 1639 | P28: =SUMIFS('WEM demand data'!$I$2:$I$4357,'WEM demand data'!$D$2:$D$4357,Summary!$A28,'WEM demand data'!$F$2:$F$4357,Summary!$C$24,'WEM demand data'!$H$2:$H$4357,Summary!P$25)*1000 -> 3031.1 | Q28: =SUMIFS('WEM demand data'!$I$2:$I$4357,'WEM demand data'!$D$2:$D$4357,Summary!$A28,'WEM demand data'!$F$2:$F$4357,Summary!$C$24,'WEM demand data'!$H$2:$H$4357,Summary!Q$25)*1000 -> 4834.1 | ... T28: =SUMIFS('WEM demand data'!$I$2:$I$4357,'WEM demand data'!$D$2:$D$4357,Summary!$A28,'WEM demand data'!$F$2:$F$4357,Summary!$C$24,'WEM demand data'!$H$2:$H$4357,Summary!T$25)*1000 -> 8139.3 | U28: =SUMIFS('WEM demand data'!$I$2:$I$4357,'WEM demand data'!$D$2:$D$4357,Summary!$A28,'WEM demand data'!$F$2:$F$4357,Summary!$A$4,'WEM demand data'!$H$2:$H$4357,Summary!U$7)*1000 -> 0 | V28: =SUMIFS('WEM demand data'!$I$2:$I$4357,'WEM demand data'!$D$2:$D$4357,Summary!$A28,'WEM demand data'!$F$2:$F$4357,Summary!$A$4,'WEM demand data'!$H$2:$H$4357,Summary!V$7)*1000 -> 0 | W28: =SUMIFS('WEM demand data'!$I$2:$I$4357,'WEM demand data'!$D$2:$D$4357,Summary!$A28,'WEM demand data'!$F$2:$F$4357,Summary!$A$4,'WEM demand data'!$H$2:$H$4357,Summary!W$7)*1000 -> 0 | X28: =SUMIFS('WEM demand data'!$I$2:$I$4357,'WEM demand data'!$D$2:$D$4357,Summary!$A28,'WEM demand data'!$F$2:$F$4357,Summary!$A$4,'WEM demand data'!$H$2:$H$4357,Summary!X$7)*1000 -> 0 | Y28: =SUMIFS('WEM demand data'!$I$2:$I$4357,'WEM demand data'!$D$2:$D$4357,Summary!$A28,'WEM demand data'!$F$2:$F$4357,Summary!$A$4,'WEM demand data'!$H$2:$H$4357,Summary!Y$7)*1000 -> 0 | Z28: =SUMIFS('WEM demand data'!$I$2:$I$4357,'WEM demand data'!$D$2:$D$4357,Summary!$A28,'WEM demand data'!$F$2:$F$4357,Summary!$A$4,'WEM demand data'!$H$2:$H$4357,Summary!Z$7)*1000 -> 0 | AA28: =SUMIFS('WEM demand data'!$I$2:$I$4357,'WEM demand data'!$D$2:$D$4357,Summary!$A28,'WEM demand data'!$F$2:$F$4357,Summary!$A$4,'WEM demand data'!$H$2:$H$4357,Summary!AA$7)*1000 -> 0 | AB28: =SUMIFS('WEM demand data'!$I$2:$I$4357,'WEM demand data'!$D$2:$D$4357,Summary!$A28,'WEM demand data'!$F$2:$F$4357,Summary!$A$4,'WEM demand data'!$H$2:$H$4357,Summary!AB$7)*1000 -> 0 | ... AJ28: =SUMIFS('WEM demand data'!$I$2:$I$4357,'WEM demand data'!$D$2:$D$4357,Summary!$A28,'WEM demand data'!$F$2:$F$4357,Summary!$A$4,'WEM demand data'!$H$2:$H$4357,Summary!AJ$7)*1000 -> 0
A29: Electric Vehicles | B29: GWh | J29: =SUMIFS('WEM demand data'!$I$2:$I$4357,'WEM demand data'!$D$2:$D$4357,Summary!$A29,'WEM demand data'!$F$2:$F$4357,Summary!$C$24,'WEM demand data'!$H$2:$H$4357,Summary!J$25)*1000 -> 51 | K29: =SUMIFS('WEM demand data'!$I$2:$I$4357,'WEM demand data'!$D$2:$D$4357,Summary!$A29,'WEM demand data'!$F$2:$F$4357,Summary!$C$24,'WEM demand data'!$H$2:$H$4357,Summary!K$25)*1000 -> 96.1 | L29: =SUMIFS('WEM demand data'!$I$2:$I$4357,'WEM demand data'!$D$2:$D$4357,Summary!$A29,'WEM demand data'!$F$2:$F$4357,Summary!$C$24,'WEM demand data'!$H$2:$H$4357,Summary!L$25)*1000 -> 164.2 | M29: =SUMIFS('WEM demand data'!$I$2:$I$4357,'WEM demand data'!$D$2:$D$4357,Summary!$A29,'WEM demand data'!$F$2:$F$4357,Summary!$C$24,'WEM demand data'!$H$2:$H$4357,Summary!M$25)*1000 -> 254.4 | N29: =SUMIFS('WEM demand data'!$I$2:$I$4357,'WEM demand data'!$D$2:$D$4357,Summary!$A29,'WEM demand data'!$F$2:$F$4357,Summary!$C$24,'WEM demand data'!$H$2:$H$4357,Summary!N$25)*1000 -> 365.5 | O29: =SUMIFS('WEM demand data'!$I$2:$I$4357,'WEM demand data'!$D$2:$D$4357,Summary!$A29,'WEM demand data'!$F$2:$F$4357,Summary!$C$24,'WEM demand data'!$H$2:$H$4357,Summary!O$25)*1000 -> 493.3 | P29: =SUMIFS('WEM demand data'!$I$2:$I$4357,'WEM demand data'!$D$2:$D$4357,Summary!$A29,'WEM demand data'!$F$2:$F$4357,Summary!$C$24,'WEM demand data'!$H$2:$H$4357,Summary!P$25)*1000 -> 644.4 | Q29: =SUMIFS('WEM demand data'!$I$2:$I$4357,'WEM demand data'!$D$2:$D$4357,Summary!$A29,'WEM demand data'!$F$2:$F$4357,Summary!$C$24,'WEM demand data'!$H$2:$H$4357,Summary!Q$25)*1000 -> 820.9 | ... T29: =SUMIFS('WEM demand data'!$I$2:$I$4357,'WEM demand data'!$D$2:$D$4357,Summary!$A29,'WEM demand data'!$F$2:$F$4357,Summary!$C$24,'WEM demand data'!$H$2:$H$4357,Summary!T$25)*1000 -> 1474.8 | U29: =SUMIFS('WEM demand data'!$I$2:$I$4357,'WEM demand data'!$D$2:$D$4357,Summary!$A29,'WEM demand data'!$F$2:$F$4357,Summary!$A$4,'WEM demand data'!$H$2:$H$4357,Summary!U$7)*1000 -> 0 | V29: =SUMIFS('WEM demand data'!$I$2:$I$4357,'WEM demand data'!$D$2:$D$4357,Summary!$A29,'WEM demand data'!$F$2:$F$4357,Summary!$A$4,'WEM demand data'!$H$2:$H$4357,Summary!V$7)*1000 -> 0 | W29: =SUMIFS('WEM demand data'!$I$2:$I$4357,'WEM demand data'!$D$2:$D$4357,Summary!$A29,'WEM demand data'!$F$2:$F$4357,Summary!$A$4,'WEM demand data'!$H$2:$H$4357,Summary!W$7)*1000 -> 0 | X29: =SUMIFS('WEM demand data'!$I$2:$I$4357,'WEM demand data'!$D$2:$D$4357,Summary!$A29,'WEM demand data'!$F$2:$F$4357,Summary!$A$4,'WEM demand data'!$H$2:$H$4357,Summary!X$7)*1000 -> 0 | Y29: =SUMIFS('WEM demand data'!$I$2:$I$4357,'WEM demand data'!$D$2:$D$4357,Summary!$A29,'WEM demand data'!$F$2:$F$4357,Summary!$A$4,'WEM demand data'!$H$2:$H$4357,Summary!Y$7)*1000 -> 0 | Z29: =SUMIFS('WEM demand data'!$I$2:$I$4357,'WEM demand data'!$D$2:$D$4357,Summary!$A29,'WEM demand data'!$F$2:$F$4357,Summary!$A$4,'WEM demand data'!$H$2:$H$4357,Summary!Z$7)*1000 -> 0 | AA29: =SUMIFS('WEM demand data'!$I$2:$I$4357,'WEM demand data'!$D$2:$D$4357,Summary!$A29,'WEM demand data'!$F$2:$F$4357,Summary!$A$4,'WEM demand data'!$H$2:$H$4357,Summary!AA$7)*1000 -> 0 | AB29: =SUMIFS('WEM demand data'!$I$2:$I$4357,'WEM demand data'!$D$2:$D$4357,Summary!$A29,'WEM demand data'!$F$2:$F$4357,Summary!$A$4,'WEM demand data'!$H$2:$H$4357,Summary!AB$7)*1000 -> 0 | ... AJ29: =SUMIFS('WEM demand data'!$I$2:$I$4357,'WEM demand data'!$D$2:$D$4357,Summary!$A29,'WEM demand data'!$F$2:$F$4357,Summary!$A$4,'WEM demand data'!$H$2:$H$4357,Summary!AJ$7)*1000 -> 0
A30: Hydrogen Production | B30: GWh | J30: =SUMIFS('WEM demand data'!$I$2:$I$4357,'WEM demand data'!$D$2:$D$4357,Summary!$A30,'WEM demand data'!$F$2:$F$4357,Summary!$C$24,'WEM demand data'!$H$2:$H$4357,Summary!J$25)*1000 -> 0.3 | K30: =SUMIFS('WEM demand data'!$I$2:$I$4357,'WEM demand data'!$D$2:$D$4357,Summary!$A30,'WEM demand data'!$F$2:$F$4357,Summary!$C$24,'WEM demand data'!$H$2:$H$4357,Summary!K$25)*1000 -> 1.2 | L30: =SUMIFS('WEM demand data'!$I$2:$I$4357,'WEM demand data'!$D$2:$D$4357,Summary!$A30,'WEM demand data'!$F$2:$F$4357,Summary!$C$24,'WEM demand data'!$H$2:$H$4357,Summary!L$25)*1000 -> 1.5 | M30: =SUMIFS('WEM demand data'!$I$2:$I$4357,'WEM demand data'!$D$2:$D$4357,Summary!$A30,'WEM demand data'!$F$2:$F$4357,Summary!$C$24,'WEM demand data'!$H$2:$H$4357,Summary!M$25)*1000 -> 1.5 | N30: =SUMIFS('WEM demand data'!$I$2:$I$4357,'WEM demand data'!$D$2:$D$4357,Summary!$A30,'WEM demand data'!$F$2:$F$4357,Summary!$C$24,'WEM demand data'!$H$2:$H$4357,Summary!N$25)*1000 -> 1.5 | O30: =SUMIFS('WEM demand data'!$I$2:$I$4357,'WEM demand data'!$D$2:$D$4357,Summary!$A30,'WEM demand data'!$F$2:$F$4357,Summary!$C$24,'WEM demand data'!$H$2:$H$4357,Summary!O$25)*1000 -> 61.6 | P30: =SUMIFS('WEM demand data'!$I$2:$I$4357,'WEM demand data'!$D$2:$D$4357,Summary!$A30,'WEM demand data'!$F$2:$F$4357,Summary!$C$24,'WEM demand data'!$H$2:$H$4357,Summary!P$25)*1000 -> 283.7 | Q30: =SUMIFS('WEM demand data'!$I$2:$I$4357,'WEM demand data'!$D$2:$D$4357,Summary!$A30,'WEM demand data'!$F$2:$F$4357,Summary!$C$24,'WEM demand data'!$H$2:$H$4357,Summary!Q$25)*1000 -> 478.3 | ... T30: =SUMIFS('WEM demand data'!$I$2:$I$4357,'WEM demand data'!$D$2:$D$4357,Summary!$A30,'WEM demand data'!$F$2:$F$4357,Summary!$C$24,'WEM demand data'!$H$2:$H$4357,Summary!T$25)*1000 -> 2039.3 | U30: =SUMIFS('WEM demand data'!$I$2:$I$4357,'WEM demand data'!$D$2:$D$4357,Summary!$A30,'WEM demand data'!$F$2:$F$4357,Summary!$A$4,'WEM demand data'!$H$2:$H$4357,Summary!U$7)*1000 -> 0 | V30: =SUMIFS('WEM demand data'!$I$2:$I$4357,'WEM demand data'!$D$2:$D$4357,Summary!$A30,'WEM demand data'!$F$2:$F$4357,Summary!$A$4,'WEM demand data'!$H$2:$H$4357,Summary!V$7)*1000 -> 0 | W30: =SUMIFS('WEM demand data'!$I$2:$I$4357,'WEM demand data'!$D$2:$D$4357,Summary!$A30,'WEM demand data'!$F$2:$F$4357,Summary!$A$4,'WEM demand data'!$H$2:$H$4357,Summary!W$7)*1000 -> 0 | X30: =SUMIFS('WEM demand data'!$I$2:$I$4357,'WEM demand data'!$D$2:$D$4357,Summary!$A30,'WEM demand data'!$F$2:$F$4357,Summary!$A$4,'WEM demand data'!$H$2:$H$4357,Summary!X$7)*1000 -> 0 | Y30: =SUMIFS('WEM demand data'!$I$2:$I$4357,'WEM demand data'!$D$2:$D$4357,Summary!$A30,'WEM demand data'!$F$2:$F$4357,Summary!$A$4,'WEM demand data'!$H$2:$H$4357,Summary!Y$7)*1000 -> 0 | Z30: =SUMIFS('WEM demand data'!$I$2:$I$4357,'WEM demand data'!$D$2:$D$4357,Summary!$A30,'WEM demand data'!$F$2:$F$4357,Summary!$A$4,'WEM demand data'!$H$2:$H$4357,Summary!Z$7)*1000 -> 0 | AA30: =SUMIFS('WEM demand data'!$I$2:$I$4357,'WEM demand data'!$D$2:$D$4357,Summary!$A30,'WEM demand data'!$F$2:$F$4357,Summary!$A$4,'WEM demand data'!$H$2:$H$4357,Summary!AA$7)*1000 -> 0 | AB30: =SUMIFS('WEM demand data'!$I$2:$I$4357,'WEM demand data'!$D$2:$D$4357,Summary!$A30,'WEM demand data'!$F$2:$F$4357,Summary!$A$4,'WEM demand data'!$H$2:$H$4357,Summary!AB$7)*1000 -> 0 | ... AJ30: =SUMIFS('WEM demand data'!$I$2:$I$4357,'WEM demand data'!$D$2:$D$4357,Summary!$A30,'WEM demand data'!$F$2:$F$4357,Summary!$A$4,'WEM demand data'!$H$2:$H$4357,Summary!AJ$7)*1000 -> 0
A31: Losses | B31: GWh | E31: =SUMIFS('WEM demand data'!$I$2:$I$4357,'WEM demand data'!$D$2:$D$4357,Summary!$A31,'WEM demand data'!$F$2:$F$4357,Summary!$C$24,'WEM demand data'!$H$2:$H$4357,Summary!E$25)*1000 -> 1396.6 | F31: =SUMIFS('WEM demand data'!$I$2:$I$4357,'WEM demand data'!$D$2:$D$4357,Summary!$A31,'WEM demand data'!$F$2:$F$4357,Summary!$C$24,'WEM demand data'!$H$2:$H$4357,Summary!F$25)*1000 -> 1392.5 | G31: =SUMIFS('WEM demand data'!$I$2:$I$4357,'WEM demand data'!$D$2:$D$4357,Summary!$A31,'WEM demand data'!$F$2:$F$4357,Summary!$C$24,'WEM demand data'!$H$2:$H$4357,Summary!G$25)*1000 -> 1418.9 | H31: =SUMIFS('WEM demand data'!$I$2:$I$4357,'WEM demand data'!$D$2:$D$4357,Summary!$A31,'WEM demand data'!$F$2:$F$4357,Summary!$C$24,'WEM demand data'!$H$2:$H$4357,Summary!H$25)*1000 -> 1312.7 | I31: =SUMIFS('WEM demand data'!$I$2:$I$4357,'WEM demand data'!$D$2:$D$4357,Summary!$A31,'WEM demand data'!$F$2:$F$4357,Summary!$C$24,'WEM demand data'!$H$2:$H$4357,Summary!I$25)*1000 -> 1524.8 | J31: =SUMIFS('WEM demand data'!$I$2:$I$4357,'WEM demand data'!$D$2:$D$4357,Summary!$A31,'WEM demand data'!$F$2:$F$4357,Summary!$C$24,'WEM demand data'!$H$2:$H$4357,Summary!J$25)*1000 -> 1434.9 | K31: =SUMIFS('WEM demand data'!$I$2:$I$4357,'WEM demand data'!$D$2:$D$4357,Summary!$A31,'WEM demand data'!$F$2:$F$4357,Summary!$C$24,'WEM demand data'!$H$2:$H$4357,Summary!K$25)*1000 -> 1454.7 | L31: =SUMIFS('WEM demand data'!$I$2:$I$4357,'WEM demand data'!$D$2:$D$4357,Summary!$A31,'WEM demand data'!$F$2:$F$4357,Summary!$C$24,'WEM demand data'!$H$2:$H$4357,Summary!L$25)*1000 -> 1462.6 | ... T31: =SUMIFS('WEM demand data'!$I$2:$I$4357,'WEM demand data'!$D$2:$D$4357,Summary!$A31,'WEM demand data'!$F$2:$F$4357,Summary!$C$24,'WEM demand data'!$H$2:$H$4357,Summary!T$25)*1000 -> 2270.1 | U31: =SUMIFS('WEM demand data'!$I$2:$I$4357,'WEM demand data'!$D$2:$D$4357,Summary!$A31,'WEM demand data'!$F$2:$F$4357,Summary!$A$4,'WEM demand data'!$H$2:$H$4357,Summary!U$7)*1000 -> 0 | V31: =SUMIFS('WEM demand data'!$I$2:$I$4357,'WEM demand data'!$D$2:$D$4357,Summary!$A31,'WEM demand data'!$F$2:$F$4357,Summary!$A$4,'WEM demand data'!$H$2:$H$4357,Summary!V$7)*1000 -> 0 | W31: =SUMIFS('WEM demand data'!$I$2:$I$4357,'WEM demand data'!$D$2:$D$4357,Summary!$A31,'WEM demand data'!$F$2:$F$4357,Summary!$A$4,'WEM demand data'!$H$2:$H$4357,Summary!W$7)*1000 -> 0 | X31: =SUMIFS('WEM demand data'!$I$2:$I$4357,'WEM demand data'!$D$2:$D$4357,Summary!$A31,'WEM demand data'!$F$2:$F$4357,Summary!$A$4,'WEM demand data'!$H$2:$H$4357,Summary!X$7)*1000 -> 0 | Y31: =SUMIFS('WEM demand data'!$I$2:$I$4357,'WEM demand data'!$D$2:$D$4357,Summary!$A31,'WEM demand data'!$F$2:$F$4357,Summary!$A$4,'WEM demand data'!$H$2:$H$4357,Summary!Y$7)*1000 -> 0 | Z31: =SUMIFS('WEM demand data'!$I$2:$I$4357,'WEM demand data'!$D$2:$D$4357,Summary!$A31,'WEM demand data'!$F$2:$F$4357,Summary!$A$4,'WEM demand data'!$H$2:$H$4357,Summary!Z$7)*1000 -> 0 | AA31: =SUMIFS('WEM demand data'!$I$2:$I$4357,'WEM demand data'!$D$2:$D$4357,Summary!$A31,'WEM demand data'!$F$2:$F$4357,Summary!$A$4,'WEM demand data'!$H$2:$H$4357,Summary!AA$7)*1000 -> 0 | AB31: =SUMIFS('WEM demand data'!$I$2:$I$4357,'WEM demand data'!$D$2:$D$4357,Summary!$A31,'WEM demand data'!$F$2:$F$4357,Summary!$A$4,'WEM demand data'!$H$2:$H$4357,Summary!AB$7)*1000 -> 0 | ... AJ31: =SUMIFS('WEM demand data'!$I$2:$I$4357,'WEM demand data'!$D$2:$D$4357,Summary!$A31,'WEM demand data'!$F$2:$F$4357,Summary!$A$4,'WEM demand data'!$H$2:$H$4357,Summary!AJ$7)*1000 -> 0
A32: Small Non Scheduled Generation | B32: GWh | E32: =SUMIFS('WEM demand data'!$I$2:$I$4357,'WEM demand data'!$D$2:$D$4357,Summary!$A32,'WEM demand data'!$F$2:$F$4357,Summary!$C$24,'WEM demand data'!$H$2:$H$4357,Summary!E$25)*1000 -> 21.3 | F32: =SUMIFS('WEM demand data'!$I$2:$I$4357,'WEM demand data'!$D$2:$D$4357,Summary!$A32,'WEM demand data'!$F$2:$F$4357,Summary!$C$24,'WEM demand data'!$H$2:$H$4357,Summary!F$25)*1000 -> 39 | G32: =SUMIFS('WEM demand data'!$I$2:$I$4357,'WEM demand data'!$D$2:$D$4357,Summary!$A32,'WEM demand data'!$F$2:$F$4357,Summary!$C$24,'WEM demand data'!$H$2:$H$4357,Summary!G$25)*1000 -> 57.1 | H32: =SUMIFS('WEM demand data'!$I$2:$I$4357,'WEM demand data'!$D$2:$D$4357,Summary!$A32,'WEM demand data'!$F$2:$F$4357,Summary!$C$24,'WEM demand data'!$H$2:$H$4357,Summary!H$25)*1000 -> 70.9 | I32: =SUMIFS('WEM demand data'!$I$2:$I$4357,'WEM demand data'!$D$2:$D$4357,Summary!$A32,'WEM demand data'!$F$2:$F$4357,Summary!$C$24,'WEM demand data'!$H$2:$H$4357,Summary!I$25)*1000 -> 77.9 | J32: =SUMIFS('WEM demand data'!$I$2:$I$4357,'WEM demand data'!$D$2:$D$4357,Summary!$A32,'WEM demand data'!$F$2:$F$4357,Summary!$C$24,'WEM demand data'!$H$2:$H$4357,Summary!J$25)*1000 -> 93.9 | K32: =SUMIFS('WEM demand data'!$I$2:$I$4357,'WEM demand data'!$D$2:$D$4357,Summary!$A32,'WEM demand data'!$F$2:$F$4357,Summary!$C$24,'WEM demand data'!$H$2:$H$4357,Summary!K$25)*1000 -> 122.3 | L32: =SUMIFS('WEM demand data'!$I$2:$I$4357,'WEM demand data'!$D$2:$D$4357,Summary!$A32,'WEM demand data'!$F$2:$F$4357,Summary!$C$24,'WEM demand data'!$H$2:$H$4357,Summary!L$25)*1000 -> 156.3 | ... T32: =SUMIFS('WEM demand data'!$I$2:$I$4357,'WEM demand data'!$D$2:$D$4357,Summary!$A32,'WEM demand data'!$F$2:$F$4357,Summary!$C$24,'WEM demand data'!$H$2:$H$4357,Summary!T$25)*1000 -> 441.2 | U32: =SUMIFS('WEM demand data'!$I$2:$I$4357,'WEM demand data'!$D$2:$D$4357,Summary!$A32,'WEM demand data'!$F$2:$F$4357,Summary!$A$4,'WEM demand data'!$H$2:$H$4357,Summary!U$7)*1000 -> 0 | V32: =SUMIFS('WEM demand data'!$I$2:$I$4357,'WEM demand data'!$D$2:$D$4357,Summary!$A32,'WEM demand data'!$F$2:$F$4357,Summary!$A$4,'WEM demand data'!$H$2:$H$4357,Summary!V$7)*1000 -> 0 | W32: =SUMIFS('WEM demand data'!$I$2:$I$4357,'WEM demand data'!$D$2:$D$4357,Summary!$A32,'WEM demand data'!$F$2:$F$4357,Summary!$A$4,'WEM demand data'!$H$2:$H$4357,Summary!W$7)*1000 -> 0 | X32: =SUMIFS('WEM demand data'!$I$2:$I$4357,'WEM demand data'!$D$2:$D$4357,Summary!$A32,'WEM demand data'!$F$2:$F$4357,Summary!$A$4,'WEM demand data'!$H$2:$H$4357,Summary!X$7)*1000 -> 0 | Y32: =SUMIFS('WEM demand data'!$I$2:$I$4357,'WEM demand data'!$D$2:$D$4357,Summary!$A32,'WEM demand data'!$F$2:$F$4357,Summary!$A$4,'WEM demand data'!$H$2:$H$4357,Summary!Y$7)*1000 -> 0 | Z32: =SUMIFS('WEM demand data'!$I$2:$I$4357,'WEM demand data'!$D$2:$D$4357,Summary!$A32,'WEM demand data'!$F$2:$F$4357,Summary!$A$4,'WEM demand data'!$H$2:$H$4357,Summary!Z$7)*1000 -> 0 | AA32: =SUMIFS('WEM demand data'!$I$2:$I$4357,'WEM demand data'!$D$2:$D$4357,Summary!$A32,'WEM demand data'!$F$2:$F$4357,Summary!$A$4,'WEM demand data'!$H$2:$H$4357,Summary!AA$7)*1000 -> 0 | AB32: =SUMIFS('WEM demand data'!$I$2:$I$4357,'WEM demand data'!$D$2:$D$4357,Summary!$A32,'WEM demand data'!$F$2:$F$4357,Summary!$A$4,'WEM demand data'!$H$2:$H$4357,Summary!AB$7)*1000 -> 0 | ... AJ32: =SUMIFS('WEM demand data'!$I$2:$I$4357,'WEM demand data'!$D$2:$D$4357,Summary!$A32,'WEM demand data'!$F$2:$F$4357,Summary!$A$4,'WEM demand data'!$H$2:$H$4357,Summary!AJ$7)*1000 -> 0
A33: Rooftop PV | B33: GWh | J33: =SUMIFS('WEM demand data'!$I$2:$I$4357,'WEM demand data'!$D$2:$D$4357,Summary!$A33,'WEM demand data'!$F$2:$F$4357,Summary!$C$24,'WEM demand data'!$H$2:$H$4357,Summary!J$25)*1000 -> 3503 | K33: =SUMIFS('WEM demand data'!$I$2:$I$4357,'WEM demand data'!$D$2:$D$4357,Summary!$A33,'WEM demand data'!$F$2:$F$4357,Summary!$C$24,'WEM demand data'!$H$2:$H$4357,Summary!K$25)*1000 -> 3939.8 | L33: =SUMIFS('WEM demand data'!$I$2:$I$4357,'WEM demand data'!$D$2:$D$4357,Summary!$A33,'WEM demand data'!$F$2:$F$4357,Summary!$C$24,'WEM demand data'!$H$2:$H$4357,Summary!L$25)*1000 -> 4399.3 | M33: =SUMIFS('WEM demand data'!$I$2:$I$4357,'WEM demand data'!$D$2:$D$4357,Summary!$A33,'WEM demand data'!$F$2:$F$4357,Summary!$C$24,'WEM demand data'!$H$2:$H$4357,Summary!M$25)*1000 -> 4866 | N33: =SUMIFS('WEM demand data'!$I$2:$I$4357,'WEM demand data'!$D$2:$D$4357,Summary!$A33,'WEM demand data'!$F$2:$F$4357,Summary!$C$24,'WEM demand data'!$H$2:$H$4357,Summary!N$25)*1000 -> 5343.4 | O33: =SUMIFS('WEM demand data'!$I$2:$I$4357,'WEM demand data'!$D$2:$D$4357,Summary!$A33,'WEM demand data'!$F$2:$F$4357,Summary!$C$24,'WEM demand data'!$H$2:$H$4357,Summary!O$25)*1000 -> 5826.1 | P33: =SUMIFS('WEM demand data'!$I$2:$I$4357,'WEM demand data'!$D$2:$D$4357,Summary!$A33,'WEM demand data'!$F$2:$F$4357,Summary!$C$24,'WEM demand data'!$H$2:$H$4357,Summary!P$25)*1000 -> 6306.2 | Q33: =SUMIFS('WEM demand data'!$I$2:$I$4357,'WEM demand data'!$D$2:$D$4357,Summary!$A33,'WEM demand data'!$F$2:$F$4357,Summary!$C$24,'WEM demand data'!$H$2:$H$4357,Summary!Q$25)*1000 -> 6817.7 | ... T33: =SUMIFS('WEM demand data'!$I$2:$I$4357,'WEM demand data'!$D$2:$D$4357,Summary!$A33,'WEM demand data'!$F$2:$F$4357,Summary!$C$24,'WEM demand data'!$H$2:$H$4357,Summary!T$25)*1000 -> 8384.5 | U33: =SUMIFS('WEM demand data'!$I$2:$I$4357,'WEM demand data'!$D$2:$D$4357,Summary!$A33,'WEM demand data'!$F$2:$F$4357,Summary!$A$4,'WEM demand data'!$H$2:$H$4357,Summary!U$7)*1000 -> 0 | V33: =SUMIFS('WEM demand data'!$I$2:$I$4357,'WEM demand data'!$D$2:$D$4357,Summary!$A33,'WEM demand data'!$F$2:$F$4357,Summary!$A$4,'WEM demand data'!$H$2:$H$4357,Summary!V$7)*1000 -> 0 | W33: =SUMIFS('WEM demand data'!$I$2:$I$4357,'WEM demand data'!$D$2:$D$4357,Summary!$A33,'WEM demand data'!$F$2:$F$4357,Summary!$A$4,'WEM demand data'!$H$2:$H$4357,Summary!W$7)*1000 -> 0 | X33: =SUMIFS('WEM demand data'!$I$2:$I$4357,'WEM demand data'!$D$2:$D$4357,Summary!$A33,'WEM demand data'!$F$2:$F$4357,Summary!$A$4,'WEM demand data'!$H$2:$H$4357,Summary!X$7)*1000 -> 0 | Y33: =SUMIFS('WEM demand data'!$I$2:$I$4357,'WEM demand data'!$D$2:$D$4357,Summary!$A33,'WEM demand data'!$F$2:$F$4357,Summary!$A$4,'WEM demand data'!$H$2:$H$4357,Summary!Y$7)*1000 -> 0 | Z33: =SUMIFS('WEM demand data'!$I$2:$I$4357,'WEM demand data'!$D$2:$D$4357,Summary!$A33,'WEM demand data'!$F$2:$F$4357,Summary!$A$4,'WEM demand data'!$H$2:$H$4357,Summary!Z$7)*1000 -> 0 | AA33: =SUMIFS('WEM demand data'!$I$2:$I$4357,'WEM demand data'!$D$2:$D$4357,Summary!$A33,'WEM demand data'!$F$2:$F$4357,Summary!$A$4,'WEM demand data'!$H$2:$H$4357,Summary!AA$7)*1000 -> 0 | AB33: =SUMIFS('WEM demand data'!$I$2:$I$4357,'WEM demand data'!$D$2:$D$4357,Summary!$A33,'WEM demand data'!$F$2:$F$4357,Summary!$A$4,'WEM demand data'!$H$2:$H$4357,Summary!AB$7)*1000 -> 0 | ... AJ33: =SUMIFS('WEM demand data'!$I$2:$I$4357,'WEM demand data'!$D$2:$D$4357,Summary!$A33,'WEM demand data'!$F$2:$F$4357,Summary!$A$4,'WEM demand data'!$H$2:$H$4357,Summary!AJ$7)*1000 -> 0
A34: Operational (Sent Out) | B34: GWh | E34: =SUMIFS('WEM demand data'!$I$2:$I$4357,'WEM demand data'!$D$2:$D$4357,Summary!$A34,'WEM demand data'!$F$2:$F$4357,Summary!$C$24,'WEM demand data'!$H$2:$H$4357,Summary!E$25)*1000 -> 17420.2 | F34: =SUMIFS('WEM demand data'!$I$2:$I$4357,'WEM demand data'!$D$2:$D$4357,Summary!$A34,'WEM demand data'!$F$2:$F$4357,Summary!$C$24,'WEM demand data'!$H$2:$H$4357,Summary!F$25)*1000 -> 17664.3 | G34: =SUMIFS('WEM demand data'!$I$2:$I$4357,'WEM demand data'!$D$2:$D$4357,Summary!$A34,'WEM demand data'!$F$2:$F$4357,Summary!$C$24,'WEM demand data'!$H$2:$H$4357,Summary!G$25)*1000 -> 17543.8 | H34: =SUMIFS('WEM demand data'!$I$2:$I$4357,'WEM demand data'!$D$2:$D$4357,Summary!$A34,'WEM demand data'!$F$2:$F$4357,Summary!$C$24,'WEM demand data'!$H$2:$H$4357,Summary!H$25)*1000 -> 17847.4 | I34: =SUMIFS('WEM demand data'!$I$2:$I$4357,'WEM demand data'!$D$2:$D$4357,Summary!$A34,'WEM demand data'!$F$2:$F$4357,Summary!$C$24,'WEM demand data'!$H$2:$H$4357,Summary!I$25)*1000 -> 17302.3 | J34: =SUMIFS('WEM demand data'!$I$2:$I$4357,'WEM demand data'!$D$2:$D$4357,Summary!$A34,'WEM demand data'!$F$2:$F$4357,Summary!$C$24,'WEM demand data'!$H$2:$H$4357,Summary!J$25)*1000 -> 17800.2 | K34: =SUMIFS('WEM demand data'!$I$2:$I$4357,'WEM demand data'!$D$2:$D$4357,Summary!$A34,'WEM demand data'!$F$2:$F$4357,Summary!$C$24,'WEM demand data'!$H$2:$H$4357,Summary!K$25)*1000 -> 18018.2 | L34: =SUMIFS('WEM demand data'!$I$2:$I$4357,'WEM demand data'!$D$2:$D$4357,Summary!$A34,'WEM demand data'!$F$2:$F$4357,Summary!$C$24,'WEM demand data'!$H$2:$H$4357,Summary!L$25)*1000 -> 18082.4 | ... T34: =SUMIFS('WEM demand data'!$I$2:$I$4357,'WEM demand data'!$D$2:$D$4357,Summary!$A34,'WEM demand data'!$F$2:$F$4357,Summary!$C$24,'WEM demand data'!$H$2:$H$4357,Summary!T$25)*1000 -> 27867.6 | U34: =T34*(1+U94) -> 28030.056 | V34: =U34*(1+V94) -> 28193.459 | W34: =V34*(1+W94) -> 28357.814 | X34: =W34*(1+X94) -> 28523.128 | Y34: =X34*(1+Y94) -> 28689.405 | Z34: =Y34*(1+Z94) -> 28856.652 | AA34: =Z34*(1+AA94) -> 29024.874 | AB34: =AA34*(1+AB94) -> 29194.076 | ... AJ34: =AI34*(1+AJ94) -> 30583.691
A35: Operational (Sent Out) + Small Non Scheduled Generation | B35: GWh | E35: =E34+E32 -> 17441.5 | F35: =F34+F32 -> 17703.3 | G35: =G34+G32 -> 17600.9 | H35: =H34+H32 -> 17918.3 | I35: =I34+I32 -> 17380.2 | J35: =J34+J32 -> 17894.1 | K35: =K34+K32 -> 18140.5 | L35: =L34+L32 -> 18238.7 | ... T35: =T34+T32 -> 28308.8 | U35: =T35*(1+U94) -> 28473.828 | V35: =U35*(1+V94) -> 28639.818 | W35: =V35*(1+W94) -> 28806.775 | X35: =W35*(1+X94) -> 28974.706 | Y35: =X35*(1+Y94) -> 29143.616 | Z35: =Y35*(1+Z94) -> 29313.511 | AA35: =Z35*(1+AA94) -> 29484.396 | AB35: =AA35*(1+AB94) -> 29656.277 | ... AJ35: =AI35*(1+AJ94) -> 31067.892
A36: Underlying Demand - Operational Sent out + Rooftop PV + Non-scheduled | B36: GWh | E36: 17471.63 | F36: 18107.077 | G36: 18558.214 | H36: 19340.246 | I36: 18934.793 | J36: =SUM(J34,J33,J32) -> 21397.1 | K36: =SUM(K34,K33,K32) -> 22080.3 | L36: =SUM(L34,L33,L32) -> 22638 | M36: =SUM(M34,M33,M32) -> 23344.6 | N36: =SUM(N34,N33,N32) -> 24100 | O36: =SUM(O34,O33,O32) -> 25275.3 | P36: =SUM(P34,P33,P32) -> 27401.9 | Q36: =SUM(Q34,Q33,Q32) -> 29982 | ... T36: =SUM(T34,T33,T32) -> 36693.3 | U36: =T36*(1+U89) -> 38188.132 | V36: =U36*(1+V89) -> 39743.861 | W36: =V36*(1+W89) -> 41362.969 | X36: =W36*(1+X89) -> 43048.036 | Y36: =X36*(1+Y89) -> 44801.751 | Z36: =Y36*(1+Z89) -> 46626.91 | AA36: =Z36*(1+AA89) -> 48526.423 | AB36: =AA36*(1+AB89) -> 50503.319 | ... AJ36: =AI36*(1+AJ89) -> 69510.926
E37: Source: 2024 Expected Underlying Consumption (Fig. 6) | F37: https://aemo.com.au/-/media/files/electricity/wem/planning_and_forecasting/esoo/2024/2024-wem-electricity-statement-of-opportunities.pdf?la=en
A39: NWIS
A40: Source
A41: NGER reports
F43: 2020 | G43: 2021 | H43: 2022 | I43: 2023 | J43: 2024 | K43: 2025 | L43: 2026 | M43: 2027 | N43: 2028 | O43: 2029 | P43: 2030 | Q43: 2031 | R43: 2032 | S43: 2033 | T43: 2034 | U43: 2035 | V43: 2036 | W43: 2037 | X43: 2038 | Y43: 2039 | Z43: 2040 | AA43: 2041 | AB43: 2042 | AC43: 2043 | AD43: 2044 | AE43: 2045 | AF43: 2046 | AG43: 2047 | AH43: 2048 | AI43: 2049 | AJ43: 2050 | AK43: 2051 | AL43: 2052 | AM43: 2053 | AN43: 2054 | AO43: 2055
A44: NWIS forecast based on NGER figures | B44: GWh | F44: =G44*notes!D19/notes!E19 -> 2712.2668 | G44: =H44*notes!E19/notes!F19 -> 2759.4366 | H44: =I44*notes!F19/notes!G19 -> 2830.1914 | I44: =J44*notes!G19/notes!H19 -> 2712.2668 | J44: 3026.194 | K44: =J44*notes!I19/notes!H19 -> 3026.194 | L44: =K44*notes!J19/notes!I19 -> 2830.1914 | M44: =L44*notes!K19/notes!J19 -> 2863.8842 | N44: =M44*notes!L19/notes!K19 -> 2897.5769 | O44: =N44*notes!M19/notes!L19 -> 2931.2697 | P44: =O44*notes!N19/notes!M19 -> 2964.9624 | Q44: =P44*notes!O19/notes!N19 -> 2998.6552 | R44: =Q44*notes!P19/notes!O19 -> 3032.3479 | ... Z44: =Y44*notes!X19/notes!W19 -> 3301.89 | AA44: =Z44*(1+AA90) -> 3338.4476 | AB44: =AA44*(1+AB90) -> 3375.41 | AC44: =AB44*(1+AC90) -> 3412.7816 | AD44: =AC44*(1+AD90) -> 3450.567 | AE44: =AD44*(1+AE90) -> 3488.7707 | AF44: =AE44*(1+AF90) -> 3527.3974 | AG44: =AF44*(1+AG90) -> 3566.4518 | AH44: =AG44*(1+AH90) -> 3605.9385 | ... AJ44: =AI44*(1+AJ90) -> 3686.2285
A47: DKIS | B47: Annual System Consumption (period ending 31st August)
A48: Source | B48: https://utilicom.nt.gov.au/electricity/reporting/electricity-outlook-report
...

Sheet NEM demand data
A1: Publication | B1: Version | C1: Parent Category | D1: Category | E1: SubCategory | F1: Region | G1: Scenario | H1: Year | I1: Annual Consumption (TWh)
A2: ESOO 2024 | B2: 2024-08-29 | C2: Operational (As Generated) | D2: Auxiliary | E2: Auxiliary | F2: New South Wales | G2: Actual | H2: 2019 | I2: 2.9956
A3: ESOO 2024 | B3: 2024-08-29 | C3: Operational (Sent Out) | D3: Operational (Sent Out) | E3: Operational (Sent Out) | F3: New South Wales | G3: Actual | H3: 2019 | I3: 68.0918
A4: ESOO 2024 | B4: 2024-08-29 | C4: Operational (Sent Out) | D4: Losses | E4: Distribution losses | F4: New South Wales | G4: Actual | H4: 2019 | I4: 2.391
A5: ESOO 2024 | B5: 2024-08-29 | C5: Operational (Sent Out) | D5: Losses | E5: Transmission Losses | F5: New South Wales | G5: Actual | H5: 2019 | I5: 1.6344
A6: ESOO 2024 | B6: 2024-08-29 | C6: Operational (Sent Out) | D6: Small Non Scheduled Generation | E6: ONSG generation | F6: New South Wales | G6: Actual | H6: 2019 | I6: 1.5405
A7: ESOO 2024 | B7: 2024-08-29 | C7: Operational (Sent Out) | D7: Small Non Scheduled Generation | E7: PVNSG generation | F7: New South Wales | G7: Actual | H7: 2019 | I7: 0.2451
A8: ESOO 2024 | B8: 2024-08-29 | C8: Operational (As Generated) | D8: Auxiliary | E8: Auxiliary | F8: New South Wales | G8: Actual | H8: 2020 | I8: 2.7745
A9: ESOO 2024 | B9: 2024-08-29 | C9: Operational (Sent Out) | D9: Operational (Sent Out) | E9: Operational (Sent Out) | F9: New South Wales | G9: Actual | H9: 2020 | I9: 66.5705
A10: ESOO 2024 | B10: 2024-08-29 | C10: Operational (Sent Out) | D10: Losses | E10: Distribution losses | F10: New South Wales | G10: Actual | H10: 2020 | I10: 2.3292
A11: ESOO 2024 | B11: 2024-08-29 | C11: Operational (Sent Out) | D11: Losses | E11: Transmission Losses | F11: New South Wales | G11: Actual | H11: 2020 | I11: 1.4846
A12: ESOO 2024 | B12: 2024-08-29 | C12: Operational (Sent Out) | D12: Small Non Scheduled Generation | E12: ONSG generation | F12: New South Wales | G12: Actual | H12: 2020 | I12: 1.3328
A13: ESOO 2024 | B13: 2024-08-29 | C13: Operational (Sent Out) | D13: Small Non Scheduled Generation | E13: PVNSG generation | F13: New South Wales | G13: Actual | H13: 2020 | I13: 0.3275
... A4357: ESOO 2024 | B4357: 2024-08-29 | C4357: Operational (Sent Out) | D4357: Rooftop PV | E4357: Residential | F4357: NEM | G4357: Central | H4357: 2054 | I4357: 93.2616

Sheet WEM demand data
A1: Publication | B1: Version | C1: Parent Category | D1: Category | E1: SubCategory | F1: Region | G1: Scenario | H1: Year | I1: Annual Consumption (TWh)
A2: WEM ESOO 2024 | B2: 2024-06-18 | C2: Operational (Sent Out) | D2: Operational (Sent Out) | E2: Operational (Sent Out) | F2: SWIS | G2: Actual | H2: 2019 | I2: 17.4202
A3: WEM ESOO 2024 | B3: 2024-06-18 | C3: Operational (Sent Out) | D3: Losses | E3: Distribution losses | F3: SWIS | G3: Actual | H3: 2019 | I3: 0.7939
A4: WEM ESOO 2024 | B4: 2024-06-18 | C4: Operational (Sent Out) | D4: Losses | E4: Transmission Losses | F4: SWIS | G4: Actual | H4: 2019 | I4: 0.6027
A5: WEM ESOO 2024 | B5: 2024-06-18 | C5: Operational (Sent Out) | D5: Small Non Scheduled Generation | E5: PVNSG generation | F5: SWIS | G5: Actual | H5: 2019 | I5: 0.0213
A6: WEM ESOO 2024 | B6: 2024-06-18 | C6: Operational (Sent Out) | D6: Operational (Sent Out) | E6: Operational (Sent Out) | F6: SWIS | G6: Actual | H6: 2020 | I6: 17.6643
A7: WEM ESOO 2024 | B7: 2024-06-18 | C7: Operational (Sent Out) | D7: Losses | E7: Distribution losses | F7: SWIS | G7: Actual | H7: 2020 | I7: 0.7937
A8: WEM ESOO 2024 | B8: 2024-06-18 | C8: Operational (Sent Out) | D8: Losses | E8: Transmission Losses | F8: SWIS | G8: Actual | H8: 2020 | I8: 0.5988
A9: WEM ESOO 2024 | B9: 2024-06-18 | C9: Operational (Sent Out) | D9: Small Non Scheduled Generation | E9: PVNSG generation | F9: SWIS | G9: Actual | H9: 2020 | I9: 0.039
A10: WEM ESOO 2024 | B10: 2024-06-18 | C10: Operational (Sent Out) | D10: Operational (Sent Out) | E10: Operational (Sent Out) | F10: SWIS | G10: Actual | H10: 2021 | I10: 17.5438
A11: WEM ESOO 2024 | B11: 2024-06-18 | C11: Operational (Sent Out) | D11: Losses | E11: Distribution losses | F11: SWIS | G11: Actual | H11: 2021 | I11: 0.8347
A12: WEM ESOO 2024 | B12: 2024-06-18 | C12: Operational (Sent Out) | D12: Losses | E12: Transmission Losses | F12: SWIS | G12: Actual | H12: 2021 | I12: 0.5842
A13: WEM ESOO 2024 | B13: 2024-06-18 | C13: Operational (Sent Out) | D13: Small Non Scheduled Generation | E13: PVNSG generation | F13: SWIS | G13: Actual | H13: 2021 | I13: 0.0571
... A208: WEM ESOO 2024 | B208: 2024-06-18 | C208: Operational (Sent Out) | D208: Rooftop PV | E208: Residential | F208: SWIS | G208: Expected (Step Change) | H208: 2034 | I208: 7.2083

Sheet notes
A2: Horizon Power Tariff setting methodology
B3: https://nwis.com.au/media/cfkhzdic/tariff-setting-methodology.pdf
D15: 2020 | E15: =D15+1 -> 2021 | F15: =E15+1 -> 2022 | G15: =F15+1 -> 2023 | H15: =G15+1 -> 2024 | I15: =H15+1 -> 2025 | J15: =I15+1 -> 2026 | K15: =J15+1 -> 2027 | L15: =K15+1 -> 2028 | ... X15: =W15+1 -> 2040
B16: P50 Peak demand | C16: kw | D16: 115000 | E16: 117000 | F16: 120000 | G16: 115000 | H16: 128310.5 | I16: =H16 -> 128310.5 | J16: 120000 | K16: =J16+$K$17 -> 121428.57 | L16: =K16+$K$17 -> 122857.14 | M16: =L16+$K$17 -> 124285.71 | N16: =M16+$K$17 -> 125714.29 | O16: =N16+$K$17 -> 127142.86 | P16: =O16+$K$17 -> 128571.43 | Q16: =P16+$K$17 -> 130000 | R16: =Q16+$K$17 -> 131428.57 | ... W16: =V16+$K$17 -> 138571.43 | X16: 140000
K17: =(X16-J16)/14 -> 1428.5714
B18: Assumed LF | D18: 1 | E18: =D18 -> 1 | F18: =E18 -> 1 | G18: =F18 -> 1 | H18: =G18 -> 1 | I18: =H18 -> 1 | J18: =I18 -> 1 | K18: =J18 -> 1 | L18: =K18 -> 1 | ... X18: =W18 -> 1
B19: Inferred Consumption forecast | C19: GWh | D19: =D16*8760/1000000/D18 -> 1007.4 | E19: =E16*8760/1000000/E18 -> 1024.92 | F19: =F16*8760/1000000/F18 -> 1051.2 | G19: =G16*8760/1000000/G18 -> 1007.4 | H19: =H16*8760/1000000/H18 -> 1124 | I19: =I16*8760/1000000/I18 -> 1124 | J19: =J16*8760/1000000/J18 -> 1051.2 | K19: =K16*8760/1000000/K18 -> 1063.7143 | ... X19: =X16*8760/1000000/X18 -> 1226.4
B20: Demand to mtach to | C20: GWh | H20: 1124
B21: (Assumes constant load factor)
D22: =D16*8760/1000000/D18 -> 1007.4
B24: Horizon Power Annual report
B25: https://www.horizonpower.com.au/globalassets/media/documents/annual-reports/20232024/horizon-power_annual-report-2024?v=4a6c54
B27: FY 2024 | E27: 1,124 GWh delivered | G27: p14 annual report
A31: Clen Energy Finance Corporation | E31: 45517
B32: Superpowering up Accelerating the electrification and decarbonisation of the Pilbara
B33: Figure 2.2 NWIS grid connected generation facilities
A62: Powerlink data on Mt Isa
A64: Queensland data from PowerLink (includes Mt Isa from 2032)
A65: Source | B65: https://www.powerlink.com.au/planning-report/transmission-annual-planning-report-2024
A66: Period ending | C66: =Summary!#REF! -> #REF! | D66: =Summary!#REF! -> #REF! | E66: =Summary!#REF! -> #REF! | F66: =Summary!#REF! -> #REF! | G66: =Summary!#REF! -> #REF! | H66: =Summary!#REF! -> #REF! | I66: =Summary!#REF! -> #REF! | J66: =Summary!#REF! -> #REF! | K66: =Summary!#REF! & "F" -> #REF! | L66: =Summary!#REF! & "F" -> #REF! | M66: =Summary!#REF! & "F" -> #REF! | N66: =Summary!#REF! & "F" -> #REF! | O66: =Summary!#REF! & "F" -> #REF! | P66: =Summary!#REF! & "F" -> #REF! | Q66: =Summary!#REF! & "F" -> #REF! | R66: =Summary!#REF! & "F" -> #REF! | ... T66: =Summary!#REF! & "F" -> #REF! | U66: 2035 | V66: =U66+1 -> 2036 | W66: =V66+1 -> 2037 | X66: =W66+1 -> 2038 | Y66: =X66+1 -> 2039 | Z66: =Y66+1 -> 2040
